WARNING --- 2024-02-03 22:53:59,241 --- log --- log.py --- Not Found: /favicon.ico
WARNING --- 2024-02-03 22:53:59,242 --- runserver --- runserver.py --- [33mHTTP GET /favicon.ico 404 [0.03, 127.0.0.1:50084][0m
WARNING --- 2024-02-07 13:41:16,080 --- log --- log.py --- Not Found: /q
WARNING --- 2024-02-07 13:41:16,081 --- runserver --- runserver.py --- [33mHTTP GET /q 404 [0.02, 127.0.0.1:50814][0m
WARNING --- 2024-02-07 13:41:16,351 --- log --- log.py --- Not Found: /favicon.ico
WARNING --- 2024-02-07 13:41:16,352 --- runserver --- runserver.py --- [33mHTTP GET /favicon.ico 404 [0.02, 127.0.0.1:50814][0m
WARNING --- 2024-02-07 14:04:16,841 --- log --- log.py --- Not Found: /q
WARNING --- 2024-02-07 14:04:16,842 --- runserver --- runserver.py --- [33mHTTP GET /q 404 [0.04, 127.0.0.1:56390][0m
ERROR --- 2024-02-07 14:08:31,330 --- runserver --- runserver.py --- [35;1mHTTP GET /q 500 [0.53, 127.0.0.1:38812][0m
WARNING --- 2024-02-07 14:09:37,910 --- log --- log.py --- Not Found: /q
WARNING --- 2024-02-07 14:09:37,911 --- runserver --- runserver.py --- [33mHTTP GET /q 404 [0.08, 127.0.0.1:48490][0m
WARNING --- 2024-02-07 14:09:44,141 --- log --- log.py --- Not Found: /q
WARNING --- 2024-02-07 14:09:44,142 --- runserver --- runserver.py --- [33mHTTP GET /q 404 [0.02, 127.0.0.1:48490][0m
WARNING --- 2024-02-07 14:11:01,901 --- log --- log.py --- Not Found: /q
WARNING --- 2024-02-07 14:11:01,902 --- runserver --- runserver.py --- [33mHTTP GET /q 404 [0.02, 127.0.0.1:47010][0m
WARNING --- 2024-02-07 14:13:02,171 --- log --- log.py --- Not Found: /q
WARNING --- 2024-02-07 14:13:02,172 --- runserver --- runserver.py --- [33mHTTP GET /q 404 [0.02, 127.0.0.1:51228][0m
WARNING --- 2024-02-07 14:13:21,302 --- log --- log.py --- Not Found: /q
WARNING --- 2024-02-07 14:13:21,302 --- runserver --- runserver.py --- [33mHTTP GET /q 404 [0.02, 127.0.0.1:51228][0m
WARNING --- 2024-02-07 14:14:04,286 --- log --- log.py --- Not Found: /q
WARNING --- 2024-02-07 14:14:04,287 --- runserver --- runserver.py --- [33mHTTP GET /q 404 [0.01, 127.0.0.1:51228][0m
WARNING --- 2024-02-07 14:14:16,760 --- log --- log.py --- Not Found: /q
WARNING --- 2024-02-07 14:14:16,761 --- runserver --- runserver.py --- [33mHTTP GET /q 404 [0.02, 127.0.0.1:51228][0m
WARNING --- 2024-02-07 14:14:25,507 --- log --- log.py --- Not Found: /q
WARNING --- 2024-02-07 14:14:25,508 --- runserver --- runserver.py --- [33mHTTP GET /q 404 [0.02, 127.0.0.1:51228][0m
WARNING --- 2024-02-07 14:14:43,534 --- log --- log.py --- Not Found: /q
WARNING --- 2024-02-07 14:14:43,535 --- runserver --- runserver.py --- [33mHTTP GET /q 404 [0.02, 127.0.0.1:51228][0m
WARNING --- 2024-02-07 14:15:01,489 --- log --- log.py --- Not Found: /q
WARNING --- 2024-02-07 14:15:01,490 --- runserver --- runserver.py --- [33mHTTP GET /q 404 [0.02, 127.0.0.1:51228][0m
WARNING --- 2024-02-07 14:15:11,082 --- log --- log.py --- Not Found: /q
WARNING --- 2024-02-07 14:15:11,083 --- runserver --- runserver.py --- [33mHTTP GET /q 404 [0.02, 127.0.0.1:51228][0m
WARNING --- 2024-02-07 14:15:21,261 --- log --- log.py --- Not Found: /q
WARNING --- 2024-02-07 14:15:21,262 --- runserver --- runserver.py --- [33mHTTP GET /q 404 [0.02, 127.0.0.1:51228][0m
WARNING --- 2024-02-07 14:17:41,072 --- log --- log.py --- Not Found: /q
WARNING --- 2024-02-07 14:17:41,073 --- runserver --- runserver.py --- [33mHTTP GET /q 404 [0.02, 127.0.0.1:43646][0m
WARNING --- 2024-02-07 14:22:43,143 --- log --- log.py --- Not Found: /q
WARNING --- 2024-02-07 14:22:43,144 --- runserver --- runserver.py --- [33mHTTP GET /q 404 [0.02, 127.0.0.1:44462][0m
WARNING --- 2024-02-07 14:22:50,002 --- log --- log.py --- Not Found: /q
WARNING --- 2024-02-07 14:22:50,004 --- runserver --- runserver.py --- [33mHTTP GET /q 404 [0.02, 127.0.0.1:44462][0m
WARNING --- 2024-02-07 14:23:02,303 --- log --- log.py --- Not Found: /q
WARNING --- 2024-02-07 14:23:02,305 --- runserver --- runserver.py --- [33mHTTP GET /q 404 [0.02, 127.0.0.1:44462][0m
WARNING --- 2024-02-07 14:23:09,199 --- log --- log.py --- Not Found: /q
WARNING --- 2024-02-07 14:23:09,200 --- runserver --- runserver.py --- [33mHTTP GET /q 404 [0.02, 127.0.0.1:44462][0m
WARNING --- 2024-02-07 14:23:24,888 --- log --- log.py --- Not Found: /q
WARNING --- 2024-02-07 14:23:24,890 --- runserver --- runserver.py --- [33mHTTP GET /q 404 [0.02, 127.0.0.1:44462][0m
WARNING --- 2024-02-07 14:28:02,957 --- log --- log.py --- Not Found: /q
WARNING --- 2024-02-07 14:28:02,958 --- runserver --- runserver.py --- [33mHTTP GET /q 404 [0.03, 127.0.0.1:44056][0m
WARNING --- 2024-02-07 14:28:43,733 --- log --- log.py --- Not Found: /q
WARNING --- 2024-02-07 14:28:43,734 --- runserver --- runserver.py --- [33mHTTP GET /q 404 [0.02, 127.0.0.1:44056][0m
WARNING --- 2024-02-07 14:29:06,454 --- log --- log.py --- Not Found: /q
WARNING --- 2024-02-07 14:29:06,455 --- runserver --- runserver.py --- [33mHTTP GET /q 404 [0.02, 127.0.0.1:44056][0m
WARNING --- 2024-02-07 14:29:59,935 --- log --- log.py --- Not Found: /q
WARNING --- 2024-02-07 14:29:59,936 --- runserver --- runserver.py --- [33mHTTP GET /q 404 [0.02, 127.0.0.1:44056][0m
WARNING --- 2024-02-07 14:30:12,306 --- log --- log.py --- Not Found: /q
WARNING --- 2024-02-07 14:30:12,307 --- runserver --- runserver.py --- [33mHTTP GET /q 404 [0.02, 127.0.0.1:44056][0m
WARNING --- 2024-02-07 14:30:25,473 --- log --- log.py --- Not Found: /q
WARNING --- 2024-02-07 14:30:25,474 --- runserver --- runserver.py --- [33mHTTP GET /q 404 [0.02, 127.0.0.1:44056][0m
WARNING --- 2024-02-07 14:30:37,696 --- log --- log.py --- Not Found: /q
WARNING --- 2024-02-07 14:30:37,697 --- runserver --- runserver.py --- [33mHTTP GET /q 404 [0.02, 127.0.0.1:44056][0m
WARNING --- 2024-02-07 14:30:53,040 --- log --- log.py --- Not Found: /q
WARNING --- 2024-02-07 14:30:53,041 --- runserver --- runserver.py --- [33mHTTP GET /q 404 [0.02, 127.0.0.1:44056][0m
WARNING --- 2024-02-07 14:31:09,751 --- log --- log.py --- Not Found: /q
WARNING --- 2024-02-07 14:31:09,752 --- runserver --- runserver.py --- [33mHTTP GET /q 404 [0.02, 127.0.0.1:44056][0m
WARNING --- 2024-02-07 14:31:18,692 --- log --- log.py --- Not Found: /q
WARNING --- 2024-02-07 14:31:18,693 --- runserver --- runserver.py --- [33mHTTP GET /q 404 [0.02, 127.0.0.1:44056][0m
WARNING --- 2024-02-07 14:31:39,497 --- log --- log.py --- Not Found: /q
WARNING --- 2024-02-07 14:31:39,498 --- runserver --- runserver.py --- [33mHTTP GET /q 404 [0.02, 127.0.0.1:44056][0m
WARNING --- 2024-02-07 14:32:08,460 --- log --- log.py --- Not Found: /q
WARNING --- 2024-02-07 14:32:08,461 --- runserver --- runserver.py --- [33mHTTP GET /q 404 [0.02, 127.0.0.1:44056][0m
WARNING --- 2024-02-07 14:33:36,767 --- log --- log.py --- Not Found: /q
WARNING --- 2024-02-07 14:33:36,768 --- runserver --- runserver.py --- [33mHTTP GET /q 404 [0.02, 127.0.0.1:43396][0m
WARNING --- 2024-02-07 14:33:55,924 --- log --- log.py --- Not Found: /q
WARNING --- 2024-02-07 14:33:55,925 --- runserver --- runserver.py --- [33mHTTP GET /q 404 [0.02, 127.0.0.1:43396][0m
WARNING --- 2024-02-07 14:34:05,240 --- log --- log.py --- Not Found: /q
WARNING --- 2024-02-07 14:34:05,241 --- runserver --- runserver.py --- [33mHTTP GET /q 404 [0.02, 127.0.0.1:43396][0m
WARNING --- 2024-02-07 14:34:20,668 --- log --- log.py --- Not Found: /q
WARNING --- 2024-02-07 14:34:20,669 --- runserver --- runserver.py --- [33mHTTP GET /q 404 [0.02, 127.0.0.1:43396][0m
WARNING --- 2024-02-07 14:34:35,595 --- log --- log.py --- Not Found: /q
WARNING --- 2024-02-07 14:34:35,597 --- runserver --- runserver.py --- [33mHTTP GET /q 404 [0.02, 127.0.0.1:43396][0m
WARNING --- 2024-02-07 14:36:58,023 --- log --- log.py --- Not Found: /q
WARNING --- 2024-02-07 14:36:58,024 --- runserver --- runserver.py --- [33mHTTP GET /q 404 [0.02, 127.0.0.1:57430][0m
WARNING --- 2024-02-07 14:37:06,779 --- log --- log.py --- Not Found: /q
WARNING --- 2024-02-07 14:37:06,780 --- runserver --- runserver.py --- [33mHTTP GET /q 404 [0.02, 127.0.0.1:57430][0m
WARNING --- 2024-02-07 14:37:19,411 --- log --- log.py --- Not Found: /q
WARNING --- 2024-02-07 14:37:19,412 --- runserver --- runserver.py --- [33mHTTP GET /q 404 [0.02, 127.0.0.1:57430][0m
WARNING --- 2024-02-07 14:38:17,694 --- log --- log.py --- Not Found: /q
WARNING --- 2024-02-07 14:38:17,695 --- runserver --- runserver.py --- [33mHTTP GET /q 404 [0.02, 127.0.0.1:57430][0m
WARNING --- 2024-02-07 14:38:32,886 --- log --- log.py --- Not Found: /q
WARNING --- 2024-02-07 14:38:32,887 --- runserver --- runserver.py --- [33mHTTP GET /q 404 [0.02, 127.0.0.1:57430][0m
WARNING --- 2024-02-07 14:38:55,744 --- log --- log.py --- Not Found: /q
WARNING --- 2024-02-07 14:38:55,745 --- runserver --- runserver.py --- [33mHTTP GET /q 404 [0.02, 127.0.0.1:57430][0m
WARNING --- 2024-02-07 14:39:12,785 --- log --- log.py --- Not Found: /q
WARNING --- 2024-02-07 14:39:12,786 --- runserver --- runserver.py --- [33mHTTP GET /q 404 [0.02, 127.0.0.1:57430][0m
WARNING --- 2024-02-07 14:39:33,084 --- log --- log.py --- Not Found: /q
WARNING --- 2024-02-07 14:39:33,085 --- runserver --- runserver.py --- [33mHTTP GET /q 404 [0.02, 127.0.0.1:57430][0m
WARNING --- 2024-02-07 14:39:47,682 --- log --- log.py --- Not Found: /q
WARNING --- 2024-02-07 14:39:47,683 --- runserver --- runserver.py --- [33mHTTP GET /q 404 [0.02, 127.0.0.1:57430][0m
WARNING --- 2024-02-07 14:40:00,835 --- log --- log.py --- Not Found: /q
WARNING --- 2024-02-07 14:40:00,837 --- runserver --- runserver.py --- [33mHTTP GET /q 404 [0.02, 127.0.0.1:57430][0m
WARNING --- 2024-02-07 14:40:10,615 --- log --- log.py --- Not Found: /q
WARNING --- 2024-02-07 14:40:10,616 --- runserver --- runserver.py --- [33mHTTP GET /q 404 [0.02, 127.0.0.1:57430][0m
WARNING --- 2024-02-07 14:41:28,847 --- log --- log.py --- Not Found: /q
WARNING --- 2024-02-07 14:41:28,848 --- runserver --- runserver.py --- [33mHTTP GET /q 404 [0.02, 127.0.0.1:53880][0m
WARNING --- 2024-02-07 14:41:42,747 --- log --- log.py --- Not Found: /q
WARNING --- 2024-02-07 14:41:42,747 --- runserver --- runserver.py --- [33mHTTP GET /q 404 [0.02, 127.0.0.1:53880][0m
WARNING --- 2024-02-07 14:42:18,058 --- log --- log.py --- Not Found: /q
WARNING --- 2024-02-07 14:42:18,060 --- runserver --- runserver.py --- [33mHTTP GET /q 404 [0.02, 127.0.0.1:53880][0m
WARNING --- 2024-02-07 14:44:00,674 --- log --- log.py --- Not Found: /q
WARNING --- 2024-02-07 14:44:00,675 --- runserver --- runserver.py --- [33mHTTP GET /q 404 [0.03, 127.0.0.1:55020][0m
WARNING --- 2024-02-07 14:44:13,675 --- log --- log.py --- Not Found: /q
WARNING --- 2024-02-07 14:44:13,676 --- runserver --- runserver.py --- [33mHTTP GET /q 404 [0.02, 127.0.0.1:55020][0m
WARNING --- 2024-02-07 14:44:24,536 --- log --- log.py --- Not Found: /q
WARNING --- 2024-02-07 14:44:24,538 --- runserver --- runserver.py --- [33mHTTP GET /q 404 [0.02, 127.0.0.1:55020][0m
WARNING --- 2024-02-07 14:47:54,030 --- log --- log.py --- Not Found: /q
WARNING --- 2024-02-07 14:47:54,031 --- runserver --- runserver.py --- [33mHTTP GET /q 404 [0.02, 127.0.0.1:40380][0m
WARNING --- 2024-02-07 14:48:41,192 --- log --- log.py --- Not Found: /q
WARNING --- 2024-02-07 14:48:41,193 --- runserver --- runserver.py --- [33mHTTP GET /q 404 [0.02, 127.0.0.1:40380][0m
WARNING --- 2024-02-07 14:48:42,635 --- log --- log.py --- Not Found: /q
WARNING --- 2024-02-07 14:48:42,636 --- runserver --- runserver.py --- [33mHTTP GET /q 404 [0.02, 127.0.0.1:40380][0m
WARNING --- 2024-02-07 14:48:57,298 --- log --- log.py --- Not Found: /q
WARNING --- 2024-02-07 14:48:57,300 --- runserver --- runserver.py --- [33mHTTP GET /q 404 [0.02, 127.0.0.1:40380][0m
WARNING --- 2024-02-07 14:49:18,401 --- log --- log.py --- Not Found: /q
WARNING --- 2024-02-07 14:49:18,402 --- runserver --- runserver.py --- [33mHTTP GET /q 404 [0.02, 127.0.0.1:40380][0m
WARNING --- 2024-02-07 14:49:39,104 --- log --- log.py --- Not Found: /q
WARNING --- 2024-02-07 14:49:39,105 --- runserver --- runserver.py --- [33mHTTP GET /q 404 [0.02, 127.0.0.1:40380][0m
WARNING --- 2024-02-07 14:50:01,501 --- log --- log.py --- Not Found: /q
WARNING --- 2024-02-07 14:50:01,502 --- runserver --- runserver.py --- [33mHTTP GET /q 404 [0.02, 127.0.0.1:40380][0m
WARNING --- 2024-02-07 14:50:26,543 --- log --- log.py --- Not Found: /q
WARNING --- 2024-02-07 14:50:26,544 --- runserver --- runserver.py --- [33mHTTP GET /q 404 [0.02, 127.0.0.1:40380][0m
WARNING --- 2024-02-07 14:51:25,212 --- log --- log.py --- Not Found: /q
WARNING --- 2024-02-07 14:51:25,213 --- runserver --- runserver.py --- [33mHTTP GET /q 404 [0.02, 127.0.0.1:40380][0m
WARNING --- 2024-02-07 15:05:50,607 --- log --- log.py --- Not Found: /q
WARNING --- 2024-02-07 15:05:50,608 --- runserver --- runserver.py --- [33mHTTP GET /q 404 [0.01, 127.0.0.1:42636][0m
WARNING --- 2024-02-07 15:05:55,871 --- log --- log.py --- Not Found: /q
WARNING --- 2024-02-07 15:05:55,871 --- runserver --- runserver.py --- [33mHTTP GET /q 404 [0.02, 127.0.0.1:42636][0m
WARNING --- 2024-02-07 15:07:03,321 --- log --- log.py --- Not Found: /q
WARNING --- 2024-02-07 15:07:03,322 --- runserver --- runserver.py --- [33mHTTP GET /q 404 [0.02, 127.0.0.1:33886][0m
WARNING --- 2024-02-07 15:07:15,808 --- log --- log.py --- Not Found: /q
WARNING --- 2024-02-07 15:07:15,809 --- runserver --- runserver.py --- [33mHTTP GET /q 404 [0.02, 127.0.0.1:33886][0m
WARNING --- 2024-02-07 15:08:01,708 --- log --- log.py --- Not Found: /q
WARNING --- 2024-02-07 15:08:01,708 --- runserver --- runserver.py --- [33mHTTP GET /q 404 [0.02, 127.0.0.1:33886][0m
WARNING --- 2024-02-07 15:08:13,974 --- log --- log.py --- Not Found: /q
WARNING --- 2024-02-07 15:08:13,975 --- runserver --- runserver.py --- [33mHTTP GET /q 404 [0.02, 127.0.0.1:33886][0m
WARNING --- 2024-02-07 15:15:47,725 --- log --- log.py --- Not Found: /q
WARNING --- 2024-02-07 15:15:47,725 --- runserver --- runserver.py --- [33mHTTP GET /q 404 [0.02, 127.0.0.1:49658][0m
WARNING --- 2024-02-07 15:15:59,434 --- log --- log.py --- Not Found: /q
WARNING --- 2024-02-07 15:15:59,434 --- runserver --- runserver.py --- [33mHTTP GET /q 404 [0.02, 127.0.0.1:49658][0m
WARNING --- 2024-02-07 15:44:11,849 --- log --- log.py --- Not Found: /q
WARNING --- 2024-02-07 15:44:11,849 --- runserver --- runserver.py --- [33mHTTP GET /q 404 [0.02, 127.0.0.1:52342][0m
WARNING --- 2024-02-07 15:44:59,988 --- log --- log.py --- Not Found: /q
WARNING --- 2024-02-07 15:44:59,989 --- runserver --- runserver.py --- [33mHTTP GET /q 404 [0.02, 127.0.0.1:52342][0m
WARNING --- 2024-02-07 15:45:01,658 --- log --- log.py --- Not Found: /q
WARNING --- 2024-02-07 15:45:01,659 --- runserver --- runserver.py --- [33mHTTP GET /q 404 [0.02, 127.0.0.1:52342][0m
WARNING --- 2024-02-07 15:45:02,572 --- log --- log.py --- Not Found: /q
WARNING --- 2024-02-07 15:45:02,573 --- runserver --- runserver.py --- [33mHTTP GET /q 404 [0.02, 127.0.0.1:52342][0m
WARNING --- 2024-02-07 15:45:07,323 --- log --- log.py --- Not Found: /q
WARNING --- 2024-02-07 15:45:07,324 --- runserver --- runserver.py --- [33mHTTP GET /q 404 [0.02, 127.0.0.1:52356][0m
WARNING --- 2024-02-07 15:45:18,030 --- log --- log.py --- Not Found: /q
WARNING --- 2024-02-07 15:45:18,031 --- runserver --- runserver.py --- [33mHTTP GET /q 404 [0.02, 127.0.0.1:52356][0m
WARNING --- 2024-02-07 15:46:07,004 --- log --- log.py --- Not Found: /q
WARNING --- 2024-02-07 15:46:07,006 --- runserver --- runserver.py --- [33mHTTP GET /q 404 [0.03, 127.0.0.1:52356][0m
WARNING --- 2024-02-07 15:46:35,665 --- log --- log.py --- Not Found: /q
WARNING --- 2024-02-07 15:46:35,666 --- runserver --- runserver.py --- [33mHTTP GET /q 404 [0.02, 127.0.0.1:52356][0m
WARNING --- 2024-02-07 15:46:37,370 --- log --- log.py --- Not Found: /q
WARNING --- 2024-02-07 15:46:37,371 --- runserver --- runserver.py --- [33mHTTP GET /q 404 [0.02, 127.0.0.1:52356][0m
WARNING --- 2024-02-07 15:46:54,766 --- log --- log.py --- Not Found: /q
WARNING --- 2024-02-07 15:46:54,767 --- runserver --- runserver.py --- [33mHTTP GET /q 404 [0.02, 127.0.0.1:52356][0m
WARNING --- 2024-02-07 15:46:59,098 --- log --- log.py --- Not Found: /q
WARNING --- 2024-02-07 15:46:59,099 --- runserver --- runserver.py --- [33mHTTP GET /q 404 [0.02, 127.0.0.1:52356][0m
WARNING --- 2024-02-07 15:47:08,647 --- log --- log.py --- Not Found: /q
WARNING --- 2024-02-07 15:47:08,648 --- runserver --- runserver.py --- [33mHTTP GET /q 404 [0.02, 127.0.0.1:52356][0m
WARNING --- 2024-02-07 15:47:28,603 --- log --- log.py --- Not Found: /q
WARNING --- 2024-02-07 15:47:28,604 --- runserver --- runserver.py --- [33mHTTP GET /q 404 [0.02, 127.0.0.1:52356][0m
WARNING --- 2024-02-07 15:47:36,176 --- log --- log.py --- Not Found: /q
WARNING --- 2024-02-07 15:47:36,177 --- runserver --- runserver.py --- [33mHTTP GET /q 404 [0.02, 127.0.0.1:52356][0m
WARNING --- 2024-02-07 15:48:38,317 --- log --- log.py --- Not Found: /q
WARNING --- 2024-02-07 15:48:38,318 --- runserver --- runserver.py --- [33mHTTP GET /q 404 [0.02, 127.0.0.1:38100][0m
WARNING --- 2024-02-07 15:48:49,065 --- log --- log.py --- Not Found: /q
WARNING --- 2024-02-07 15:48:49,066 --- runserver --- runserver.py --- [33mHTTP GET /q 404 [0.03, 127.0.0.1:38100][0m
WARNING --- 2024-02-07 15:48:53,590 --- log --- log.py --- Not Found: /q
WARNING --- 2024-02-07 15:48:53,591 --- runserver --- runserver.py --- [33mHTTP GET /q 404 [0.02, 127.0.0.1:38100][0m
WARNING --- 2024-02-07 15:49:38,573 --- log --- log.py --- Not Found: /q
WARNING --- 2024-02-07 15:49:38,574 --- runserver --- runserver.py --- [33mHTTP GET /q 404 [0.02, 127.0.0.1:38100][0m
WARNING --- 2024-02-07 15:49:54,894 --- log --- log.py --- Not Found: /q
WARNING --- 2024-02-07 15:49:54,895 --- runserver --- runserver.py --- [33mHTTP GET /q 404 [0.02, 127.0.0.1:38100][0m
WARNING --- 2024-02-07 15:49:59,980 --- log --- log.py --- Not Found: /q
WARNING --- 2024-02-07 15:49:59,981 --- runserver --- runserver.py --- [33mHTTP GET /q 404 [0.02, 127.0.0.1:38100][0m
WARNING --- 2024-02-07 15:50:03,954 --- log --- log.py --- Not Found: /q
WARNING --- 2024-02-07 15:50:03,955 --- runserver --- runserver.py --- [33mHTTP GET /q 404 [0.02, 127.0.0.1:38100][0m
WARNING --- 2024-02-07 15:50:18,420 --- log --- log.py --- Not Found: /q
WARNING --- 2024-02-07 15:50:18,420 --- runserver --- runserver.py --- [33mHTTP GET /q 404 [0.02, 127.0.0.1:38100][0m
WARNING --- 2024-02-07 15:51:24,900 --- log --- log.py --- Not Found: /q
WARNING --- 2024-02-07 15:51:24,901 --- runserver --- runserver.py --- [33mHTTP GET /q 404 [0.02, 127.0.0.1:39230][0m
WARNING --- 2024-02-07 15:51:37,146 --- log --- log.py --- Not Found: /q
WARNING --- 2024-02-07 15:51:37,146 --- runserver --- runserver.py --- [33mHTTP GET /q 404 [0.02, 127.0.0.1:39230][0m
WARNING --- 2024-02-07 15:51:47,936 --- log --- log.py --- Not Found: /q
WARNING --- 2024-02-07 15:51:47,938 --- runserver --- runserver.py --- [33mHTTP GET /q 404 [0.02, 127.0.0.1:39230][0m
WARNING --- 2024-02-07 15:51:57,516 --- log --- log.py --- Not Found: /q
WARNING --- 2024-02-07 15:51:57,517 --- runserver --- runserver.py --- [33mHTTP GET /q 404 [0.02, 127.0.0.1:39230][0m
WARNING --- 2024-02-07 15:51:57,815 --- log --- log.py --- Not Found: /q
WARNING --- 2024-02-07 15:51:57,816 --- runserver --- runserver.py --- [33mHTTP GET /q 404 [0.02, 127.0.0.1:39230][0m
WARNING --- 2024-02-07 15:54:15,183 --- log --- log.py --- Not Found: /q
WARNING --- 2024-02-07 15:54:15,183 --- runserver --- runserver.py --- [33mHTTP GET /q 404 [0.03, 127.0.0.1:32918][0m
WARNING --- 2024-02-07 15:55:57,531 --- log --- log.py --- Not Found: /static/admin/css/login.css
WARNING --- 2024-02-07 15:55:57,531 --- runserver --- runserver.py --- [33mHTTP GET /static/admin/css/login.css 404 [0.01, 127.0.0.1:37774][0m
WARNING --- 2024-02-07 15:55:59,463 --- log --- log.py --- Not Found: /logout
WARNING --- 2024-02-07 15:55:59,464 --- runserver --- runserver.py --- [33mHTTP GET /logout 404 [0.01, 127.0.0.1:37774][0m
WARNING --- 2024-02-07 15:56:10,983 --- log --- log.py --- Forbidden (Permission denied): /user/logout/
Traceback (most recent call last):
  File "/mnt/myprojects/project/mysite/venv/lib/python3.11/site-packages/asgiref/sync.py", line 534, in thread_handler
    raise exc_info[1]
  File "/mnt/myprojects/project/mysite/venv/lib/python3.11/site-packages/django/core/handlers/exception.py", line 42, in inner
    response = await get_response(request)
               ^^^^^^^^^^^^^^^^^^^^^^^^^^^
  File "/mnt/myprojects/project/mysite/venv/lib/python3.11/site-packages/asgiref/sync.py", line 534, in thread_handler
    raise exc_info[1]
  File "/mnt/myprojects/project/mysite/venv/lib/python3.11/site-packages/django/core/handlers/base.py", line 253, in _get_response_async
    response = await wrapped_callback(
               ^^^^^^^^^^^^^^^^^^^^^^^
  File "/mnt/myprojects/project/mysite/venv/lib/python3.11/site-packages/asgiref/sync.py", line 479, in __call__
    ret: _R = await loop.run_in_executor(
              ^^^^^^^^^^^^^^^^^^^^^^^^^^^
  File "/home/kenun/.python3.11/lib/python3.11/concurrent/futures/thread.py", line 58, in run
    result = self.fn(*self.args, **self.kwargs)
             ^^^^^^^^^^^^^^^^^^^^^^^^^^^^^^^^^^
  File "/mnt/myprojects/project/mysite/venv/lib/python3.11/site-packages/asgiref/sync.py", line 538, in thread_handler
    return func(*args, **kwargs)
           ^^^^^^^^^^^^^^^^^^^^^
  File "/mnt/myprojects/project/mysite/venv/lib/python3.11/site-packages/django/views/generic/base.py", line 104, in view
    return self.dispatch(request, *args, **kwargs)
           ^^^^^^^^^^^^^^^^^^^^^^^^^^^^^^^^^^^^^^^
  File "/mnt/myprojects/project/mysite/venv/lib/python3.11/site-packages/django/contrib/auth/mixins.py", line 72, in dispatch
    return self.handle_no_permission()
           ^^^^^^^^^^^^^^^^^^^^^^^^^^^
  File "/mnt/myprojects/project/mysite/venv/lib/python3.11/site-packages/django/contrib/auth/mixins.py", line 48, in handle_no_permission
    raise PermissionDenied(self.get_permission_denied_message())
django.core.exceptions.PermissionDenied: Вы не авторизованы.
WARNING --- 2024-02-07 15:56:10,988 --- runserver --- runserver.py --- [31;1mHTTP GET /user/logout/ 403 [0.01, 127.0.0.1:37774][0m
WARNING --- 2024-02-08 11:02:32,079 --- log --- log.py --- Not Found: /q
WARNING --- 2024-02-08 11:02:32,081 --- runserver --- runserver.py --- [33mHTTP GET /q 404 [0.02, 127.0.0.1:41858][0m
WARNING --- 2024-02-08 11:02:33,056 --- log --- log.py --- Not Found: /q
WARNING --- 2024-02-08 11:02:33,058 --- runserver --- runserver.py --- [33mHTTP GET /q 404 [0.02, 127.0.0.1:41858][0m
WARNING --- 2024-02-08 11:02:33,302 --- log --- log.py --- Not Found: /favicon.ico
WARNING --- 2024-02-08 11:02:33,303 --- runserver --- runserver.py --- [33mHTTP GET /favicon.ico 404 [0.01, 127.0.0.1:41858][0m
WARNING --- 2024-02-08 11:02:45,882 --- log --- log.py --- Not Found: /q
WARNING --- 2024-02-08 11:02:45,883 --- runserver --- runserver.py --- [33mHTTP GET /q 404 [0.07, 127.0.0.1:52034][0m
WARNING --- 2024-02-08 12:04:40,930 --- log --- log.py --- Not Found: /favicon.ico
WARNING --- 2024-02-08 12:04:40,931 --- runserver --- runserver.py --- [33mHTTP GET /favicon.ico 404 [0.01, 127.0.0.1:40206][0m
WARNING --- 2024-02-08 12:04:43,043 --- log --- log.py --- Not Found: /static/admin/js/vendor/jquery/jquery.min.js
WARNING --- 2024-02-08 12:04:43,043 --- log --- log.py --- Not Found: /static/admin/js/admin/RelatedObjectLookups.js
WARNING --- 2024-02-08 12:04:43,044 --- log --- log.py --- Not Found: /static/admin/css/changelists.css
WARNING --- 2024-02-08 12:04:43,044 --- log --- log.py --- Not Found: /static/admin/js/jquery.init.js
WARNING --- 2024-02-08 12:04:43,045 --- runserver --- runserver.py --- [33mHTTP GET /static/admin/js/vendor/jquery/jquery.min.js 404 [0.05, 127.0.0.1:56734][0m
WARNING --- 2024-02-08 12:04:43,047 --- runserver --- runserver.py --- [33mHTTP GET /static/admin/js/admin/RelatedObjectLookups.js 404 [0.05, 127.0.0.1:56762][0m
WARNING --- 2024-02-08 12:04:43,048 --- runserver --- runserver.py --- [33mHTTP GET /static/admin/css/changelists.css 404 [0.06, 127.0.0.1:40206][0m
WARNING --- 2024-02-08 12:04:43,049 --- runserver --- runserver.py --- [33mHTTP GET /static/admin/js/jquery.init.js 404 [0.06, 127.0.0.1:56748][0m
WARNING --- 2024-02-08 12:04:43,051 --- log --- log.py --- Not Found: /static/admin/js/core.js
WARNING --- 2024-02-08 12:04:43,055 --- runserver --- runserver.py --- [33mHTTP GET /static/admin/js/core.js 404 [0.06, 127.0.0.1:56760][0m
WARNING --- 2024-02-08 12:04:43,083 --- log --- log.py --- Not Found: /static/admin/js/urlify.js
WARNING --- 2024-02-08 12:04:43,085 --- log --- log.py --- Not Found: /static/admin/js/actions.js
WARNING --- 2024-02-08 12:04:43,088 --- runserver --- runserver.py --- [33mHTTP GET /static/admin/js/urlify.js 404 [0.03, 127.0.0.1:56734][0m
WARNING --- 2024-02-08 12:04:43,089 --- runserver --- runserver.py --- [33mHTTP GET /static/admin/js/actions.js 404 [0.04, 127.0.0.1:40230][0m
WARNING --- 2024-02-08 12:04:43,091 --- log --- log.py --- Not Found: /static/admin/js/vendor/xregexp/xregexp.min.js
WARNING --- 2024-02-08 12:04:43,092 --- runserver --- runserver.py --- [33mHTTP GET /static/admin/js/vendor/xregexp/xregexp.min.js 404 [0.03, 127.0.0.1:56774][0m
WARNING --- 2024-02-08 12:04:43,093 --- log --- log.py --- Not Found: /static/admin/js/prepopulate.js
WARNING --- 2024-02-08 12:04:43,094 --- runserver --- runserver.py --- [33mHTTP GET /static/admin/js/prepopulate.js 404 [0.03, 127.0.0.1:56762][0m
WARNING --- 2024-02-08 12:04:43,139 --- log --- log.py --- Not Found: /static/admin/js/filters.js
WARNING --- 2024-02-08 12:04:43,140 --- runserver --- runserver.py --- [33mHTTP GET /static/admin/js/filters.js 404 [0.02, 127.0.0.1:40230][0m
WARNING --- 2024-02-08 12:04:43,146 --- log --- log.py --- Not Found: /static/admin/img/tooltag-add.svg
WARNING --- 2024-02-08 12:04:43,147 --- runserver --- runserver.py --- [33mHTTP GET /static/admin/img/tooltag-add.svg 404 [0.02, 127.0.0.1:56734][0m
WARNING --- 2024-02-08 12:04:50,578 --- log --- log.py --- Not Found: /@
WARNING --- 2024-02-08 12:04:50,579 --- runserver --- runserver.py --- [33mHTTP GET /@ 404 [0.02, 127.0.0.1:56806][0m
ERROR --- 2024-02-08 12:06:49,976 --- log --- log.py --- Internal Server Error: /addons/failed
Traceback (most recent call last):
  File "/mnt/myprojects/project/mysite/venv/lib/python3.11/site-packages/asgiref/sync.py", line 534, in thread_handler
    raise exc_info[1]
  File "/mnt/myprojects/project/mysite/venv/lib/python3.11/site-packages/django/core/handlers/exception.py", line 42, in inner
    response = await get_response(request)
               ^^^^^^^^^^^^^^^^^^^^^^^^^^^
  File "/mnt/myprojects/project/mysite/venv/lib/python3.11/site-packages/asgiref/sync.py", line 534, in thread_handler
    raise exc_info[1]
  File "/mnt/myprojects/project/mysite/venv/lib/python3.11/site-packages/django/core/handlers/base.py", line 253, in _get_response_async
    response = await wrapped_callback(
               ^^^^^^^^^^^^^^^^^^^^^^^
  File "/mnt/myprojects/project/mysite/venv/lib/python3.11/site-packages/asgiref/sync.py", line 479, in __call__
    ret: _R = await loop.run_in_executor(
              ^^^^^^^^^^^^^^^^^^^^^^^^^^^
  File "/home/kenun/.python3.11/lib/python3.11/concurrent/futures/thread.py", line 58, in run
    result = self.fn(*self.args, **self.kwargs)
             ^^^^^^^^^^^^^^^^^^^^^^^^^^^^^^^^^^
  File "/mnt/myprojects/project/mysite/venv/lib/python3.11/site-packages/asgiref/sync.py", line 538, in thread_handler
    return func(*args, **kwargs)
           ^^^^^^^^^^^^^^^^^^^^^
  File "/mnt/myprojects/project/mysite/venv/lib/python3.11/site-packages/django/views/generic/base.py", line 104, in view
    return self.dispatch(request, *args, **kwargs)
           ^^^^^^^^^^^^^^^^^^^^^^^^^^^^^^^^^^^^^^^
  File "/mnt/myprojects/project/mysite/venv/lib/python3.11/site-packages/django/views/generic/base.py", line 143, in dispatch
    return handler(request, *args, **kwargs)
           ^^^^^^^^^^^^^^^^^^^^^^^^^^^^^^^^^
  File "/mnt/myprojects/project/mysite/venv/lib/python3.11/site-packages/django/views/generic/base.py", line 226, in get
    context = self.get_context_data(**kwargs)
              ^^^^^^^^^^^^^^^^^^^^^^^^^^^^^^^
  File "/mnt/myprojects/project/mysite/addons/views.py", line 61, in get_context_data
    context['addon'] = Addon.objects.filter(slug=kwargs['addon_slug'])[0]
                       ~~~~~~~~~~~~~~~~~~~~~~~~~~~~~~~~~~~~~~~~~~~~~~~^^^
  File "/mnt/myprojects/project/mysite/venv/lib/python3.11/site-packages/django/db/models/query.py", line 450, in __getitem__
    return qs._result_cache[0]
           ~~~~~~~~~~~~~~~~^^^
IndexError: list index out of range
ERROR --- 2024-02-08 12:06:50,684 --- runserver --- runserver.py --- [35;1mHTTP GET /addons/failed 500 [0.75, 127.0.0.1:35692][0m
ERROR --- 2024-02-08 12:09:17,790 --- log --- log.py --- Internal Server Error: /addons/failed/
Traceback (most recent call last):
  File "/mnt/myprojects/project/mysite/venv/lib/python3.11/site-packages/asgiref/sync.py", line 534, in thread_handler
    raise exc_info[1]
  File "/mnt/myprojects/project/mysite/venv/lib/python3.11/site-packages/django/core/handlers/exception.py", line 42, in inner
    response = await get_response(request)
               ^^^^^^^^^^^^^^^^^^^^^^^^^^^
  File "/mnt/myprojects/project/mysite/venv/lib/python3.11/site-packages/asgiref/sync.py", line 534, in thread_handler
    raise exc_info[1]
  File "/mnt/myprojects/project/mysite/venv/lib/python3.11/site-packages/django/core/handlers/base.py", line 253, in _get_response_async
    response = await wrapped_callback(
               ^^^^^^^^^^^^^^^^^^^^^^^
  File "/mnt/myprojects/project/mysite/venv/lib/python3.11/site-packages/asgiref/sync.py", line 479, in __call__
    ret: _R = await loop.run_in_executor(
              ^^^^^^^^^^^^^^^^^^^^^^^^^^^
  File "/home/kenun/.python3.11/lib/python3.11/concurrent/futures/thread.py", line 58, in run
    result = self.fn(*self.args, **self.kwargs)
             ^^^^^^^^^^^^^^^^^^^^^^^^^^^^^^^^^^
  File "/mnt/myprojects/project/mysite/venv/lib/python3.11/site-packages/asgiref/sync.py", line 538, in thread_handler
    return func(*args, **kwargs)
           ^^^^^^^^^^^^^^^^^^^^^
  File "/mnt/myprojects/project/mysite/venv/lib/python3.11/site-packages/django/views/generic/base.py", line 104, in view
    return self.dispatch(request, *args, **kwargs)
           ^^^^^^^^^^^^^^^^^^^^^^^^^^^^^^^^^^^^^^^
  File "/mnt/myprojects/project/mysite/venv/lib/python3.11/site-packages/django/views/generic/base.py", line 143, in dispatch
    return handler(request, *args, **kwargs)
           ^^^^^^^^^^^^^^^^^^^^^^^^^^^^^^^^^
  File "/mnt/myprojects/project/mysite/venv/lib/python3.11/site-packages/django/views/generic/base.py", line 226, in get
    context = self.get_context_data(**kwargs)
              ^^^^^^^^^^^^^^^^^^^^^^^^^^^^^^^
  File "/mnt/myprojects/project/mysite/addons/views.py", line 61, in get_context_data
    context['addon'] = Addon.objects.filter(slug=kwargs['addon_slug'])[0]
                       ~~~~~~~~~~~~~~~~~~~~~~~~~~~~~~~~~~~~~~~~~~~~~~~^^^
  File "/mnt/myprojects/project/mysite/venv/lib/python3.11/site-packages/django/db/models/query.py", line 450, in __getitem__
    return qs._result_cache[0]
           ~~~~~~~~~~~~~~~~^^^
IndexError: list index out of range
ERROR --- 2024-02-08 12:09:18,547 --- runserver --- runserver.py --- [35;1mHTTP GET /addons/failed/ 500 [0.78, 127.0.0.1:40366][0m
ERROR --- 2024-02-08 12:10:18,363 --- log --- log.py --- Internal Server Error: /addons/failed/
Traceback (most recent call last):
  File "/mnt/myprojects/project/mysite/venv/lib/python3.11/site-packages/asgiref/sync.py", line 534, in thread_handler
    raise exc_info[1]
  File "/mnt/myprojects/project/mysite/venv/lib/python3.11/site-packages/django/core/handlers/exception.py", line 42, in inner
    response = await get_response(request)
               ^^^^^^^^^^^^^^^^^^^^^^^^^^^
  File "/mnt/myprojects/project/mysite/venv/lib/python3.11/site-packages/asgiref/sync.py", line 534, in thread_handler
    raise exc_info[1]
  File "/mnt/myprojects/project/mysite/venv/lib/python3.11/site-packages/django/core/handlers/base.py", line 253, in _get_response_async
    response = await wrapped_callback(
               ^^^^^^^^^^^^^^^^^^^^^^^
  File "/mnt/myprojects/project/mysite/venv/lib/python3.11/site-packages/asgiref/sync.py", line 479, in __call__
    ret: _R = await loop.run_in_executor(
              ^^^^^^^^^^^^^^^^^^^^^^^^^^^
  File "/home/kenun/.python3.11/lib/python3.11/concurrent/futures/thread.py", line 58, in run
    result = self.fn(*self.args, **self.kwargs)
             ^^^^^^^^^^^^^^^^^^^^^^^^^^^^^^^^^^
  File "/mnt/myprojects/project/mysite/venv/lib/python3.11/site-packages/asgiref/sync.py", line 538, in thread_handler
    return func(*args, **kwargs)
           ^^^^^^^^^^^^^^^^^^^^^
  File "/mnt/myprojects/project/mysite/venv/lib/python3.11/site-packages/django/views/generic/base.py", line 104, in view
    return self.dispatch(request, *args, **kwargs)
           ^^^^^^^^^^^^^^^^^^^^^^^^^^^^^^^^^^^^^^^
  File "/mnt/myprojects/project/mysite/venv/lib/python3.11/site-packages/django/views/generic/base.py", line 143, in dispatch
    return handler(request, *args, **kwargs)
           ^^^^^^^^^^^^^^^^^^^^^^^^^^^^^^^^^
  File "/mnt/myprojects/project/mysite/venv/lib/python3.11/site-packages/django/views/generic/base.py", line 226, in get
    context = self.get_context_data(**kwargs)
              ^^^^^^^^^^^^^^^^^^^^^^^^^^^^^^^
  File "/mnt/myprojects/project/mysite/addons/views.py", line 61, in get_context_data
    context['addon'] = Addon.objects.filter(slug=kwargs['addon_slug'])[0]
                       ~~~~~~~~~~~~~~~~~~~~~~~~~~~~~~~~~~~~~~~~~~~~~~~^^^
  File "/mnt/myprojects/project/mysite/venv/lib/python3.11/site-packages/django/db/models/query.py", line 450, in __getitem__
    return qs._result_cache[0]
           ~~~~~~~~~~~~~~~~^^^
IndexError: list index out of range
ERROR --- 2024-02-08 12:10:19,153 --- runserver --- runserver.py --- [35;1mHTTP GET /addons/failed/ 500 [0.81, 127.0.0.1:40366][0m
ERROR --- 2024-02-08 12:11:42,892 --- log --- log.py --- Internal Server Error: /addons/failed/
Traceback (most recent call last):
  File "/mnt/myprojects/project/mysite/venv/lib/python3.11/site-packages/asgiref/sync.py", line 534, in thread_handler
    raise exc_info[1]
  File "/mnt/myprojects/project/mysite/venv/lib/python3.11/site-packages/django/core/handlers/exception.py", line 42, in inner
    response = await get_response(request)
               ^^^^^^^^^^^^^^^^^^^^^^^^^^^
  File "/mnt/myprojects/project/mysite/venv/lib/python3.11/site-packages/asgiref/sync.py", line 534, in thread_handler
    raise exc_info[1]
  File "/mnt/myprojects/project/mysite/venv/lib/python3.11/site-packages/django/core/handlers/base.py", line 253, in _get_response_async
    response = await wrapped_callback(
               ^^^^^^^^^^^^^^^^^^^^^^^
  File "/mnt/myprojects/project/mysite/venv/lib/python3.11/site-packages/asgiref/sync.py", line 479, in __call__
    ret: _R = await loop.run_in_executor(
              ^^^^^^^^^^^^^^^^^^^^^^^^^^^
  File "/home/kenun/.python3.11/lib/python3.11/concurrent/futures/thread.py", line 58, in run
    result = self.fn(*self.args, **self.kwargs)
             ^^^^^^^^^^^^^^^^^^^^^^^^^^^^^^^^^^
  File "/mnt/myprojects/project/mysite/venv/lib/python3.11/site-packages/asgiref/sync.py", line 538, in thread_handler
    return func(*args, **kwargs)
           ^^^^^^^^^^^^^^^^^^^^^
  File "/mnt/myprojects/project/mysite/venv/lib/python3.11/site-packages/django/views/generic/base.py", line 104, in view
    return self.dispatch(request, *args, **kwargs)
           ^^^^^^^^^^^^^^^^^^^^^^^^^^^^^^^^^^^^^^^
  File "/mnt/myprojects/project/mysite/venv/lib/python3.11/site-packages/django/views/generic/base.py", line 143, in dispatch
    return handler(request, *args, **kwargs)
           ^^^^^^^^^^^^^^^^^^^^^^^^^^^^^^^^^
  File "/mnt/myprojects/project/mysite/venv/lib/python3.11/site-packages/django/views/generic/base.py", line 226, in get
    context = self.get_context_data(**kwargs)
              ^^^^^^^^^^^^^^^^^^^^^^^^^^^^^^^
  File "/mnt/myprojects/project/mysite/addons/views.py", line 61, in get_context_data
    context['addon'] = Addon.objects.filter(slug=kwargs['addon_slug'])[0]
                       ~~~~~~~~~~~~~~~~~~~~~~~~~~~~~~~~~~~~~~~~~~~~~~~^^^
  File "/mnt/myprojects/project/mysite/venv/lib/python3.11/site-packages/django/db/models/query.py", line 450, in __getitem__
    return qs._result_cache[0]
           ~~~~~~~~~~~~~~~~^^^
IndexError: list index out of range
ERROR --- 2024-02-08 12:11:43,713 --- runserver --- runserver.py --- [35;1mHTTP GET /addons/failed/?MERCHANT_ID=46130 500 [0.84, 127.0.0.1:43908][0m
WARNING --- 2024-02-08 12:18:28,884 --- log --- log.py --- Not Found: /static/admin/js/jquery.init.js
WARNING --- 2024-02-08 12:18:28,887 --- runserver --- runserver.py --- [33mHTTP GET /static/admin/js/jquery.init.js 404 [0.06, 127.0.0.1:39442][0m
WARNING --- 2024-02-08 12:18:28,887 --- log --- log.py --- Not Found: /static/admin/js/core.js
WARNING --- 2024-02-08 12:18:28,889 --- runserver --- runserver.py --- [33mHTTP GET /static/admin/js/core.js 404 [0.06, 127.0.0.1:39446][0m
WARNING --- 2024-02-08 12:18:28,891 --- log --- log.py --- Not Found: /static/admin/css/changelists.css
WARNING --- 2024-02-08 12:18:28,892 --- log --- log.py --- Not Found: /static/admin/js/vendor/jquery/jquery.min.js
WARNING --- 2024-02-08 12:18:28,894 --- log --- log.py --- Not Found: /static/admin/js/admin/RelatedObjectLookups.js
WARNING --- 2024-02-08 12:18:28,895 --- runserver --- runserver.py --- [33mHTTP GET /static/admin/css/changelists.css 404 [0.07, 127.0.0.1:53794][0m
WARNING --- 2024-02-08 12:18:28,897 --- runserver --- runserver.py --- [33mHTTP GET /static/admin/js/vendor/jquery/jquery.min.js 404 [0.07, 127.0.0.1:39434][0m
WARNING --- 2024-02-08 12:18:28,898 --- runserver --- runserver.py --- [33mHTTP GET /static/admin/js/admin/RelatedObjectLookups.js 404 [0.06, 127.0.0.1:39456][0m
WARNING --- 2024-02-08 12:18:28,914 --- log --- log.py --- Not Found: /static/admin/js/actions.js
WARNING --- 2024-02-08 12:18:28,918 --- runserver --- runserver.py --- [33mHTTP GET /static/admin/js/actions.js 404 [0.04, 127.0.0.1:53800][0m
WARNING --- 2024-02-08 12:18:28,926 --- log --- log.py --- Not Found: /static/admin/js/urlify.js
WARNING --- 2024-02-08 12:18:28,928 --- runserver --- runserver.py --- [33mHTTP GET /static/admin/js/urlify.js 404 [0.04, 127.0.0.1:39442][0m
WARNING --- 2024-02-08 12:18:28,929 --- log --- log.py --- Not Found: /static/admin/js/prepopulate.js
WARNING --- 2024-02-08 12:18:28,930 --- runserver --- runserver.py --- [33mHTTP GET /static/admin/js/prepopulate.js 404 [0.04, 127.0.0.1:39446][0m
WARNING --- 2024-02-08 12:18:28,931 --- log --- log.py --- Not Found: /static/admin/js/vendor/xregexp/xregexp.min.js
WARNING --- 2024-02-08 12:18:28,932 --- runserver --- runserver.py --- [33mHTTP GET /static/admin/js/vendor/xregexp/xregexp.min.js 404 [0.03, 127.0.0.1:53794][0m
WARNING --- 2024-02-08 12:18:28,981 --- log --- log.py --- Not Found: /static/admin/js/filters.js
WARNING --- 2024-02-08 12:18:28,982 --- runserver --- runserver.py --- [33mHTTP GET /static/admin/js/filters.js 404 [0.02, 127.0.0.1:39442][0m
WARNING --- 2024-02-08 12:18:28,983 --- log --- log.py --- Not Found: /static/admin/img/tooltag-add.svg
WARNING --- 2024-02-08 12:18:28,984 --- runserver --- runserver.py --- [33mHTTP GET /static/admin/img/tooltag-add.svg 404 [0.02, 127.0.0.1:53800][0m
WARNING --- 2024-02-08 12:18:33,329 --- log --- log.py --- Not Found: /static/admin/js/vendor/jquery/jquery.min.js
WARNING --- 2024-02-08 12:18:33,331 --- log --- log.py --- Not Found: /static/tinymce/tinymce.min.js
WARNING --- 2024-02-08 12:18:33,331 --- log --- log.py --- Not Found: /static/admin/js/jquery.init.js
WARNING --- 2024-02-08 12:18:33,331 --- log --- log.py --- Not Found: /static/admin/css/forms.css
WARNING --- 2024-02-08 12:18:33,332 --- runserver --- runserver.py --- [33mHTTP GET /static/admin/js/vendor/jquery/jquery.min.js 404 [0.04, 127.0.0.1:39456][0m
WARNING --- 2024-02-08 12:18:33,332 --- log --- log.py --- Not Found: /static/django_tinymce/init_tinymce.js
WARNING --- 2024-02-08 12:18:33,333 --- runserver --- runserver.py --- [33mHTTP GET /static/tinymce/tinymce.min.js 404 [0.05, 127.0.0.1:39434][0m
WARNING --- 2024-02-08 12:18:33,334 --- runserver --- runserver.py --- [33mHTTP GET /static/admin/js/jquery.init.js 404 [0.04, 127.0.0.1:32820][0m
WARNING --- 2024-02-08 12:18:33,335 --- runserver --- runserver.py --- [33mHTTP GET /static/admin/css/forms.css 404 [0.05, 127.0.0.1:53800][0m
WARNING --- 2024-02-08 12:18:33,337 --- runserver --- runserver.py --- [33mHTTP GET /static/django_tinymce/init_tinymce.js 404 [0.05, 127.0.0.1:32824][0m
WARNING --- 2024-02-08 12:18:33,365 --- log --- log.py --- Not Found: /static/admin/js/inlines.js
WARNING --- 2024-02-08 12:18:33,365 --- log --- log.py --- Not Found: /static/admin/js/core.js
WARNING --- 2024-02-08 12:18:33,366 --- runserver --- runserver.py --- [33mHTTP GET /static/admin/js/inlines.js 404 [0.03, 127.0.0.1:39456][0m
WARNING --- 2024-02-08 12:18:33,371 --- runserver --- runserver.py --- [33mHTTP GET /static/admin/js/core.js 404 [0.04, 127.0.0.1:39442][0m
WARNING --- 2024-02-08 12:18:33,391 --- log --- log.py --- Not Found: /static/admin/js/urlify.js
WARNING --- 2024-02-08 12:18:33,391 --- log --- log.py --- Not Found: /static/admin/js/actions.js
WARNING --- 2024-02-08 12:18:33,392 --- log --- log.py --- Not Found: /static/admin/js/admin/RelatedObjectLookups.js
WARNING --- 2024-02-08 12:18:33,392 --- log --- log.py --- Not Found: /static/admin/js/prepopulate.js
WARNING --- 2024-02-08 12:18:33,392 --- runserver --- runserver.py --- [33mHTTP GET /static/admin/js/urlify.js 404 [0.04, 127.0.0.1:32842][0m
WARNING --- 2024-02-08 12:18:33,395 --- runserver --- runserver.py --- [33mHTTP GET /static/admin/js/actions.js 404 [0.05, 127.0.0.1:32834][0m
WARNING --- 2024-02-08 12:18:33,396 --- runserver --- runserver.py --- [33mHTTP GET /static/admin/js/admin/RelatedObjectLookups.js 404 [0.05, 127.0.0.1:39434][0m
WARNING --- 2024-02-08 12:18:33,397 --- runserver --- runserver.py --- [33mHTTP GET /static/admin/js/prepopulate.js 404 [0.05, 127.0.0.1:32824][0m
WARNING --- 2024-02-08 12:18:33,404 --- log --- log.py --- Not Found: /static/admin/js/prepopulate_init.js
WARNING --- 2024-02-08 12:18:33,404 --- log --- log.py --- Not Found: /static/admin/js/vendor/xregexp/xregexp.min.js
WARNING --- 2024-02-08 12:18:33,405 --- runserver --- runserver.py --- [33mHTTP GET /static/admin/js/prepopulate_init.js 404 [0.03, 127.0.0.1:39442][0m
WARNING --- 2024-02-08 12:18:33,406 --- runserver --- runserver.py --- [33mHTTP GET /static/admin/js/vendor/xregexp/xregexp.min.js 404 [0.03, 127.0.0.1:39456][0m
WARNING --- 2024-02-08 12:18:33,436 --- log --- log.py --- Not Found: /static/admin/js/change_form.js
WARNING --- 2024-02-08 12:18:33,436 --- runserver --- runserver.py --- [33mHTTP GET /static/admin/js/change_form.js 404 [0.02, 127.0.0.1:32842][0m
WARNING --- 2024-02-08 12:18:33,444 --- log --- log.py --- Not Found: /static/admin/img/icon-deletelink.svg
WARNING --- 2024-02-08 12:18:33,444 --- runserver --- runserver.py --- [33mHTTP GET /static/admin/img/icon-deletelink.svg 404 [0.02, 127.0.0.1:32854][0m
WARNING --- 2024-02-08 12:19:09,186 --- log --- log.py --- Not Found: /static/admin/js/prepopulate.js
WARNING --- 2024-02-08 12:19:09,186 --- log --- log.py --- Not Found: /static/admin/js/jquery.init.js
WARNING --- 2024-02-08 12:19:09,187 --- log --- log.py --- Not Found: /static/admin/js/vendor/xregexp/xregexp.min.js
WARNING --- 2024-02-08 12:19:09,187 --- log --- log.py --- Not Found: /static/admin/js/actions.js
WARNING --- 2024-02-08 12:19:09,187 --- runserver --- runserver.py --- [33mHTTP GET /static/admin/js/prepopulate.js 404 [0.05, 127.0.0.1:54826][0m
WARNING --- 2024-02-08 12:19:09,187 --- log --- log.py --- Not Found: /static/admin/js/admin/RelatedObjectLookups.js
WARNING --- 2024-02-08 12:19:09,187 --- log --- log.py --- Not Found: /static/admin/js/urlify.js
WARNING --- 2024-02-08 12:19:09,189 --- runserver --- runserver.py --- [33mHTTP GET /static/admin/js/jquery.init.js 404 [0.05, 127.0.0.1:54808][0m
WARNING --- 2024-02-08 12:19:09,190 --- runserver --- runserver.py --- [33mHTTP GET /static/admin/js/vendor/xregexp/xregexp.min.js 404 [0.05, 127.0.0.1:54836][0m
WARNING --- 2024-02-08 12:19:09,191 --- runserver --- runserver.py --- [33mHTTP GET /static/admin/js/actions.js 404 [0.05, 127.0.0.1:32854][0m
WARNING --- 2024-02-08 12:19:09,192 --- runserver --- runserver.py --- [33mHTTP GET /static/admin/js/admin/RelatedObjectLookups.js 404 [0.05, 127.0.0.1:32842][0m
WARNING --- 2024-02-08 12:19:09,193 --- runserver --- runserver.py --- [33mHTTP GET /static/admin/js/urlify.js 404 [0.05, 127.0.0.1:54818][0m
WARNING --- 2024-02-08 12:19:15,523 --- log --- log.py --- Not Found: /static/admin/js/vendor/jquery/jquery.min.js
WARNING --- 2024-02-08 12:19:15,524 --- log --- log.py --- Not Found: /static/admin/js/jquery.init.js
WARNING --- 2024-02-08 12:19:15,524 --- log --- log.py --- Not Found: /static/tinymce/tinymce.min.js
WARNING --- 2024-02-08 12:19:15,525 --- runserver --- runserver.py --- [33mHTTP GET /static/admin/js/vendor/jquery/jquery.min.js 404 [0.05, 127.0.0.1:54836][0m
WARNING --- 2024-02-08 12:19:15,528 --- runserver --- runserver.py --- [33mHTTP GET /static/admin/js/jquery.init.js 404 [0.05, 127.0.0.1:54826][0m
WARNING --- 2024-02-08 12:19:15,528 --- log --- log.py --- Not Found: /static/admin/css/forms.css
WARNING --- 2024-02-08 12:19:15,529 --- runserver --- runserver.py --- [33mHTTP GET /static/tinymce/tinymce.min.js 404 [0.05, 127.0.0.1:54808][0m
WARNING --- 2024-02-08 12:19:15,531 --- log --- log.py --- Not Found: /static/django_tinymce/init_tinymce.js
WARNING --- 2024-02-08 12:19:15,531 --- runserver --- runserver.py --- [33mHTTP GET /static/admin/css/forms.css 404 [0.06, 127.0.0.1:54818][0m
WARNING --- 2024-02-08 12:19:15,534 --- runserver --- runserver.py --- [33mHTTP GET /static/django_tinymce/init_tinymce.js 404 [0.06, 127.0.0.1:60300][0m
WARNING --- 2024-02-08 12:19:15,569 --- log --- log.py --- Not Found: /static/admin/js/inlines.js
WARNING --- 2024-02-08 12:19:15,572 --- runserver --- runserver.py --- [33mHTTP GET /static/admin/js/inlines.js 404 [0.04, 127.0.0.1:54836][0m
WARNING --- 2024-02-08 12:19:15,576 --- log --- log.py --- Not Found: /static/admin/js/core.js
WARNING --- 2024-02-08 12:19:15,578 --- runserver --- runserver.py --- [33mHTTP GET /static/admin/js/core.js 404 [0.05, 127.0.0.1:32854][0m
WARNING --- 2024-02-08 12:19:15,582 --- log --- log.py --- Not Found: /static/admin/js/prepopulate.js
WARNING --- 2024-02-08 12:19:15,584 --- log --- log.py --- Not Found: /static/admin/js/urlify.js
WARNING --- 2024-02-08 12:19:15,584 --- log --- log.py --- Not Found: /static/admin/js/actions.js
WARNING --- 2024-02-08 12:19:15,584 --- log --- log.py --- Not Found: /static/admin/js/admin/RelatedObjectLookups.js
WARNING --- 2024-02-08 12:19:15,584 --- runserver --- runserver.py --- [33mHTTP GET /static/admin/js/prepopulate.js 404 [0.04, 127.0.0.1:60328][0m
WARNING --- 2024-02-08 12:19:15,586 --- runserver --- runserver.py --- [33mHTTP GET /static/admin/js/urlify.js 404 [0.04, 127.0.0.1:60316][0m
WARNING --- 2024-02-08 12:19:15,586 --- runserver --- runserver.py --- [33mHTTP GET /static/admin/js/actions.js 404 [0.04, 127.0.0.1:54808][0m
WARNING --- 2024-02-08 12:19:15,587 --- runserver --- runserver.py --- [33mHTTP GET /static/admin/js/admin/RelatedObjectLookups.js 404 [0.05, 127.0.0.1:54826][0m
WARNING --- 2024-02-08 12:19:15,604 --- log --- log.py --- Not Found: /static/admin/js/vendor/xregexp/xregexp.min.js
WARNING --- 2024-02-08 12:19:15,605 --- runserver --- runserver.py --- [33mHTTP GET /static/admin/js/vendor/xregexp/xregexp.min.js 404 [0.03, 127.0.0.1:54836][0m
WARNING --- 2024-02-08 12:19:15,606 --- log --- log.py --- Not Found: /static/admin/js/prepopulate_init.js
WARNING --- 2024-02-08 12:19:15,607 --- runserver --- runserver.py --- [33mHTTP GET /static/admin/js/prepopulate_init.js 404 [0.02, 127.0.0.1:32854][0m
WARNING --- 2024-02-08 12:19:15,639 --- log --- log.py --- Not Found: /static/admin/js/change_form.js
WARNING --- 2024-02-08 12:19:15,640 --- runserver --- runserver.py --- [33mHTTP GET /static/admin/js/change_form.js 404 [0.01, 127.0.0.1:54836][0m
WARNING --- 2024-02-08 12:19:43,408 --- log --- log.py --- Not Found: /static/admin/css/changelists.css
WARNING --- 2024-02-08 12:19:43,409 --- log --- log.py --- Not Found: /static/admin/js/admin/RelatedObjectLookups.js
WARNING --- 2024-02-08 12:19:43,412 --- log --- log.py --- Not Found: /static/admin/js/core.js
WARNING --- 2024-02-08 12:19:43,412 --- log --- log.py --- Not Found: /static/admin/js/jquery.init.js
WARNING --- 2024-02-08 12:19:43,412 --- runserver --- runserver.py --- [33mHTTP GET /static/admin/css/changelists.css 404 [0.05, 127.0.0.1:54836][0m
WARNING --- 2024-02-08 12:19:43,414 --- runserver --- runserver.py --- [33mHTTP GET /static/admin/js/admin/RelatedObjectLookups.js 404 [0.05, 127.0.0.1:60328][0m
WARNING --- 2024-02-08 12:19:43,415 --- runserver --- runserver.py --- [33mHTTP GET /static/admin/js/core.js 404 [0.05, 127.0.0.1:60316][0m
WARNING --- 2024-02-08 12:19:43,415 --- runserver --- runserver.py --- [33mHTTP GET /static/admin/js/jquery.init.js 404 [0.05, 127.0.0.1:54808][0m
WARNING --- 2024-02-08 12:19:43,418 --- log --- log.py --- Not Found: /static/admin/js/vendor/jquery/jquery.min.js
WARNING --- 2024-02-08 12:19:43,420 --- runserver --- runserver.py --- [33mHTTP GET /static/admin/js/vendor/jquery/jquery.min.js 404 [0.06, 127.0.0.1:54826][0m
WARNING --- 2024-02-08 12:19:43,445 --- log --- log.py --- Not Found: /static/admin/js/actions.js
WARNING --- 2024-02-08 12:19:43,447 --- runserver --- runserver.py --- [33mHTTP GET /static/admin/js/actions.js 404 [0.04, 127.0.0.1:32854][0m
WARNING --- 2024-02-08 12:19:43,449 --- log --- log.py --- Not Found: /static/admin/js/urlify.js
WARNING --- 2024-02-08 12:19:43,455 --- runserver --- runserver.py --- [33mHTTP GET /static/admin/js/urlify.js 404 [0.04, 127.0.0.1:54836][0m
WARNING --- 2024-02-08 12:19:43,458 --- log --- log.py --- Not Found: /static/admin/js/vendor/xregexp/xregexp.min.js
WARNING --- 2024-02-08 12:19:43,458 --- log --- log.py --- Not Found: /static/admin/js/prepopulate.js
WARNING --- 2024-02-08 12:19:43,459 --- runserver --- runserver.py --- [33mHTTP GET /static/admin/js/vendor/xregexp/xregexp.min.js 404 [0.03, 127.0.0.1:49888][0m
WARNING --- 2024-02-08 12:19:43,460 --- runserver --- runserver.py --- [33mHTTP GET /static/admin/js/prepopulate.js 404 [0.04, 127.0.0.1:60328][0m
WARNING --- 2024-02-08 12:19:43,516 --- log --- log.py --- Not Found: /static/admin/img/tooltag-add.svg
WARNING --- 2024-02-08 12:19:43,517 --- log --- log.py --- Not Found: /static/admin/js/filters.js
WARNING --- 2024-02-08 12:19:43,517 --- runserver --- runserver.py --- [33mHTTP GET /static/admin/img/tooltag-add.svg 404 [0.02, 127.0.0.1:49888][0m
WARNING --- 2024-02-08 12:19:43,518 --- runserver --- runserver.py --- [33mHTTP GET /static/admin/js/filters.js 404 [0.02, 127.0.0.1:60328][0m
WARNING --- 2024-02-08 12:20:06,847 --- log --- log.py --- Not Found: /static/admin/css/forms.css
WARNING --- 2024-02-08 12:20:06,854 --- runserver --- runserver.py --- [33mHTTP GET /static/admin/css/forms.css 404 [0.04, 127.0.0.1:60328][0m
WARNING --- 2024-02-08 12:20:06,861 --- log --- log.py --- Not Found: /static/admin/js/vendor/jquery/jquery.min.js
WARNING --- 2024-02-08 12:20:06,862 --- log --- log.py --- Not Found: /static/django_tinymce/init_tinymce.js
WARNING --- 2024-02-08 12:20:06,863 --- runserver --- runserver.py --- [33mHTTP GET /static/admin/js/vendor/jquery/jquery.min.js 404 [0.05, 127.0.0.1:54836][0m
WARNING --- 2024-02-08 12:20:06,863 --- log --- log.py --- Not Found: /static/admin/js/jquery.init.js
WARNING --- 2024-02-08 12:20:06,865 --- runserver --- runserver.py --- [33mHTTP GET /static/django_tinymce/init_tinymce.js 404 [0.04, 127.0.0.1:60854][0m
WARNING --- 2024-02-08 12:20:06,865 --- log --- log.py --- Not Found: /static/tinymce/tinymce.min.js
WARNING --- 2024-02-08 12:20:06,867 --- runserver --- runserver.py --- [33mHTTP GET /static/admin/js/jquery.init.js 404 [0.05, 127.0.0.1:54826][0m
WARNING --- 2024-02-08 12:20:06,870 --- runserver --- runserver.py --- [33mHTTP GET /static/tinymce/tinymce.min.js 404 [0.05, 127.0.0.1:32854][0m
WARNING --- 2024-02-08 12:20:06,890 --- log --- log.py --- Not Found: /static/admin/js/core.js
WARNING --- 2024-02-08 12:20:06,894 --- runserver --- runserver.py --- [33mHTTP GET /static/admin/js/core.js 404 [0.04, 127.0.0.1:49888][0m
WARNING --- 2024-02-08 12:20:06,912 --- log --- log.py --- Not Found: /static/admin/js/inlines.js
WARNING --- 2024-02-08 12:20:06,916 --- runserver --- runserver.py --- [33mHTTP GET /static/admin/js/inlines.js 404 [0.06, 127.0.0.1:60328][0m
WARNING --- 2024-02-08 12:20:06,919 --- log --- log.py --- Not Found: /static/admin/js/admin/RelatedObjectLookups.js
WARNING --- 2024-02-08 12:20:06,921 --- runserver --- runserver.py --- [33mHTTP GET /static/admin/js/admin/RelatedObjectLookups.js 404 [0.05, 127.0.0.1:54836][0m
WARNING --- 2024-02-08 12:20:06,922 --- log --- log.py --- Not Found: /static/admin/js/actions.js
WARNING --- 2024-02-08 12:20:06,922 --- log --- log.py --- Not Found: /static/admin/js/prepopulate.js
WARNING --- 2024-02-08 12:20:06,923 --- log --- log.py --- Not Found: /static/admin/js/urlify.js
WARNING --- 2024-02-08 12:20:06,924 --- runserver --- runserver.py --- [33mHTTP GET /static/admin/js/actions.js 404 [0.05, 127.0.0.1:60854][0m
WARNING --- 2024-02-08 12:20:06,925 --- runserver --- runserver.py --- [33mHTTP GET /static/admin/js/prepopulate.js 404 [0.05, 127.0.0.1:32854][0m
WARNING --- 2024-02-08 12:20:06,926 --- runserver --- runserver.py --- [33mHTTP GET /static/admin/js/urlify.js 404 [0.05, 127.0.0.1:54826][0m
WARNING --- 2024-02-08 12:20:06,930 --- log --- log.py --- Not Found: /static/admin/js/vendor/xregexp/xregexp.min.js
WARNING --- 2024-02-08 12:20:06,931 --- runserver --- runserver.py --- [33mHTTP GET /static/admin/js/vendor/xregexp/xregexp.min.js 404 [0.03, 127.0.0.1:49888][0m
WARNING --- 2024-02-08 12:20:06,970 --- log --- log.py --- Not Found: /static/admin/js/change_form.js
WARNING --- 2024-02-08 12:20:06,973 --- runserver --- runserver.py --- [33mHTTP GET /static/admin/js/change_form.js 404 [0.02, 127.0.0.1:60328][0m
WARNING --- 2024-02-08 12:20:06,975 --- log --- log.py --- Not Found: /static/admin/js/prepopulate_init.js
WARNING --- 2024-02-08 12:20:06,976 --- runserver --- runserver.py --- [33mHTTP GET /static/admin/js/prepopulate_init.js 404 [0.03, 127.0.0.1:60858][0m
WARNING --- 2024-02-08 12:20:06,977 --- log --- log.py --- Not Found: /static/admin/img/icon-deletelink.svg
WARNING --- 2024-02-08 12:20:06,978 --- runserver --- runserver.py --- [33mHTTP GET /static/admin/img/icon-deletelink.svg 404 [0.02, 127.0.0.1:60874][0m
WARNING --- 2024-02-08 12:20:34,860 --- log --- log.py --- Not Found: /static/admin/css/forms.css
WARNING --- 2024-02-08 12:20:34,861 --- log --- log.py --- Not Found: /static/admin/js/jquery.init.js
WARNING --- 2024-02-08 12:20:34,862 --- runserver --- runserver.py --- [33mHTTP GET /static/admin/css/forms.css 404 [0.07, 127.0.0.1:32818][0m
WARNING --- 2024-02-08 12:20:34,864 --- runserver --- runserver.py --- [33mHTTP GET /static/admin/js/jquery.init.js 404 [0.07, 127.0.0.1:32854][0m
WARNING --- 2024-02-08 12:20:34,865 --- log --- log.py --- Not Found: /static/tinymce/tinymce.min.js
WARNING --- 2024-02-08 12:20:34,866 --- log --- log.py --- Not Found: /static/admin/js/vendor/jquery/jquery.min.js
WARNING --- 2024-02-08 12:20:34,868 --- runserver --- runserver.py --- [33mHTTP GET /static/tinymce/tinymce.min.js 404 [0.07, 127.0.0.1:32852][0m
WARNING --- 2024-02-08 12:20:34,870 --- log --- log.py --- Not Found: /static/django_tinymce/init_tinymce.js
WARNING --- 2024-02-08 12:20:34,871 --- runserver --- runserver.py --- [33mHTTP GET /static/admin/js/vendor/jquery/jquery.min.js 404 [0.08, 127.0.0.1:32840][0m
WARNING --- 2024-02-08 12:20:34,873 --- runserver --- runserver.py --- [33mHTTP GET /static/django_tinymce/init_tinymce.js 404 [0.08, 127.0.0.1:32864][0m
WARNING --- 2024-02-08 12:20:34,886 --- log --- log.py --- Not Found: /static/admin/js/core.js
WARNING --- 2024-02-08 12:20:34,889 --- runserver --- runserver.py --- [33mHTTP GET /static/admin/js/core.js 404 [0.05, 127.0.0.1:32826][0m
WARNING --- 2024-02-08 12:20:34,910 --- log --- log.py --- Not Found: /static/admin/js/inlines.js
WARNING --- 2024-02-08 12:20:34,913 --- runserver --- runserver.py --- [33mHTTP GET /static/admin/js/inlines.js 404 [0.05, 127.0.0.1:32818][0m
WARNING --- 2024-02-08 12:20:34,917 --- log --- log.py --- Not Found: /static/admin/js/admin/RelatedObjectLookups.js
WARNING --- 2024-02-08 12:20:34,918 --- log --- log.py --- Not Found: /static/admin/js/urlify.js
WARNING --- 2024-02-08 12:20:34,919 --- log --- log.py --- Not Found: /static/admin/js/actions.js
WARNING --- 2024-02-08 12:20:34,920 --- runserver --- runserver.py --- [33mHTTP GET /static/admin/js/admin/RelatedObjectLookups.js 404 [0.05, 127.0.0.1:32854][0m
WARNING --- 2024-02-08 12:20:34,921 --- runserver --- runserver.py --- [33mHTTP GET /static/admin/js/urlify.js 404 [0.05, 127.0.0.1:32840][0m
WARNING --- 2024-02-08 12:20:34,923 --- runserver --- runserver.py --- [33mHTTP GET /static/admin/js/actions.js 404 [0.05, 127.0.0.1:32852][0m
WARNING --- 2024-02-08 12:20:34,924 --- log --- log.py --- Not Found: /static/admin/js/prepopulate.js
WARNING --- 2024-02-08 12:20:34,925 --- runserver --- runserver.py --- [33mHTTP GET /static/admin/js/prepopulate.js 404 [0.05, 127.0.0.1:32864][0m
WARNING --- 2024-02-08 12:20:34,927 --- log --- log.py --- Not Found: /static/admin/js/vendor/xregexp/xregexp.min.js
WARNING --- 2024-02-08 12:20:34,928 --- runserver --- runserver.py --- [33mHTTP GET /static/admin/js/vendor/xregexp/xregexp.min.js 404 [0.03, 127.0.0.1:32826][0m
WARNING --- 2024-02-08 12:20:34,968 --- log --- log.py --- Not Found: /static/admin/js/prepopulate_init.js
WARNING --- 2024-02-08 12:20:34,968 --- log --- log.py --- Not Found: /static/admin/js/change_form.js
WARNING --- 2024-02-08 12:20:34,970 --- runserver --- runserver.py --- [33mHTTP GET /static/admin/js/prepopulate_init.js 404 [0.02, 127.0.0.1:32872][0m
WARNING --- 2024-02-08 12:20:34,971 --- runserver --- runserver.py --- [33mHTTP GET /static/admin/js/change_form.js 404 [0.02, 127.0.0.1:32818][0m
WARNING --- 2024-02-08 12:20:37,532 --- log --- log.py --- Not Found: /static/admin/css/base.css
WARNING --- 2024-02-08 12:20:37,534 --- log --- log.py --- Not Found: /static/admin/css/nav_sidebar.css
WARNING --- 2024-02-08 12:20:37,535 --- runserver --- runserver.py --- [33mHTTP GET /static/admin/css/base.css 404 [0.05, 127.0.0.1:32818][0m
WARNING --- 2024-02-08 12:20:37,536 --- runserver --- runserver.py --- [33mHTTP GET /static/admin/css/nav_sidebar.css 404 [0.04, 127.0.0.1:32880][0m
WARNING --- 2024-02-08 12:20:37,541 --- log --- log.py --- Not Found: /static/admin/js/vendor/jquery/jquery.min.js
WARNING --- 2024-02-08 12:20:37,541 --- log --- log.py --- Not Found: /static/admin/css/forms.css
WARNING --- 2024-02-08 12:20:37,541 --- log --- log.py --- Not Found: /static/admin/css/dark_mode.css
WARNING --- 2024-02-08 12:20:37,542 --- runserver --- runserver.py --- [33mHTTP GET /static/admin/js/vendor/jquery/jquery.min.js 404 [0.05, 127.0.0.1:32910][0m
WARNING --- 2024-02-08 12:20:37,545 --- runserver --- runserver.py --- [33mHTTP GET /static/admin/css/forms.css 404 [0.05, 127.0.0.1:32892][0m
WARNING --- 2024-02-08 12:20:37,545 --- runserver --- runserver.py --- [33mHTTP GET /static/admin/css/dark_mode.css 404 [0.06, 127.0.0.1:32872][0m
WARNING --- 2024-02-08 12:20:37,586 --- log --- log.py --- Not Found: /static/tinymce/tinymce.min.js
WARNING --- 2024-02-08 12:20:37,587 --- log --- log.py --- Not Found: /static/admin/css/responsive.css
WARNING --- 2024-02-08 12:20:37,588 --- runserver --- runserver.py --- [33mHTTP GET /static/tinymce/tinymce.min.js 404 [0.04, 127.0.0.1:32880][0m
WARNING --- 2024-02-08 12:20:37,590 --- runserver --- runserver.py --- [33mHTTP GET /static/admin/css/responsive.css 404 [0.05, 127.0.0.1:32818][0m
WARNING --- 2024-02-08 12:20:37,596 --- log --- log.py --- Not Found: /static/django_tinymce/init_tinymce.js
WARNING --- 2024-02-08 12:20:37,597 --- log --- log.py --- Not Found: /static/admin/js/jquery.init.js
WARNING --- 2024-02-08 12:20:37,598 --- runserver --- runserver.py --- [33mHTTP GET /static/django_tinymce/init_tinymce.js 404 [0.05, 127.0.0.1:32910][0m
WARNING --- 2024-02-08 12:20:37,600 --- runserver --- runserver.py --- [33mHTTP GET /static/admin/js/jquery.init.js 404 [0.06, 127.0.0.1:32902][0m
WARNING --- 2024-02-08 12:20:37,605 --- log --- log.py --- Not Found: /static/admin/js/inlines.js
WARNING --- 2024-02-08 12:20:37,606 --- runserver --- runserver.py --- [33mHTTP GET /static/admin/js/inlines.js 404 [0.05, 127.0.0.1:32872][0m
WARNING --- 2024-02-08 12:20:37,609 --- log --- log.py --- Not Found: /static/admin/js/core.js
WARNING --- 2024-02-08 12:20:37,609 --- runserver --- runserver.py --- [33mHTTP GET /static/admin/js/core.js 404 [0.05, 127.0.0.1:32892][0m
WARNING --- 2024-02-08 12:20:37,619 --- log --- log.py --- Not Found: /static/admin/js/admin/RelatedObjectLookups.js
WARNING --- 2024-02-08 12:20:37,621 --- runserver --- runserver.py --- [33mHTTP GET /static/admin/js/admin/RelatedObjectLookups.js 404 [0.03, 127.0.0.1:32880][0m
WARNING --- 2024-02-08 12:20:37,623 --- log --- log.py --- Not Found: /static/admin/js/actions.js
WARNING --- 2024-02-08 12:20:37,623 --- runserver --- runserver.py --- [33mHTTP GET /static/admin/js/actions.js 404 [0.03, 127.0.0.1:32818][0m
WARNING --- 2024-02-08 12:20:37,672 --- log --- log.py --- Not Found: /static/admin/js/prepopulate.js
WARNING --- 2024-02-08 12:20:37,672 --- log --- log.py --- Not Found: /static/admin/img/icon-addlink.svg
WARNING --- 2024-02-08 12:20:37,673 --- log --- log.py --- Not Found: /static/admin/js/urlify.js
WARNING --- 2024-02-08 12:20:37,673 --- log --- log.py --- Not Found: /static/admin/js/vendor/xregexp/xregexp.min.js
WARNING --- 2024-02-08 12:20:37,673 --- log --- log.py --- Not Found: /static/admin/js/prepopulate_init.js
WARNING --- 2024-02-08 12:20:37,674 --- runserver --- runserver.py --- [33mHTTP GET /static/admin/js/prepopulate.js 404 [0.03, 127.0.0.1:32926][0m
WARNING --- 2024-02-08 12:20:37,675 --- runserver --- runserver.py --- [33mHTTP GET /static/admin/img/icon-addlink.svg 404 [0.03, 127.0.0.1:32954][0m
WARNING --- 2024-02-08 12:20:37,675 --- runserver --- runserver.py --- [33mHTTP GET /static/admin/js/urlify.js 404 [0.04, 127.0.0.1:32910][0m
WARNING --- 2024-02-08 12:20:37,676 --- runserver --- runserver.py --- [33mHTTP GET /static/admin/js/vendor/xregexp/xregexp.min.js 404 [0.04, 127.0.0.1:32942][0m
WARNING --- 2024-02-08 12:20:37,677 --- runserver --- runserver.py --- [33mHTTP GET /static/admin/js/prepopulate_init.js 404 [0.04, 127.0.0.1:32958][0m
WARNING --- 2024-02-08 12:20:37,724 --- log --- log.py --- Not Found: /static/admin/css/responsive.css
WARNING --- 2024-02-08 12:20:37,725 --- log --- log.py --- Not Found: /static/admin/img/icon-addlink.svg
WARNING --- 2024-02-08 12:20:37,725 --- log --- log.py --- Not Found: /static/admin/js/theme.js
WARNING --- 2024-02-08 12:20:37,725 --- log --- log.py --- Not Found: /static/admin/js/change_form.js
WARNING --- 2024-02-08 12:20:37,726 --- runserver --- runserver.py --- [33mHTTP GET /static/admin/css/responsive.css 404 [0.04, 127.0.0.1:32954][0m
WARNING --- 2024-02-08 12:20:37,727 --- runserver --- runserver.py --- [33mHTTP GET /static/admin/img/icon-addlink.svg 404 [0.04, 127.0.0.1:32964][0m
WARNING --- 2024-02-08 12:20:37,728 --- runserver --- runserver.py --- [33mHTTP GET /static/admin/js/theme.js 404 [0.04, 127.0.0.1:32926][0m
WARNING --- 2024-02-08 12:20:37,728 --- runserver --- runserver.py --- [33mHTTP GET /static/admin/js/change_form.js 404 [0.04, 127.0.0.1:32962][0m
WARNING --- 2024-02-08 12:20:37,730 --- log --- log.py --- Not Found: /static/admin/js/nav_sidebar.js
WARNING --- 2024-02-08 12:20:37,731 --- runserver --- runserver.py --- [33mHTTP GET /static/admin/js/nav_sidebar.js 404 [0.04, 127.0.0.1:32958][0m
WARNING --- 2024-02-08 12:20:37,940 --- log --- log.py --- Not Found: /favicon.ico
WARNING --- 2024-02-08 12:20:37,941 --- runserver --- runserver.py --- [33mHTTP GET /favicon.ico 404 [0.02, 127.0.0.1:32962][0m
WARNING --- 2024-02-08 12:20:40,849 --- log --- log.py --- Not Found: /static/admin/css/base.css
WARNING --- 2024-02-08 12:20:40,855 --- runserver --- runserver.py --- [33mHTTP GET /static/admin/css/base.css 404 [0.05, 127.0.0.1:32962][0m
WARNING --- 2024-02-08 12:20:40,859 --- log --- log.py --- Not Found: /static/admin/css/dark_mode.css
WARNING --- 2024-02-08 12:20:40,859 --- log --- log.py --- Not Found: /static/admin/css/forms.css
WARNING --- 2024-02-08 12:20:40,859 --- log --- log.py --- Not Found: /static/admin/js/vendor/jquery/jquery.min.js
WARNING --- 2024-02-08 12:20:40,861 --- runserver --- runserver.py --- [33mHTTP GET /static/admin/css/dark_mode.css 404 [0.06, 127.0.0.1:32964][0m
WARNING --- 2024-02-08 12:20:40,864 --- runserver --- runserver.py --- [33mHTTP GET /static/admin/css/forms.css 404 [0.06, 127.0.0.1:45374][0m
WARNING --- 2024-02-08 12:20:40,865 --- runserver --- runserver.py --- [33mHTTP GET /static/admin/js/vendor/jquery/jquery.min.js 404 [0.06, 127.0.0.1:45396][0m
WARNING --- 2024-02-08 12:20:40,868 --- log --- log.py --- Not Found: /static/admin/css/nav_sidebar.css
WARNING --- 2024-02-08 12:20:40,870 --- runserver --- runserver.py --- [33mHTTP GET /static/admin/css/nav_sidebar.css 404 [0.07, 127.0.0.1:32954][0m
WARNING --- 2024-02-08 12:20:40,912 --- log --- log.py --- Not Found: /static/tinymce/tinymce.min.js
WARNING --- 2024-02-08 12:20:40,912 --- log --- log.py --- Not Found: /static/admin/css/responsive.css
WARNING --- 2024-02-08 12:20:40,913 --- log --- log.py --- Not Found: /static/admin/js/jquery.init.js
WARNING --- 2024-02-08 12:20:40,914 --- runserver --- runserver.py --- [33mHTTP GET /static/tinymce/tinymce.min.js 404 [0.05, 127.0.0.1:32962][0m
WARNING --- 2024-02-08 12:20:40,918 --- runserver --- runserver.py --- [33mHTTP GET /static/admin/css/responsive.css 404 [0.06, 127.0.0.1:45382][0m
WARNING --- 2024-02-08 12:20:40,919 --- runserver --- runserver.py --- [33mHTTP GET /static/admin/js/jquery.init.js 404 [0.05, 127.0.0.1:32964][0m
WARNING --- 2024-02-08 12:20:40,926 --- log --- log.py --- Not Found: /static/admin/js/inlines.js
WARNING --- 2024-02-08 12:20:40,926 --- log --- log.py --- Not Found: /static/admin/js/core.js
WARNING --- 2024-02-08 12:20:40,927 --- log --- log.py --- Not Found: /static/django_tinymce/init_tinymce.js
WARNING --- 2024-02-08 12:20:40,928 --- runserver --- runserver.py --- [33mHTTP GET /static/admin/js/inlines.js 404 [0.05, 127.0.0.1:32954][0m
WARNING --- 2024-02-08 12:20:40,929 --- runserver --- runserver.py --- [33mHTTP GET /static/admin/js/core.js 404 [0.05, 127.0.0.1:45396][0m
WARNING --- 2024-02-08 12:20:40,930 --- runserver --- runserver.py --- [33mHTTP GET /static/django_tinymce/init_tinymce.js 404 [0.05, 127.0.0.1:45374][0m
WARNING --- 2024-02-08 12:20:40,939 --- log --- log.py --- Not Found: /static/admin/js/admin/RelatedObjectLookups.js
WARNING --- 2024-02-08 12:20:40,940 --- runserver --- runserver.py --- [33mHTTP GET /static/admin/js/admin/RelatedObjectLookups.js 404 [0.02, 127.0.0.1:32962][0m
WARNING --- 2024-02-08 12:20:41,004 --- log --- log.py --- Not Found: /static/admin/js/prepopulate.js
WARNING --- 2024-02-08 12:20:41,006 --- runserver --- runserver.py --- [33mHTTP GET /static/admin/js/prepopulate.js 404 [0.04, 127.0.0.1:45418][0m
WARNING --- 2024-02-08 12:20:41,006 --- log --- log.py --- Not Found: /static/admin/js/actions.js
WARNING --- 2024-02-08 12:20:41,007 --- log --- log.py --- Not Found: /static/admin/img/icon-addlink.svg
WARNING --- 2024-02-08 12:20:41,007 --- log --- log.py --- Not Found: /static/admin/js/vendor/xregexp/xregexp.min.js
WARNING --- 2024-02-08 12:20:41,008 --- runserver --- runserver.py --- [33mHTTP GET /static/admin/js/actions.js 404 [0.04, 127.0.0.1:45382][0m
WARNING --- 2024-02-08 12:20:41,008 --- log --- log.py --- Not Found: /static/admin/js/urlify.js
WARNING --- 2024-02-08 12:20:41,010 --- runserver --- runserver.py --- [33mHTTP GET /static/admin/img/icon-addlink.svg 404 [0.04, 127.0.0.1:45446][0m
WARNING --- 2024-02-08 12:20:41,010 --- log --- log.py --- Not Found: /static/admin/js/prepopulate_init.js
WARNING --- 2024-02-08 12:20:41,011 --- runserver --- runserver.py --- [33mHTTP GET /static/admin/js/vendor/xregexp/xregexp.min.js 404 [0.05, 127.0.0.1:45434][0m
WARNING --- 2024-02-08 12:20:41,014 --- runserver --- runserver.py --- [33mHTTP GET /static/admin/js/urlify.js 404 [0.05, 127.0.0.1:45406][0m
WARNING --- 2024-02-08 12:20:41,015 --- runserver --- runserver.py --- [33mHTTP GET /static/admin/js/prepopulate_init.js 404 [0.05, 127.0.0.1:45452][0m
WARNING --- 2024-02-08 12:20:41,060 --- log --- log.py --- Not Found: /static/admin/js/change_form.js
WARNING --- 2024-02-08 12:20:41,061 --- log --- log.py --- Not Found: /static/admin/js/nav_sidebar.js
WARNING --- 2024-02-08 12:20:41,061 --- log --- log.py --- Not Found: /static/admin/js/theme.js
WARNING --- 2024-02-08 12:20:41,061 --- log --- log.py --- Not Found: /static/admin/img/icon-addlink.svg
WARNING --- 2024-02-08 12:20:41,062 --- runserver --- runserver.py --- [33mHTTP GET /static/admin/js/change_form.js 404 [0.04, 127.0.0.1:45418][0m
WARNING --- 2024-02-08 12:20:41,063 --- log --- log.py --- Not Found: /static/admin/css/responsive.css
WARNING --- 2024-02-08 12:20:41,064 --- runserver --- runserver.py --- [33mHTTP GET /static/admin/js/nav_sidebar.js 404 [0.04, 127.0.0.1:45382][0m
WARNING --- 2024-02-08 12:20:41,064 --- runserver --- runserver.py --- [33mHTTP GET /static/admin/js/theme.js 404 [0.04, 127.0.0.1:45434][0m
WARNING --- 2024-02-08 12:20:41,065 --- runserver --- runserver.py --- [33mHTTP GET /static/admin/img/icon-addlink.svg 404 [0.04, 127.0.0.1:45468][0m
WARNING --- 2024-02-08 12:20:41,067 --- runserver --- runserver.py --- [33mHTTP GET /static/admin/css/responsive.css 404 [0.04, 127.0.0.1:45446][0m
WARNING --- 2024-02-08 12:26:07,897 --- runserver --- runserver.py --- [33mHTTP POST /static/tinymce/plugins/spellchecker/ 404 [0.02, 127.0.0.1:47112][0m
WARNING --- 2024-02-08 12:28:11,538 --- log --- log.py --- Not Found: /favicon.ico
WARNING --- 2024-02-08 12:28:11,539 --- runserver --- runserver.py --- [33mHTTP GET /favicon.ico 404 [0.02, 127.0.0.1:46232][0m
WARNING --- 2024-02-08 12:31:34,725 --- log --- log.py --- Not Found: /favicon.ico
WARNING --- 2024-02-08 12:31:34,726 --- runserver --- runserver.py --- [33mHTTP GET /favicon.ico 404 [0.02, 127.0.0.1:52828][0m
WARNING --- 2024-02-08 23:36:50,123 --- log --- log.py --- Not Found: /favicon.ico
WARNING --- 2024-02-08 23:36:50,135 --- runserver --- runserver.py --- [33mHTTP GET /favicon.ico 404 [0.09, 127.0.0.1:36918][0m
ERROR --- 2024-02-09 13:36:04,294 --- log --- log.py --- Internal Server Error: /flower/
Traceback (most recent call last):
  File "/mnt/myprojects/project/mysite/venv/lib/python3.11/site-packages/urllib3/connection.py", line 203, in _new_conn
    sock = connection.create_connection(
           ^^^^^^^^^^^^^^^^^^^^^^^^^^^^^
  File "/mnt/myprojects/project/mysite/venv/lib/python3.11/site-packages/urllib3/util/connection.py", line 85, in create_connection
    raise err
  File "/mnt/myprojects/project/mysite/venv/lib/python3.11/site-packages/urllib3/util/connection.py", line 73, in create_connection
    sock.connect(sa)
ConnectionRefusedError: [Errno 111] Connection refused

The above exception was the direct cause of the following exception:

Traceback (most recent call last):
  File "/mnt/myprojects/project/mysite/venv/lib/python3.11/site-packages/urllib3/connectionpool.py", line 791, in urlopen
    response = self._make_request(
               ^^^^^^^^^^^^^^^^^^^
  File "/mnt/myprojects/project/mysite/venv/lib/python3.11/site-packages/urllib3/connectionpool.py", line 497, in _make_request
    conn.request(
  File "/mnt/myprojects/project/mysite/venv/lib/python3.11/site-packages/urllib3/connection.py", line 395, in request
    self.endheaders()
  File "/home/kenun/.python3.11/lib/python3.11/http/client.py", line 1289, in endheaders
    self._send_output(message_body, encode_chunked=encode_chunked)
  File "/home/kenun/.python3.11/lib/python3.11/http/client.py", line 1048, in _send_output
    self.send(msg)
  File "/home/kenun/.python3.11/lib/python3.11/http/client.py", line 986, in send
    self.connect()
  File "/mnt/myprojects/project/mysite/venv/lib/python3.11/site-packages/urllib3/connection.py", line 243, in connect
    self.sock = self._new_conn()
                ^^^^^^^^^^^^^^^^
  File "/mnt/myprojects/project/mysite/venv/lib/python3.11/site-packages/urllib3/connection.py", line 218, in _new_conn
    raise NewConnectionError(
urllib3.exceptions.NewConnectionError: <urllib3.connection.HTTPConnection object at 0x7f4bf0784390>: Failed to establish a new connection: [Errno 111] Connection refused

The above exception was the direct cause of the following exception:

Traceback (most recent call last):
  File "/mnt/myprojects/project/mysite/venv/lib/python3.11/site-packages/requests/adapters.py", line 486, in send
    resp = conn.urlopen(
           ^^^^^^^^^^^^^
  File "/mnt/myprojects/project/mysite/venv/lib/python3.11/site-packages/urllib3/connectionpool.py", line 845, in urlopen
    retries = retries.increment(
              ^^^^^^^^^^^^^^^^^^
  File "/mnt/myprojects/project/mysite/venv/lib/python3.11/site-packages/urllib3/util/retry.py", line 515, in increment
    raise MaxRetryError(_pool, url, reason) from reason  # type: ignore[arg-type]
    ^^^^^^^^^^^^^^^^^^^^^^^^^^^^^^^^^^^^^^^^^^^^^^^^^^^
urllib3.exceptions.MaxRetryError: HTTPConnectionPool(host='127.0.0.1', port=5555): Max retries exceeded with url: /flower/ (Caused by NewConnectionError('<urllib3.connection.HTTPConnection object at 0x7f4bf0784390>: Failed to establish a new connection: [Errno 111] Connection refused'))

During handling of the above exception, another exception occurred:

Traceback (most recent call last):
  File "/mnt/myprojects/project/mysite/venv/lib/python3.11/site-packages/asgiref/sync.py", line 534, in thread_handler
    raise exc_info[1]
  File "/mnt/myprojects/project/mysite/venv/lib/python3.11/site-packages/django/core/handlers/exception.py", line 42, in inner
    response = await get_response(request)
               ^^^^^^^^^^^^^^^^^^^^^^^^^^^
  File "/mnt/myprojects/project/mysite/venv/lib/python3.11/site-packages/asgiref/sync.py", line 534, in thread_handler
    raise exc_info[1]
  File "/mnt/myprojects/project/mysite/venv/lib/python3.11/site-packages/django/core/handlers/base.py", line 253, in _get_response_async
    response = await wrapped_callback(
               ^^^^^^^^^^^^^^^^^^^^^^^
  File "/mnt/myprojects/project/mysite/venv/lib/python3.11/site-packages/asgiref/sync.py", line 479, in __call__
    ret: _R = await loop.run_in_executor(
              ^^^^^^^^^^^^^^^^^^^^^^^^^^^
  File "/home/kenun/.python3.11/lib/python3.11/concurrent/futures/thread.py", line 58, in run
    result = self.fn(*self.args, **self.kwargs)
             ^^^^^^^^^^^^^^^^^^^^^^^^^^^^^^^^^^
  File "/mnt/myprojects/project/mysite/venv/lib/python3.11/site-packages/asgiref/sync.py", line 538, in thread_handler
    return func(*args, **kwargs)
           ^^^^^^^^^^^^^^^^^^^^^
  File "/mnt/myprojects/project/mysite/venv/lib/python3.11/site-packages/django/views/decorators/csrf.py", line 56, in wrapper_view
    return view_func(*args, **kwargs)
           ^^^^^^^^^^^^^^^^^^^^^^^^^^
  File "/mnt/myprojects/project/mysite/HomePage/views.py", line 151, in flower_proxy_view
    return proxy_view(
           ^^^^^^^^^^^
  File "/mnt/myprojects/project/mysite/venv/lib/python3.11/site-packages/proxy/views.py", line 45, in proxy_view
    response = requests.request(request.method, url, **requests_args)
               ^^^^^^^^^^^^^^^^^^^^^^^^^^^^^^^^^^^^^^^^^^^^^^^^^^^^^^
  File "/mnt/myprojects/project/mysite/venv/lib/python3.11/site-packages/requests/api.py", line 59, in request
    return session.request(method=method, url=url, **kwargs)
           ^^^^^^^^^^^^^^^^^^^^^^^^^^^^^^^^^^^^^^^^^^^^^^^^^
  File "/mnt/myprojects/project/mysite/venv/lib/python3.11/site-packages/requests/sessions.py", line 589, in request
    resp = self.send(prep, **send_kwargs)
           ^^^^^^^^^^^^^^^^^^^^^^^^^^^^^^
  File "/mnt/myprojects/project/mysite/venv/lib/python3.11/site-packages/requests/sessions.py", line 703, in send
    r = adapter.send(request, **kwargs)
        ^^^^^^^^^^^^^^^^^^^^^^^^^^^^^^^
  File "/mnt/myprojects/project/mysite/venv/lib/python3.11/site-packages/requests/adapters.py", line 519, in send
    raise ConnectionError(e, request=request)
requests.exceptions.ConnectionError: HTTPConnectionPool(host='127.0.0.1', port=5555): Max retries exceeded with url: /flower/ (Caused by NewConnectionError('<urllib3.connection.HTTPConnection object at 0x7f4bf0784390>: Failed to establish a new connection: [Errno 111] Connection refused'))
ERROR --- 2024-02-09 13:36:05,306 --- runserver --- runserver.py --- [35;1mHTTP GET /flower/ 500 [1.22, 127.0.0.1:33952][0m
WARNING --- 2024-02-09 13:39:39,018 --- log --- log.py --- Forbidden (Permission denied): /flower/
Traceback (most recent call last):
  File "/mnt/myprojects/project/mysite/venv/lib/python3.11/site-packages/asgiref/sync.py", line 534, in thread_handler
    raise exc_info[1]
  File "/mnt/myprojects/project/mysite/venv/lib/python3.11/site-packages/django/core/handlers/exception.py", line 42, in inner
    response = await get_response(request)
               ^^^^^^^^^^^^^^^^^^^^^^^^^^^
  File "/mnt/myprojects/project/mysite/venv/lib/python3.11/site-packages/asgiref/sync.py", line 534, in thread_handler
    raise exc_info[1]
  File "/mnt/myprojects/project/mysite/venv/lib/python3.11/site-packages/django/core/handlers/base.py", line 253, in _get_response_async
    response = await wrapped_callback(
               ^^^^^^^^^^^^^^^^^^^^^^^
  File "/mnt/myprojects/project/mysite/venv/lib/python3.11/site-packages/asgiref/sync.py", line 479, in __call__
    ret: _R = await loop.run_in_executor(
              ^^^^^^^^^^^^^^^^^^^^^^^^^^^
  File "/home/kenun/.python3.11/lib/python3.11/concurrent/futures/thread.py", line 58, in run
    result = self.fn(*self.args, **self.kwargs)
             ^^^^^^^^^^^^^^^^^^^^^^^^^^^^^^^^^^
  File "/mnt/myprojects/project/mysite/venv/lib/python3.11/site-packages/asgiref/sync.py", line 538, in thread_handler
    return func(*args, **kwargs)
           ^^^^^^^^^^^^^^^^^^^^^
  File "/mnt/myprojects/project/mysite/venv/lib/python3.11/site-packages/django/views/decorators/csrf.py", line 56, in wrapper_view
    return view_func(*args, **kwargs)
           ^^^^^^^^^^^^^^^^^^^^^^^^^^
  File "/mnt/myprojects/project/mysite/HomePage/views.py", line 150, in flower_proxy_view
    if not request.user.is_superuser: raise PermissionDenied
                                      ^^^^^^^^^^^^^^^^^^^^^^
django.core.exceptions.PermissionDenied
WARNING --- 2024-02-09 13:39:39,021 --- runserver --- runserver.py --- [31;1mHTTP GET /flower/ 403 [0.02, 127.0.0.1:37702][0m
WARNING --- 2024-02-09 13:39:51,135 --- log --- log.py --- Not Found: /flowet
WARNING --- 2024-02-09 13:39:51,136 --- runserver --- runserver.py --- [33mHTTP GET /flowet 404 [0.02, 127.0.0.1:37702][0m
ERROR --- 2024-02-09 13:40:08,719 --- log --- log.py --- Internal Server Error: /flower/
Traceback (most recent call last):
  File "/mnt/myprojects/project/mysite/venv/lib/python3.11/site-packages/urllib3/connection.py", line 203, in _new_conn
    sock = connection.create_connection(
           ^^^^^^^^^^^^^^^^^^^^^^^^^^^^^
  File "/mnt/myprojects/project/mysite/venv/lib/python3.11/site-packages/urllib3/util/connection.py", line 85, in create_connection
    raise err
  File "/mnt/myprojects/project/mysite/venv/lib/python3.11/site-packages/urllib3/util/connection.py", line 73, in create_connection
    sock.connect(sa)
ConnectionRefusedError: [Errno 111] Connection refused

The above exception was the direct cause of the following exception:

Traceback (most recent call last):
  File "/mnt/myprojects/project/mysite/venv/lib/python3.11/site-packages/urllib3/connectionpool.py", line 791, in urlopen
    response = self._make_request(
               ^^^^^^^^^^^^^^^^^^^
  File "/mnt/myprojects/project/mysite/venv/lib/python3.11/site-packages/urllib3/connectionpool.py", line 497, in _make_request
    conn.request(
  File "/mnt/myprojects/project/mysite/venv/lib/python3.11/site-packages/urllib3/connection.py", line 395, in request
    self.endheaders()
  File "/home/kenun/.python3.11/lib/python3.11/http/client.py", line 1289, in endheaders
    self._send_output(message_body, encode_chunked=encode_chunked)
  File "/home/kenun/.python3.11/lib/python3.11/http/client.py", line 1048, in _send_output
    self.send(msg)
  File "/home/kenun/.python3.11/lib/python3.11/http/client.py", line 986, in send
    self.connect()
  File "/mnt/myprojects/project/mysite/venv/lib/python3.11/site-packages/urllib3/connection.py", line 243, in connect
    self.sock = self._new_conn()
                ^^^^^^^^^^^^^^^^
  File "/mnt/myprojects/project/mysite/venv/lib/python3.11/site-packages/urllib3/connection.py", line 218, in _new_conn
    raise NewConnectionError(
urllib3.exceptions.NewConnectionError: <urllib3.connection.HTTPConnection object at 0x7f4bf07b6b90>: Failed to establish a new connection: [Errno 111] Connection refused

The above exception was the direct cause of the following exception:

Traceback (most recent call last):
  File "/mnt/myprojects/project/mysite/venv/lib/python3.11/site-packages/requests/adapters.py", line 486, in send
    resp = conn.urlopen(
           ^^^^^^^^^^^^^
  File "/mnt/myprojects/project/mysite/venv/lib/python3.11/site-packages/urllib3/connectionpool.py", line 845, in urlopen
    retries = retries.increment(
              ^^^^^^^^^^^^^^^^^^
  File "/mnt/myprojects/project/mysite/venv/lib/python3.11/site-packages/urllib3/util/retry.py", line 515, in increment
    raise MaxRetryError(_pool, url, reason) from reason  # type: ignore[arg-type]
    ^^^^^^^^^^^^^^^^^^^^^^^^^^^^^^^^^^^^^^^^^^^^^^^^^^^
urllib3.exceptions.MaxRetryError: HTTPConnectionPool(host='127.0.0.1', port=5555): Max retries exceeded with url: /flower/ (Caused by NewConnectionError('<urllib3.connection.HTTPConnection object at 0x7f4bf07b6b90>: Failed to establish a new connection: [Errno 111] Connection refused'))

During handling of the above exception, another exception occurred:

Traceback (most recent call last):
  File "/mnt/myprojects/project/mysite/venv/lib/python3.11/site-packages/asgiref/sync.py", line 534, in thread_handler
    raise exc_info[1]
  File "/mnt/myprojects/project/mysite/venv/lib/python3.11/site-packages/django/core/handlers/exception.py", line 42, in inner
    response = await get_response(request)
               ^^^^^^^^^^^^^^^^^^^^^^^^^^^
  File "/mnt/myprojects/project/mysite/venv/lib/python3.11/site-packages/asgiref/sync.py", line 534, in thread_handler
    raise exc_info[1]
  File "/mnt/myprojects/project/mysite/venv/lib/python3.11/site-packages/django/core/handlers/base.py", line 253, in _get_response_async
    response = await wrapped_callback(
               ^^^^^^^^^^^^^^^^^^^^^^^
  File "/mnt/myprojects/project/mysite/venv/lib/python3.11/site-packages/asgiref/sync.py", line 479, in __call__
    ret: _R = await loop.run_in_executor(
              ^^^^^^^^^^^^^^^^^^^^^^^^^^^
  File "/home/kenun/.python3.11/lib/python3.11/concurrent/futures/thread.py", line 58, in run
    result = self.fn(*self.args, **self.kwargs)
             ^^^^^^^^^^^^^^^^^^^^^^^^^^^^^^^^^^
  File "/mnt/myprojects/project/mysite/venv/lib/python3.11/site-packages/asgiref/sync.py", line 538, in thread_handler
    return func(*args, **kwargs)
           ^^^^^^^^^^^^^^^^^^^^^
  File "/mnt/myprojects/project/mysite/venv/lib/python3.11/site-packages/django/views/decorators/csrf.py", line 56, in wrapper_view
    return view_func(*args, **kwargs)
           ^^^^^^^^^^^^^^^^^^^^^^^^^^
  File "/mnt/myprojects/project/mysite/HomePage/views.py", line 151, in flower_proxy_view
    return proxy_view(
           ^^^^^^^^^^^
  File "/mnt/myprojects/project/mysite/venv/lib/python3.11/site-packages/proxy/views.py", line 45, in proxy_view
    response = requests.request(request.method, url, **requests_args)
               ^^^^^^^^^^^^^^^^^^^^^^^^^^^^^^^^^^^^^^^^^^^^^^^^^^^^^^
  File "/mnt/myprojects/project/mysite/venv/lib/python3.11/site-packages/requests/api.py", line 59, in request
    return session.request(method=method, url=url, **kwargs)
           ^^^^^^^^^^^^^^^^^^^^^^^^^^^^^^^^^^^^^^^^^^^^^^^^^
  File "/mnt/myprojects/project/mysite/venv/lib/python3.11/site-packages/requests/sessions.py", line 589, in request
    resp = self.send(prep, **send_kwargs)
           ^^^^^^^^^^^^^^^^^^^^^^^^^^^^^^
  File "/mnt/myprojects/project/mysite/venv/lib/python3.11/site-packages/requests/sessions.py", line 703, in send
    r = adapter.send(request, **kwargs)
        ^^^^^^^^^^^^^^^^^^^^^^^^^^^^^^^
  File "/mnt/myprojects/project/mysite/venv/lib/python3.11/site-packages/requests/adapters.py", line 519, in send
    raise ConnectionError(e, request=request)
requests.exceptions.ConnectionError: HTTPConnectionPool(host='127.0.0.1', port=5555): Max retries exceeded with url: /flower/ (Caused by NewConnectionError('<urllib3.connection.HTTPConnection object at 0x7f4bf07b6b90>: Failed to establish a new connection: [Errno 111] Connection refused'))
ERROR --- 2024-02-09 13:40:09,737 --- runserver --- runserver.py --- [35;1mHTTP GET /flower/ 500 [1.15, 127.0.0.1:37702][0m
WARNING --- 2024-02-09 13:40:14,726 --- log --- log.py --- Not Found: /flower/
WARNING --- 2024-02-09 13:40:14,727 --- runserver --- runserver.py --- [33mHTTP GET /flower/ 404 [0.12, 127.0.0.1:37702][0m
WARNING --- 2024-02-09 13:40:15,000 --- runserver --- runserver.py --- [33mHTTP GET /static/css/bootstrap.min.css?v=eea261d9b89e1738193c9f9b06196592b31a87daee9aaec45629e54645e460853a40ad27b3860a83b2c0b65c3ebb2b039371a4fb42a1aa592695d33e74be6dd1 404 [0.04, 127.0.0.1:37702][0m
WARNING --- 2024-02-09 13:40:15,002 --- runserver --- runserver.py --- [33mHTTP GET /static/css/datatables-1.13.4.min.css?v=74c4a6b553604403588edd63769db7dfbaf4c22cb68aba292a93e02ac283a6136e686b2fd7502a7816f160fae558412a7c877b81fd557298f07b32e026739559 404 [0.04, 127.0.0.1:37710][0m
WARNING --- 2024-02-09 13:40:15,004 --- runserver --- runserver.py --- [33mHTTP GET /static/js/datatables-1.13.4.min.js?v=545b043132ca7e6d31fa9428dda427f4116732de8b19face781a8aa2372265d1f22fa1ed5e54428899170459577732a98c15bafb6663c40fcf11bb770d896b59 404 [0.04, 127.0.0.1:41008][0m
WARNING --- 2024-02-09 13:40:15,005 --- runserver --- runserver.py --- [33mHTTP GET /static/css/flower.css?v=cb65558ddda9a029f1ef92d591aec21646e1c50225c1f94f6ba79686bd6690f029b56fd21aef9a8a7b9e2c069bf113decaae7ee1098f33132619f22f47124415 404 [0.04, 127.0.0.1:40980][0m
WARNING --- 2024-02-09 13:40:15,006 --- runserver --- runserver.py --- [33mHTTP GET /static/js/jquery-3.6.4.min.js?v=a6e981b23351186aa43f32879dd64c6801be6e2af7ef8b0e472cccdeeba52d5d7894de4bcb292a364f1e11e525524077534338140a72687ada4fae62849843a5 404 [0.04, 127.0.0.1:41002][0m
WARNING --- 2024-02-09 13:40:15,007 --- runserver --- runserver.py --- [33mHTTP GET /static/js/bootstrap.bundle.min.js?v=d159d8395c8a2c53390808d1b696929be19b9974d6feff72904b069004583f469ac5a352608ead49e396f36e5a312b4a8c50708be2e041f47613a3e03d344ba9 404 [0.04, 127.0.0.1:40990][0m
WARNING --- 2024-02-09 13:40:15,028 --- runserver --- runserver.py --- [33mHTTP GET /static/js/moment-2.29.4.min.js?v=0abc8a6cc7bbb234820cf975f23b492390d1e63b64516c4f5d668b0acb7a4231fcc310dec5f44989cd964664579acb6bd98f12c430d6b813ba0900ba204e0a4c 404 [0.02, 127.0.0.1:37710][0m
WARNING --- 2024-02-09 13:40:15,030 --- runserver --- runserver.py --- [33mHTTP GET /static/js/moment-timezone-with-data-2.29.4.min.js?v=28223e7d1ddb51b39c534642dd471a3f008bb8ee4b124ba469605875d9a12cf5e0a403d627c8faa492e64c8eadf42318733138602ad6650ff0ad9cff26cc82f8 404 [0.02, 127.0.0.1:37702][0m
WARNING --- 2024-02-09 13:40:15,039 --- runserver --- runserver.py --- [33mHTTP GET /static/favicon.ico?v=ff1ba46e61b7e034e9ce38326f398a2b86c222a137e2eb96a3ea16c77300d423d6ebf0cc8d4ac73d95087e6114ef8e13fa52fa5b6f9fadc0b5d1a9e3680015b8 404 [0.02, 127.0.0.1:41002][0m
WARNING --- 2024-02-09 13:40:15,041 --- runserver --- runserver.py --- [33mHTTP GET /static/js/flower.js?v=5ef89e36a054bc521327fbffe46c2fe45abe476b53305e400c33444ba76dd4e0ee261fcceddc77c624827c28994413c3201c6b97f878ae2d0ad0c5faa0a6bf78 404 [0.02, 127.0.0.1:40990][0m
WARNING --- 2024-02-09 13:40:48,606 --- log --- log.py --- Not Found: /tasks
WARNING --- 2024-02-09 13:40:48,607 --- runserver --- runserver.py --- [33mHTTP GET /tasks 404 [0.02, 127.0.0.1:40990][0m
WARNING --- 2024-02-09 13:40:55,783 --- runserver --- runserver.py --- [33mHTTP GET /static/css/flower.css?v=cb65558ddda9a029f1ef92d591aec21646e1c50225c1f94f6ba79686bd6690f029b56fd21aef9a8a7b9e2c069bf113decaae7ee1098f33132619f22f47124415 404 [0.02, 127.0.0.1:40990][0m
WARNING --- 2024-02-09 13:41:10,513 --- log --- log.py --- Not Found: /workers
WARNING --- 2024-02-09 13:41:10,514 --- runserver --- runserver.py --- [33mHTTP GET /workers 404 [0.03, 127.0.0.1:40990][0m
WARNING --- 2024-02-09 13:43:30,646 --- log --- log.py --- Not Found: /flower/
WARNING --- 2024-02-09 13:43:30,647 --- runserver --- runserver.py --- [33mHTTP GET /flower/ 404 [0.03, 127.0.0.1:60228][0m
WARNING --- 2024-02-09 13:43:31,025 --- log --- log.py --- Not Found: /flower/
WARNING --- 2024-02-09 13:43:31,026 --- runserver --- runserver.py --- [33mHTTP GET /flower/ 404 [0.02, 127.0.0.1:60228][0m
WARNING --- 2024-02-09 13:43:31,343 --- runserver --- runserver.py --- [33mHTTP GET /static/css/flower.css?v=cb65558ddda9a029f1ef92d591aec21646e1c50225c1f94f6ba79686bd6690f029b56fd21aef9a8a7b9e2c069bf113decaae7ee1098f33132619f22f47124415 404 [0.05, 127.0.0.1:37154][0m
WARNING --- 2024-02-09 13:43:31,346 --- runserver --- runserver.py --- [33mHTTP GET /static/js/bootstrap.bundle.min.js?v=d159d8395c8a2c53390808d1b696929be19b9974d6feff72904b069004583f469ac5a352608ead49e396f36e5a312b4a8c50708be2e041f47613a3e03d344ba9 404 [0.05, 127.0.0.1:37168][0m
WARNING --- 2024-02-09 13:43:31,346 --- runserver --- runserver.py --- [33mHTTP GET /static/css/bootstrap.min.css?v=eea261d9b89e1738193c9f9b06196592b31a87daee9aaec45629e54645e460853a40ad27b3860a83b2c0b65c3ebb2b039371a4fb42a1aa592695d33e74be6dd1 404 [0.06, 127.0.0.1:60228][0m
WARNING --- 2024-02-09 13:43:31,347 --- runserver --- runserver.py --- [33mHTTP GET /static/js/datatables-1.13.4.min.js?v=545b043132ca7e6d31fa9428dda427f4116732de8b19face781a8aa2372265d1f22fa1ed5e54428899170459577732a98c15bafb6663c40fcf11bb770d896b59 404 [0.05, 127.0.0.1:37186][0m
WARNING --- 2024-02-09 13:43:31,348 --- runserver --- runserver.py --- [33mHTTP GET /static/js/jquery-3.6.4.min.js?v=a6e981b23351186aa43f32879dd64c6801be6e2af7ef8b0e472cccdeeba52d5d7894de4bcb292a364f1e11e525524077534338140a72687ada4fae62849843a5 404 [0.05, 127.0.0.1:37180][0m
WARNING --- 2024-02-09 13:43:31,348 --- runserver --- runserver.py --- [33mHTTP GET /static/css/datatables-1.13.4.min.css?v=74c4a6b553604403588edd63769db7dfbaf4c22cb68aba292a93e02ac283a6136e686b2fd7502a7816f160fae558412a7c877b81fd557298f07b32e026739559 404 [0.05, 127.0.0.1:60236][0m
WARNING --- 2024-02-09 13:43:31,357 --- runserver --- runserver.py --- [33mHTTP GET /static/js/moment-2.29.4.min.js?v=0abc8a6cc7bbb234820cf975f23b492390d1e63b64516c4f5d668b0acb7a4231fcc310dec5f44989cd964664579acb6bd98f12c430d6b813ba0900ba204e0a4c 404 [0.01, 127.0.0.1:37154][0m
WARNING --- 2024-02-09 13:43:31,377 --- runserver --- runserver.py --- [33mHTTP GET /static/js/moment-timezone-with-data-2.29.4.min.js?v=28223e7d1ddb51b39c534642dd471a3f008bb8ee4b124ba469605875d9a12cf5e0a403d627c8faa492e64c8eadf42318733138602ad6650ff0ad9cff26cc82f8 404 [0.01, 127.0.0.1:37154][0m
WARNING --- 2024-02-09 13:43:31,378 --- runserver --- runserver.py --- [33mHTTP GET /static/js/flower.js?v=5ef89e36a054bc521327fbffe46c2fe45abe476b53305e400c33444ba76dd4e0ee261fcceddc77c624827c28994413c3201c6b97f878ae2d0ad0c5faa0a6bf78 404 [0.01, 127.0.0.1:60236][0m
WARNING --- 2024-02-09 13:43:31,379 --- runserver --- runserver.py --- [33mHTTP GET /static/favicon.ico?v=ff1ba46e61b7e034e9ce38326f398a2b86c222a137e2eb96a3ea16c77300d423d6ebf0cc8d4ac73d95087e6114ef8e13fa52fa5b6f9fadc0b5d1a9e3680015b8 404 [0.01, 127.0.0.1:37180][0m
WARNING --- 2024-02-09 13:45:04,485 --- log --- log.py --- Not Found: /flower/addons/
WARNING --- 2024-02-09 13:45:04,486 --- runserver --- runserver.py --- [33mHTTP GET /flower/addons/ 404 [0.02, 127.0.0.1:50252][0m
WARNING --- 2024-02-09 13:45:04,761 --- runserver --- runserver.py --- [33mHTTP GET /static/css/bootstrap.min.css?v=eea261d9b89e1738193c9f9b06196592b31a87daee9aaec45629e54645e460853a40ad27b3860a83b2c0b65c3ebb2b039371a4fb42a1aa592695d33e74be6dd1 404 [0.03, 127.0.0.1:50252][0m
WARNING --- 2024-02-09 13:45:04,762 --- runserver --- runserver.py --- [33mHTTP GET /static/css/datatables-1.13.4.min.css?v=74c4a6b553604403588edd63769db7dfbaf4c22cb68aba292a93e02ac283a6136e686b2fd7502a7816f160fae558412a7c877b81fd557298f07b32e026739559 404 [0.03, 127.0.0.1:50246][0m
WARNING --- 2024-02-09 13:45:04,765 --- runserver --- runserver.py --- [33mHTTP GET /static/js/jquery-3.6.4.min.js?v=a6e981b23351186aa43f32879dd64c6801be6e2af7ef8b0e472cccdeeba52d5d7894de4bcb292a364f1e11e525524077534338140a72687ada4fae62849843a5 404 [0.03, 127.0.0.1:32974][0m
WARNING --- 2024-02-09 13:45:04,765 --- runserver --- runserver.py --- [33mHTTP GET /static/js/bootstrap.bundle.min.js?v=d159d8395c8a2c53390808d1b696929be19b9974d6feff72904b069004583f469ac5a352608ead49e396f36e5a312b4a8c50708be2e041f47613a3e03d344ba9 404 [0.03, 127.0.0.1:50236][0m
WARNING --- 2024-02-09 13:45:04,766 --- runserver --- runserver.py --- [33mHTTP GET /static/css/flower.css?v=cb65558ddda9a029f1ef92d591aec21646e1c50225c1f94f6ba79686bd6690f029b56fd21aef9a8a7b9e2c069bf113decaae7ee1098f33132619f22f47124415 404 [0.03, 127.0.0.1:50244][0m
WARNING --- 2024-02-09 13:45:04,767 --- runserver --- runserver.py --- [33mHTTP GET /static/js/datatables-1.13.4.min.js?v=545b043132ca7e6d31fa9428dda427f4116732de8b19face781a8aa2372265d1f22fa1ed5e54428899170459577732a98c15bafb6663c40fcf11bb770d896b59 404 [0.03, 127.0.0.1:32964][0m
WARNING --- 2024-02-09 13:45:04,777 --- runserver --- runserver.py --- [33mHTTP GET /static/js/moment-2.29.4.min.js?v=0abc8a6cc7bbb234820cf975f23b492390d1e63b64516c4f5d668b0acb7a4231fcc310dec5f44989cd964664579acb6bd98f12c430d6b813ba0900ba204e0a4c 404 [0.01, 127.0.0.1:50246][0m
WARNING --- 2024-02-09 13:45:04,803 --- runserver --- runserver.py --- [33mHTTP GET /static/js/moment-timezone-with-data-2.29.4.min.js?v=28223e7d1ddb51b39c534642dd471a3f008bb8ee4b124ba469605875d9a12cf5e0a403d627c8faa492e64c8eadf42318733138602ad6650ff0ad9cff26cc82f8 404 [0.02, 127.0.0.1:50252][0m
WARNING --- 2024-02-09 13:45:04,806 --- runserver --- runserver.py --- [33mHTTP GET /static/js/flower.js?v=5ef89e36a054bc521327fbffe46c2fe45abe476b53305e400c33444ba76dd4e0ee261fcceddc77c624827c28994413c3201c6b97f878ae2d0ad0c5faa0a6bf78 404 [0.03, 127.0.0.1:32964][0m
WARNING --- 2024-02-09 13:45:04,808 --- runserver --- runserver.py --- [33mHTTP GET /static/favicon.ico?v=ff1ba46e61b7e034e9ce38326f398a2b86c222a137e2eb96a3ea16c77300d423d6ebf0cc8d4ac73d95087e6114ef8e13fa52fa5b6f9fadc0b5d1a9e3680015b8 404 [0.03, 127.0.0.1:50244][0m
WARNING --- 2024-02-09 13:45:08,075 --- log --- log.py --- Not Found: /flower/
WARNING --- 2024-02-09 13:45:08,077 --- runserver --- runserver.py --- [33mHTTP GET /flower/ 404 [0.02, 127.0.0.1:50244][0m
WARNING --- 2024-02-09 13:45:08,352 --- runserver --- runserver.py --- [33mHTTP GET /static/css/bootstrap.min.css?v=eea261d9b89e1738193c9f9b06196592b31a87daee9aaec45629e54645e460853a40ad27b3860a83b2c0b65c3ebb2b039371a4fb42a1aa592695d33e74be6dd1 404 [0.03, 127.0.0.1:50244][0m
WARNING --- 2024-02-09 13:45:08,354 --- runserver --- runserver.py --- [33mHTTP GET /static/css/datatables-1.13.4.min.css?v=74c4a6b553604403588edd63769db7dfbaf4c22cb68aba292a93e02ac283a6136e686b2fd7502a7816f160fae558412a7c877b81fd557298f07b32e026739559 404 [0.03, 127.0.0.1:32964][0m
WARNING --- 2024-02-09 13:45:08,355 --- runserver --- runserver.py --- [33mHTTP GET /static/js/bootstrap.bundle.min.js?v=d159d8395c8a2c53390808d1b696929be19b9974d6feff72904b069004583f469ac5a352608ead49e396f36e5a312b4a8c50708be2e041f47613a3e03d344ba9 404 [0.03, 127.0.0.1:50246][0m
WARNING --- 2024-02-09 13:45:08,356 --- runserver --- runserver.py --- [33mHTTP GET /static/js/jquery-3.6.4.min.js?v=a6e981b23351186aa43f32879dd64c6801be6e2af7ef8b0e472cccdeeba52d5d7894de4bcb292a364f1e11e525524077534338140a72687ada4fae62849843a5 404 [0.04, 127.0.0.1:50236][0m
WARNING --- 2024-02-09 13:45:08,356 --- runserver --- runserver.py --- [33mHTTP GET /static/js/datatables-1.13.4.min.js?v=545b043132ca7e6d31fa9428dda427f4116732de8b19face781a8aa2372265d1f22fa1ed5e54428899170459577732a98c15bafb6663c40fcf11bb770d896b59 404 [0.03, 127.0.0.1:32974][0m
WARNING --- 2024-02-09 13:45:08,357 --- runserver --- runserver.py --- [33mHTTP GET /static/css/flower.css?v=cb65558ddda9a029f1ef92d591aec21646e1c50225c1f94f6ba79686bd6690f029b56fd21aef9a8a7b9e2c069bf113decaae7ee1098f33132619f22f47124415 404 [0.04, 127.0.0.1:50252][0m
WARNING --- 2024-02-09 13:45:08,389 --- runserver --- runserver.py --- [33mHTTP GET /static/js/moment-timezone-with-data-2.29.4.min.js?v=28223e7d1ddb51b39c534642dd471a3f008bb8ee4b124ba469605875d9a12cf5e0a403d627c8faa492e64c8eadf42318733138602ad6650ff0ad9cff26cc82f8 404 [0.02, 127.0.0.1:50252][0m
WARNING --- 2024-02-09 13:45:08,390 --- runserver --- runserver.py --- [33mHTTP GET /static/js/flower.js?v=5ef89e36a054bc521327fbffe46c2fe45abe476b53305e400c33444ba76dd4e0ee261fcceddc77c624827c28994413c3201c6b97f878ae2d0ad0c5faa0a6bf78 404 [0.02, 127.0.0.1:32974][0m
WARNING --- 2024-02-09 13:45:08,391 --- runserver --- runserver.py --- [33mHTTP GET /static/js/moment-2.29.4.min.js?v=0abc8a6cc7bbb234820cf975f23b492390d1e63b64516c4f5d668b0acb7a4231fcc310dec5f44989cd964664579acb6bd98f12c430d6b813ba0900ba204e0a4c 404 [0.02, 127.0.0.1:50236][0m
WARNING --- 2024-02-09 13:45:08,392 --- runserver --- runserver.py --- [33mHTTP GET /static/favicon.ico?v=ff1ba46e61b7e034e9ce38326f398a2b86c222a137e2eb96a3ea16c77300d423d6ebf0cc8d4ac73d95087e6114ef8e13fa52fa5b6f9fadc0b5d1a9e3680015b8 404 [0.02, 127.0.0.1:50246][0m
WARNING --- 2024-02-09 13:45:09,626 --- log --- log.py --- Not Found: /flower/
WARNING --- 2024-02-09 13:45:09,627 --- runserver --- runserver.py --- [33mHTTP GET /flower/ 404 [0.02, 127.0.0.1:50246][0m
WARNING --- 2024-02-09 13:45:09,929 --- runserver --- runserver.py --- [33mHTTP GET /static/css/datatables-1.13.4.min.css?v=74c4a6b553604403588edd63769db7dfbaf4c22cb68aba292a93e02ac283a6136e686b2fd7502a7816f160fae558412a7c877b81fd557298f07b32e026739559 404 [0.04, 127.0.0.1:50236][0m
WARNING --- 2024-02-09 13:45:09,933 --- runserver --- runserver.py --- [33mHTTP GET /static/js/bootstrap.bundle.min.js?v=d159d8395c8a2c53390808d1b696929be19b9974d6feff72904b069004583f469ac5a352608ead49e396f36e5a312b4a8c50708be2e041f47613a3e03d344ba9 404 [0.04, 127.0.0.1:50252][0m
WARNING --- 2024-02-09 13:45:09,933 --- runserver --- runserver.py --- [33mHTTP GET /static/css/bootstrap.min.css?v=eea261d9b89e1738193c9f9b06196592b31a87daee9aaec45629e54645e460853a40ad27b3860a83b2c0b65c3ebb2b039371a4fb42a1aa592695d33e74be6dd1 404 [0.05, 127.0.0.1:50246][0m
WARNING --- 2024-02-09 13:45:09,934 --- runserver --- runserver.py --- [33mHTTP GET /static/css/flower.css?v=cb65558ddda9a029f1ef92d591aec21646e1c50225c1f94f6ba79686bd6690f029b56fd21aef9a8a7b9e2c069bf113decaae7ee1098f33132619f22f47124415 404 [0.04, 127.0.0.1:32974][0m
WARNING --- 2024-02-09 13:45:09,935 --- runserver --- runserver.py --- [33mHTTP GET /static/js/datatables-1.13.4.min.js?v=545b043132ca7e6d31fa9428dda427f4116732de8b19face781a8aa2372265d1f22fa1ed5e54428899170459577732a98c15bafb6663c40fcf11bb770d896b59 404 [0.04, 127.0.0.1:50244][0m
WARNING --- 2024-02-09 13:45:09,935 --- runserver --- runserver.py --- [33mHTTP GET /static/js/jquery-3.6.4.min.js?v=a6e981b23351186aa43f32879dd64c6801be6e2af7ef8b0e472cccdeeba52d5d7894de4bcb292a364f1e11e525524077534338140a72687ada4fae62849843a5 404 [0.04, 127.0.0.1:32964][0m
WARNING --- 2024-02-09 13:45:09,947 --- runserver --- runserver.py --- [33mHTTP GET /static/js/moment-2.29.4.min.js?v=0abc8a6cc7bbb234820cf975f23b492390d1e63b64516c4f5d668b0acb7a4231fcc310dec5f44989cd964664579acb6bd98f12c430d6b813ba0900ba204e0a4c 404 [0.01, 127.0.0.1:50236][0m
WARNING --- 2024-02-09 13:45:09,970 --- runserver --- runserver.py --- [33mHTTP GET /static/js/flower.js?v=5ef89e36a054bc521327fbffe46c2fe45abe476b53305e400c33444ba76dd4e0ee261fcceddc77c624827c28994413c3201c6b97f878ae2d0ad0c5faa0a6bf78 404 [0.02, 127.0.0.1:32974][0m
WARNING --- 2024-02-09 13:45:09,973 --- runserver --- runserver.py --- [33mHTTP GET /static/favicon.ico?v=ff1ba46e61b7e034e9ce38326f398a2b86c222a137e2eb96a3ea16c77300d423d6ebf0cc8d4ac73d95087e6114ef8e13fa52fa5b6f9fadc0b5d1a9e3680015b8 404 [0.02, 127.0.0.1:50244][0m
WARNING --- 2024-02-09 13:45:09,974 --- runserver --- runserver.py --- [33mHTTP GET /static/js/moment-timezone-with-data-2.29.4.min.js?v=28223e7d1ddb51b39c534642dd471a3f008bb8ee4b124ba469605875d9a12cf5e0a403d627c8faa492e64c8eadf42318733138602ad6650ff0ad9cff26cc82f8 404 [0.03, 127.0.0.1:32964][0m
WARNING --- 2024-02-09 13:45:10,184 --- log --- log.py --- Not Found: /favicon.ico
WARNING --- 2024-02-09 13:45:10,185 --- runserver --- runserver.py --- [33mHTTP GET /favicon.ico 404 [0.02, 127.0.0.1:32964][0m
ERROR --- 2024-02-09 13:45:47,444 --- log --- log.py --- Internal Server Error: /flower/
Traceback (most recent call last):
  File "/mnt/myprojects/project/mysite/venv/lib/python3.11/site-packages/urllib3/connection.py", line 203, in _new_conn
    sock = connection.create_connection(
           ^^^^^^^^^^^^^^^^^^^^^^^^^^^^^
  File "/mnt/myprojects/project/mysite/venv/lib/python3.11/site-packages/urllib3/util/connection.py", line 85, in create_connection
    raise err
  File "/mnt/myprojects/project/mysite/venv/lib/python3.11/site-packages/urllib3/util/connection.py", line 73, in create_connection
    sock.connect(sa)
ConnectionRefusedError: [Errno 111] Connection refused

The above exception was the direct cause of the following exception:

Traceback (most recent call last):
  File "/mnt/myprojects/project/mysite/venv/lib/python3.11/site-packages/urllib3/connectionpool.py", line 791, in urlopen
    response = self._make_request(
               ^^^^^^^^^^^^^^^^^^^
  File "/mnt/myprojects/project/mysite/venv/lib/python3.11/site-packages/urllib3/connectionpool.py", line 497, in _make_request
    conn.request(
  File "/mnt/myprojects/project/mysite/venv/lib/python3.11/site-packages/urllib3/connection.py", line 395, in request
    self.endheaders()
  File "/home/kenun/.python3.11/lib/python3.11/http/client.py", line 1289, in endheaders
    self._send_output(message_body, encode_chunked=encode_chunked)
  File "/home/kenun/.python3.11/lib/python3.11/http/client.py", line 1048, in _send_output
    self.send(msg)
  File "/home/kenun/.python3.11/lib/python3.11/http/client.py", line 986, in send
    self.connect()
  File "/mnt/myprojects/project/mysite/venv/lib/python3.11/site-packages/urllib3/connection.py", line 243, in connect
    self.sock = self._new_conn()
                ^^^^^^^^^^^^^^^^
  File "/mnt/myprojects/project/mysite/venv/lib/python3.11/site-packages/urllib3/connection.py", line 218, in _new_conn
    raise NewConnectionError(
urllib3.exceptions.NewConnectionError: <urllib3.connection.HTTPConnection object at 0x7f4e155a99d0>: Failed to establish a new connection: [Errno 111] Connection refused

The above exception was the direct cause of the following exception:

Traceback (most recent call last):
  File "/mnt/myprojects/project/mysite/venv/lib/python3.11/site-packages/requests/adapters.py", line 486, in send
    resp = conn.urlopen(
           ^^^^^^^^^^^^^
  File "/mnt/myprojects/project/mysite/venv/lib/python3.11/site-packages/urllib3/connectionpool.py", line 845, in urlopen
    retries = retries.increment(
              ^^^^^^^^^^^^^^^^^^
  File "/mnt/myprojects/project/mysite/venv/lib/python3.11/site-packages/urllib3/util/retry.py", line 515, in increment
    raise MaxRetryError(_pool, url, reason) from reason  # type: ignore[arg-type]
    ^^^^^^^^^^^^^^^^^^^^^^^^^^^^^^^^^^^^^^^^^^^^^^^^^^^
urllib3.exceptions.MaxRetryError: HTTPConnectionPool(host='127.0.0.1', port=5555): Max retries exceeded with url: /flower/ (Caused by NewConnectionError('<urllib3.connection.HTTPConnection object at 0x7f4e155a99d0>: Failed to establish a new connection: [Errno 111] Connection refused'))

During handling of the above exception, another exception occurred:

Traceback (most recent call last):
  File "/mnt/myprojects/project/mysite/venv/lib/python3.11/site-packages/asgiref/sync.py", line 534, in thread_handler
    raise exc_info[1]
  File "/mnt/myprojects/project/mysite/venv/lib/python3.11/site-packages/django/core/handlers/exception.py", line 42, in inner
    response = await get_response(request)
               ^^^^^^^^^^^^^^^^^^^^^^^^^^^
  File "/mnt/myprojects/project/mysite/venv/lib/python3.11/site-packages/asgiref/sync.py", line 534, in thread_handler
    raise exc_info[1]
  File "/mnt/myprojects/project/mysite/venv/lib/python3.11/site-packages/django/core/handlers/base.py", line 253, in _get_response_async
    response = await wrapped_callback(
               ^^^^^^^^^^^^^^^^^^^^^^^
  File "/mnt/myprojects/project/mysite/venv/lib/python3.11/site-packages/asgiref/sync.py", line 479, in __call__
    ret: _R = await loop.run_in_executor(
              ^^^^^^^^^^^^^^^^^^^^^^^^^^^
  File "/home/kenun/.python3.11/lib/python3.11/concurrent/futures/thread.py", line 58, in run
    result = self.fn(*self.args, **self.kwargs)
             ^^^^^^^^^^^^^^^^^^^^^^^^^^^^^^^^^^
  File "/mnt/myprojects/project/mysite/venv/lib/python3.11/site-packages/asgiref/sync.py", line 538, in thread_handler
    return func(*args, **kwargs)
           ^^^^^^^^^^^^^^^^^^^^^
  File "/mnt/myprojects/project/mysite/venv/lib/python3.11/site-packages/django/views/decorators/csrf.py", line 56, in wrapper_view
    return view_func(*args, **kwargs)
           ^^^^^^^^^^^^^^^^^^^^^^^^^^
  File "/mnt/myprojects/project/mysite/HomePage/views.py", line 151, in flower_proxy_view
    return proxy_view(
           ^^^^^^^^^^^
  File "/mnt/myprojects/project/mysite/venv/lib/python3.11/site-packages/proxy/views.py", line 45, in proxy_view
    response = requests.request(request.method, url, **requests_args)
               ^^^^^^^^^^^^^^^^^^^^^^^^^^^^^^^^^^^^^^^^^^^^^^^^^^^^^^
  File "/mnt/myprojects/project/mysite/venv/lib/python3.11/site-packages/requests/api.py", line 59, in request
    return session.request(method=method, url=url, **kwargs)
           ^^^^^^^^^^^^^^^^^^^^^^^^^^^^^^^^^^^^^^^^^^^^^^^^^
  File "/mnt/myprojects/project/mysite/venv/lib/python3.11/site-packages/requests/sessions.py", line 589, in request
    resp = self.send(prep, **send_kwargs)
           ^^^^^^^^^^^^^^^^^^^^^^^^^^^^^^
  File "/mnt/myprojects/project/mysite/venv/lib/python3.11/site-packages/requests/sessions.py", line 703, in send
    r = adapter.send(request, **kwargs)
        ^^^^^^^^^^^^^^^^^^^^^^^^^^^^^^^
  File "/mnt/myprojects/project/mysite/venv/lib/python3.11/site-packages/requests/adapters.py", line 519, in send
    raise ConnectionError(e, request=request)
requests.exceptions.ConnectionError: HTTPConnectionPool(host='127.0.0.1', port=5555): Max retries exceeded with url: /flower/ (Caused by NewConnectionError('<urllib3.connection.HTTPConnection object at 0x7f4e155a99d0>: Failed to establish a new connection: [Errno 111] Connection refused'))
ERROR --- 2024-02-09 13:45:48,323 --- runserver --- runserver.py --- [35;1mHTTP GET /flower/ 500 [0.97, 127.0.0.1:45136][0m
WARNING --- 2024-02-09 13:45:50,430 --- log --- log.py --- Not Found: /flower/
WARNING --- 2024-02-09 13:45:50,432 --- runserver --- runserver.py --- [33mHTTP GET /flower/ 404 [0.03, 127.0.0.1:45136][0m
WARNING --- 2024-02-09 13:45:50,711 --- runserver --- runserver.py --- [33mHTTP GET /static/js/datatables-1.13.4.min.js?v=545b043132ca7e6d31fa9428dda427f4116732de8b19face781a8aa2372265d1f22fa1ed5e54428899170459577732a98c15bafb6663c40fcf11bb770d896b59 404 [0.03, 127.0.0.1:45186][0m
WARNING --- 2024-02-09 13:45:50,713 --- runserver --- runserver.py --- [33mHTTP GET /static/css/datatables-1.13.4.min.css?v=74c4a6b553604403588edd63769db7dfbaf4c22cb68aba292a93e02ac283a6136e686b2fd7502a7816f160fae558412a7c877b81fd557298f07b32e026739559 404 [0.04, 127.0.0.1:45146][0m
WARNING --- 2024-02-09 13:45:50,714 --- runserver --- runserver.py --- [33mHTTP GET /static/css/bootstrap.min.css?v=eea261d9b89e1738193c9f9b06196592b31a87daee9aaec45629e54645e460853a40ad27b3860a83b2c0b65c3ebb2b039371a4fb42a1aa592695d33e74be6dd1 404 [0.04, 127.0.0.1:45136][0m
WARNING --- 2024-02-09 13:45:50,715 --- runserver --- runserver.py --- [33mHTTP GET /static/css/flower.css?v=cb65558ddda9a029f1ef92d591aec21646e1c50225c1f94f6ba79686bd6690f029b56fd21aef9a8a7b9e2c069bf113decaae7ee1098f33132619f22f47124415 404 [0.04, 127.0.0.1:45148][0m
WARNING --- 2024-02-09 13:45:50,715 --- runserver --- runserver.py --- [33mHTTP GET /static/js/jquery-3.6.4.min.js?v=a6e981b23351186aa43f32879dd64c6801be6e2af7ef8b0e472cccdeeba52d5d7894de4bcb292a364f1e11e525524077534338140a72687ada4fae62849843a5 404 [0.04, 127.0.0.1:45170][0m
WARNING --- 2024-02-09 13:45:50,716 --- runserver --- runserver.py --- [33mHTTP GET /static/js/bootstrap.bundle.min.js?v=d159d8395c8a2c53390808d1b696929be19b9974d6feff72904b069004583f469ac5a352608ead49e396f36e5a312b4a8c50708be2e041f47613a3e03d344ba9 404 [0.04, 127.0.0.1:45160][0m
WARNING --- 2024-02-09 13:45:50,747 --- runserver --- runserver.py --- [33mHTTP GET /static/js/moment-timezone-with-data-2.29.4.min.js?v=28223e7d1ddb51b39c534642dd471a3f008bb8ee4b124ba469605875d9a12cf5e0a403d627c8faa492e64c8eadf42318733138602ad6650ff0ad9cff26cc82f8 404 [0.02, 127.0.0.1:45146][0m
WARNING --- 2024-02-09 13:45:50,750 --- runserver --- runserver.py --- [33mHTTP GET /static/js/moment-2.29.4.min.js?v=0abc8a6cc7bbb234820cf975f23b492390d1e63b64516c4f5d668b0acb7a4231fcc310dec5f44989cd964664579acb6bd98f12c430d6b813ba0900ba204e0a4c 404 [0.02, 127.0.0.1:45136][0m
WARNING --- 2024-02-09 13:45:50,751 --- runserver --- runserver.py --- [33mHTTP GET /static/js/flower.js?v=5ef89e36a054bc521327fbffe46c2fe45abe476b53305e400c33444ba76dd4e0ee261fcceddc77c624827c28994413c3201c6b97f878ae2d0ad0c5faa0a6bf78 404 [0.02, 127.0.0.1:45160][0m
WARNING --- 2024-02-09 13:45:50,752 --- runserver --- runserver.py --- [33mHTTP GET /static/favicon.ico?v=ff1ba46e61b7e034e9ce38326f398a2b86c222a137e2eb96a3ea16c77300d423d6ebf0cc8d4ac73d95087e6114ef8e13fa52fa5b6f9fadc0b5d1a9e3680015b8 404 [0.03, 127.0.0.1:45170][0m
WARNING --- 2024-02-09 13:45:53,091 --- log --- log.py --- Not Found: /flower/
WARNING --- 2024-02-09 13:45:53,092 --- runserver --- runserver.py --- [33mHTTP GET /flower/ 404 [0.02, 127.0.0.1:45170][0m
WARNING --- 2024-02-09 13:45:53,394 --- runserver --- runserver.py --- [33mHTTP GET /static/css/datatables-1.13.4.min.css?v=74c4a6b553604403588edd63769db7dfbaf4c22cb68aba292a93e02ac283a6136e686b2fd7502a7816f160fae558412a7c877b81fd557298f07b32e026739559 404 [0.04, 127.0.0.1:45160][0m
WARNING --- 2024-02-09 13:45:53,395 --- runserver --- runserver.py --- [33mHTTP GET /static/css/flower.css?v=cb65558ddda9a029f1ef92d591aec21646e1c50225c1f94f6ba79686bd6690f029b56fd21aef9a8a7b9e2c069bf113decaae7ee1098f33132619f22f47124415 404 [0.04, 127.0.0.1:45136][0m
WARNING --- 2024-02-09 13:45:53,397 --- runserver --- runserver.py --- [33mHTTP GET /static/js/bootstrap.bundle.min.js?v=d159d8395c8a2c53390808d1b696929be19b9974d6feff72904b069004583f469ac5a352608ead49e396f36e5a312b4a8c50708be2e041f47613a3e03d344ba9 404 [0.04, 127.0.0.1:45146][0m
WARNING --- 2024-02-09 13:45:53,398 --- runserver --- runserver.py --- [33mHTTP GET /static/js/jquery-3.6.4.min.js?v=a6e981b23351186aa43f32879dd64c6801be6e2af7ef8b0e472cccdeeba52d5d7894de4bcb292a364f1e11e525524077534338140a72687ada4fae62849843a5 404 [0.04, 127.0.0.1:45148][0m
WARNING --- 2024-02-09 13:45:53,398 --- runserver --- runserver.py --- [33mHTTP GET /static/css/bootstrap.min.css?v=eea261d9b89e1738193c9f9b06196592b31a87daee9aaec45629e54645e460853a40ad27b3860a83b2c0b65c3ebb2b039371a4fb42a1aa592695d33e74be6dd1 404 [0.04, 127.0.0.1:45170][0m
WARNING --- 2024-02-09 13:45:53,399 --- runserver --- runserver.py --- [33mHTTP GET /static/js/datatables-1.13.4.min.js?v=545b043132ca7e6d31fa9428dda427f4116732de8b19face781a8aa2372265d1f22fa1ed5e54428899170459577732a98c15bafb6663c40fcf11bb770d896b59 404 [0.04, 127.0.0.1:45186][0m
WARNING --- 2024-02-09 13:45:53,429 --- runserver --- runserver.py --- [33mHTTP GET /static/js/moment-2.29.4.min.js?v=0abc8a6cc7bbb234820cf975f23b492390d1e63b64516c4f5d668b0acb7a4231fcc310dec5f44989cd964664579acb6bd98f12c430d6b813ba0900ba204e0a4c 404 [0.02, 127.0.0.1:45186][0m
WARNING --- 2024-02-09 13:45:53,431 --- runserver --- runserver.py --- [33mHTTP GET /static/favicon.ico?v=ff1ba46e61b7e034e9ce38326f398a2b86c222a137e2eb96a3ea16c77300d423d6ebf0cc8d4ac73d95087e6114ef8e13fa52fa5b6f9fadc0b5d1a9e3680015b8 404 [0.02, 127.0.0.1:45146][0m
WARNING --- 2024-02-09 13:45:53,432 --- runserver --- runserver.py --- [33mHTTP GET /static/js/moment-timezone-with-data-2.29.4.min.js?v=28223e7d1ddb51b39c534642dd471a3f008bb8ee4b124ba469605875d9a12cf5e0a403d627c8faa492e64c8eadf42318733138602ad6650ff0ad9cff26cc82f8 404 [0.02, 127.0.0.1:45170][0m
WARNING --- 2024-02-09 13:45:53,434 --- runserver --- runserver.py --- [33mHTTP GET /static/js/flower.js?v=5ef89e36a054bc521327fbffe46c2fe45abe476b53305e400c33444ba76dd4e0ee261fcceddc77c624827c28994413c3201c6b97f878ae2d0ad0c5faa0a6bf78 404 [0.02, 127.0.0.1:45148][0m
WARNING --- 2024-02-09 13:45:53,661 --- log --- log.py --- Not Found: /favicon.ico
WARNING --- 2024-02-09 13:45:53,661 --- runserver --- runserver.py --- [33mHTTP GET /favicon.ico 404 [0.02, 127.0.0.1:45148][0m
ERROR --- 2024-02-09 13:47:44,108 --- log --- log.py --- Internal Server Error: /
Traceback (most recent call last):
  File "/mnt/myprojects/project/mysite/venv/lib/python3.11/site-packages/asgiref/sync.py", line 534, in thread_handler
    raise exc_info[1]
  File "/mnt/myprojects/project/mysite/venv/lib/python3.11/site-packages/django/core/handlers/exception.py", line 42, in inner
    response = await get_response(request)
               ^^^^^^^^^^^^^^^^^^^^^^^^^^^
  File "/mnt/myprojects/project/mysite/venv/lib/python3.11/site-packages/asgiref/sync.py", line 534, in thread_handler
    raise exc_info[1]
  File "/mnt/myprojects/project/mysite/venv/lib/python3.11/site-packages/django/core/handlers/base.py", line 284, in _get_response_async
    response = await sync_to_async(
               ^^^^^^^^^^^^^^^^^^^^
  File "/mnt/myprojects/project/mysite/venv/lib/python3.11/site-packages/asgiref/sync.py", line 479, in __call__
    ret: _R = await loop.run_in_executor(
              ^^^^^^^^^^^^^^^^^^^^^^^^^^^
  File "/home/kenun/.python3.11/lib/python3.11/concurrent/futures/thread.py", line 58, in run
    result = self.fn(*self.args, **self.kwargs)
             ^^^^^^^^^^^^^^^^^^^^^^^^^^^^^^^^^^
  File "/mnt/myprojects/project/mysite/venv/lib/python3.11/site-packages/asgiref/sync.py", line 538, in thread_handler
    return func(*args, **kwargs)
           ^^^^^^^^^^^^^^^^^^^^^
  File "/mnt/myprojects/project/mysite/venv/lib/python3.11/site-packages/django/template/response.py", line 114, in render
    self.content = self.rendered_content
                   ^^^^^^^^^^^^^^^^^^^^^
  File "/mnt/myprojects/project/mysite/venv/lib/python3.11/site-packages/django/template/response.py", line 92, in rendered_content
    return template.render(context, self._request)
           ^^^^^^^^^^^^^^^^^^^^^^^^^^^^^^^^^^^^^^^
  File "/mnt/myprojects/project/mysite/venv/lib/python3.11/site-packages/django/template/backends/django.py", line 61, in render
    return self.template.render(context)
           ^^^^^^^^^^^^^^^^^^^^^^^^^^^^^
  File "/mnt/myprojects/project/mysite/venv/lib/python3.11/site-packages/django/template/base.py", line 175, in render
    return self._render(context)
           ^^^^^^^^^^^^^^^^^^^^^
  File "/mnt/myprojects/project/mysite/venv/lib/python3.11/site-packages/django/template/base.py", line 167, in _render
    return self.nodelist.render(context)
           ^^^^^^^^^^^^^^^^^^^^^^^^^^^^^
  File "/mnt/myprojects/project/mysite/venv/lib/python3.11/site-packages/django/template/base.py", line 1005, in render
    return SafeString("".join([node.render_annotated(context) for node in self]))
                              ^^^^^^^^^^^^^^^^^^^^^^^^^^^^^^^^^^^^^^^^^^^^^^^^^
  File "/mnt/myprojects/project/mysite/venv/lib/python3.11/site-packages/django/template/base.py", line 1005, in <listcomp>
    return SafeString("".join([node.render_annotated(context) for node in self]))
                               ^^^^^^^^^^^^^^^^^^^^^^^^^^^^^^
  File "/mnt/myprojects/project/mysite/venv/lib/python3.11/site-packages/django/template/base.py", line 966, in render_annotated
    return self.render(context)
           ^^^^^^^^^^^^^^^^^^^^
  File "/mnt/myprojects/project/mysite/venv/lib/python3.11/site-packages/django/template/loader_tags.py", line 157, in render
    return compiled_parent._render(context)
           ^^^^^^^^^^^^^^^^^^^^^^^^^^^^^^^^
  File "/mnt/myprojects/project/mysite/venv/lib/python3.11/site-packages/django/template/base.py", line 167, in _render
    return self.nodelist.render(context)
           ^^^^^^^^^^^^^^^^^^^^^^^^^^^^^
  File "/mnt/myprojects/project/mysite/venv/lib/python3.11/site-packages/django/template/base.py", line 1005, in render
    return SafeString("".join([node.render_annotated(context) for node in self]))
                              ^^^^^^^^^^^^^^^^^^^^^^^^^^^^^^^^^^^^^^^^^^^^^^^^^
  File "/mnt/myprojects/project/mysite/venv/lib/python3.11/site-packages/django/template/base.py", line 1005, in <listcomp>
    return SafeString("".join([node.render_annotated(context) for node in self]))
                               ^^^^^^^^^^^^^^^^^^^^^^^^^^^^^^
  File "/mnt/myprojects/project/mysite/venv/lib/python3.11/site-packages/django/template/base.py", line 966, in render_annotated
    return self.render(context)
           ^^^^^^^^^^^^^^^^^^^^
  File "/mnt/myprojects/project/mysite/venv/lib/python3.11/site-packages/django/template/defaulttags.py", line 321, in render
    return nodelist.render(context)
           ^^^^^^^^^^^^^^^^^^^^^^^^
  File "/mnt/myprojects/project/mysite/venv/lib/python3.11/site-packages/django/template/base.py", line 1005, in render
    return SafeString("".join([node.render_annotated(context) for node in self]))
                              ^^^^^^^^^^^^^^^^^^^^^^^^^^^^^^^^^^^^^^^^^^^^^^^^^
  File "/mnt/myprojects/project/mysite/venv/lib/python3.11/site-packages/django/template/base.py", line 1005, in <listcomp>
    return SafeString("".join([node.render_annotated(context) for node in self]))
                               ^^^^^^^^^^^^^^^^^^^^^^^^^^^^^^
  File "/mnt/myprojects/project/mysite/venv/lib/python3.11/site-packages/django/template/base.py", line 966, in render_annotated
    return self.render(context)
           ^^^^^^^^^^^^^^^^^^^^
  File "/mnt/myprojects/project/mysite/venv/lib/python3.11/site-packages/django/template/defaulttags.py", line 471, in render
    url = reverse(view_name, args=args, kwargs=kwargs, current_app=current_app)
          ^^^^^^^^^^^^^^^^^^^^^^^^^^^^^^^^^^^^^^^^^^^^^^^^^^^^^^^^^^^^^^^^^^^^^
  File "/mnt/myprojects/project/mysite/venv/lib/python3.11/site-packages/django/urls/base.py", line 88, in reverse
    return resolver._reverse_with_prefix(view, prefix, *args, **kwargs)
           ^^^^^^^^^^^^^^^^^^^^^^^^^^^^^^^^^^^^^^^^^^^^^^^^^^^^^^^^^^^^
  File "/mnt/myprojects/project/mysite/venv/lib/python3.11/site-packages/django/urls/resolvers.py", line 828, in _reverse_with_prefix
    raise NoReverseMatch(msg)
django.urls.exceptions.NoReverseMatch: Reverse for 'flower' with no arguments not found. 1 pattern(s) tried: ['flower/(?P<path>.*)']
ERROR --- 2024-02-09 13:47:44,946 --- runserver --- runserver.py --- [35;1mHTTP GET / 500 [0.99, 127.0.0.1:44292][0m
ERROR --- 2024-02-09 13:59:25,419 --- log --- log.py --- Internal Server Error: /support/chat/
Traceback (most recent call last):
  File "/mnt/myprojects/project/mysite/venv/lib/python3.11/site-packages/django/db/backends/utils.py", line 89, in _execute
    return self.cursor.execute(sql, params)
           ^^^^^^^^^^^^^^^^^^^^^^^^^^^^^^^^
psycopg2.errors.NotNullViolation: ОШИБКА:  значение NULL в столбце "slug" отношения "support_chatroom" нарушает ограничение NOT NULL
DETAIL:  Ошибочная строка содержит (36, 3, null, null).


The above exception was the direct cause of the following exception:

Traceback (most recent call last):
  File "/mnt/myprojects/project/mysite/venv/lib/python3.11/site-packages/asgiref/sync.py", line 534, in thread_handler
    raise exc_info[1]
  File "/mnt/myprojects/project/mysite/venv/lib/python3.11/site-packages/django/core/handlers/exception.py", line 42, in inner
    response = await get_response(request)
               ^^^^^^^^^^^^^^^^^^^^^^^^^^^
  File "/mnt/myprojects/project/mysite/venv/lib/python3.11/site-packages/asgiref/sync.py", line 534, in thread_handler
    raise exc_info[1]
  File "/mnt/myprojects/project/mysite/venv/lib/python3.11/site-packages/django/core/handlers/base.py", line 253, in _get_response_async
    response = await wrapped_callback(
               ^^^^^^^^^^^^^^^^^^^^^^^
  File "/mnt/myprojects/project/mysite/venv/lib/python3.11/site-packages/asgiref/sync.py", line 479, in __call__
    ret: _R = await loop.run_in_executor(
              ^^^^^^^^^^^^^^^^^^^^^^^^^^^
  File "/home/kenun/.python3.11/lib/python3.11/concurrent/futures/thread.py", line 58, in run
    result = self.fn(*self.args, **self.kwargs)
             ^^^^^^^^^^^^^^^^^^^^^^^^^^^^^^^^^^
  File "/mnt/myprojects/project/mysite/venv/lib/python3.11/site-packages/asgiref/sync.py", line 538, in thread_handler
    return func(*args, **kwargs)
           ^^^^^^^^^^^^^^^^^^^^^
  File "/mnt/myprojects/project/mysite/venv/lib/python3.11/site-packages/django/views/generic/base.py", line 104, in view
    return self.dispatch(request, *args, **kwargs)
           ^^^^^^^^^^^^^^^^^^^^^^^^^^^^^^^^^^^^^^^
  File "/mnt/myprojects/project/mysite/venv/lib/python3.11/site-packages/django/views/generic/base.py", line 143, in dispatch
    return handler(request, *args, **kwargs)
           ^^^^^^^^^^^^^^^^^^^^^^^^^^^^^^^^^
  File "/mnt/myprojects/project/mysite/venv/lib/python3.11/site-packages/django/views/generic/base.py", line 226, in get
    context = self.get_context_data(**kwargs)
              ^^^^^^^^^^^^^^^^^^^^^^^^^^^^^^^
  File "/mnt/myprojects/project/mysite/support/views.py", line 38, in get_context_data
    ChatRoom.objects.create(
  File "/mnt/myprojects/project/mysite/venv/lib/python3.11/site-packages/django/db/models/manager.py", line 87, in manager_method
    return getattr(self.get_queryset(), name)(*args, **kwargs)
           ^^^^^^^^^^^^^^^^^^^^^^^^^^^^^^^^^^^^^^^^^^^^^^^^^^^
  File "/mnt/myprojects/project/mysite/venv/lib/python3.11/site-packages/django/db/models/query.py", line 658, in create
    obj.save(force_insert=True, using=self.db)
  File "/mnt/myprojects/project/mysite/venv/lib/python3.11/site-packages/django/db/models/base.py", line 814, in save
    self.save_base(
  File "/mnt/myprojects/project/mysite/venv/lib/python3.11/site-packages/django/db/models/base.py", line 877, in save_base
    updated = self._save_table(
              ^^^^^^^^^^^^^^^^^
  File "/mnt/myprojects/project/mysite/venv/lib/python3.11/site-packages/django/db/models/base.py", line 1020, in _save_table
    results = self._do_insert(
              ^^^^^^^^^^^^^^^^
  File "/mnt/myprojects/project/mysite/venv/lib/python3.11/site-packages/django/db/models/base.py", line 1061, in _do_insert
    return manager._insert(
           ^^^^^^^^^^^^^^^^
  File "/mnt/myprojects/project/mysite/venv/lib/python3.11/site-packages/django/db/models/manager.py", line 87, in manager_method
    return getattr(self.get_queryset(), name)(*args, **kwargs)
           ^^^^^^^^^^^^^^^^^^^^^^^^^^^^^^^^^^^^^^^^^^^^^^^^^^^
  File "/mnt/myprojects/project/mysite/venv/lib/python3.11/site-packages/django/db/models/query.py", line 1805, in _insert
    return query.get_compiler(using=using).execute_sql(returning_fields)
           ^^^^^^^^^^^^^^^^^^^^^^^^^^^^^^^^^^^^^^^^^^^^^^^^^^^^^^^^^^^^^
  File "/mnt/myprojects/project/mysite/venv/lib/python3.11/site-packages/django/db/models/sql/compiler.py", line 1820, in execute_sql
    cursor.execute(sql, params)
  File "/mnt/myprojects/project/mysite/venv/lib/python3.11/site-packages/django/db/backends/utils.py", line 102, in execute
    return super().execute(sql, params)
           ^^^^^^^^^^^^^^^^^^^^^^^^^^^^
  File "/mnt/myprojects/project/mysite/venv/lib/python3.11/site-packages/django/db/backends/utils.py", line 67, in execute
    return self._execute_with_wrappers(
           ^^^^^^^^^^^^^^^^^^^^^^^^^^^^
  File "/mnt/myprojects/project/mysite/venv/lib/python3.11/site-packages/django/db/backends/utils.py", line 80, in _execute_with_wrappers
    return executor(sql, params, many, context)
           ^^^^^^^^^^^^^^^^^^^^^^^^^^^^^^^^^^^^
  File "/mnt/myprojects/project/mysite/venv/lib/python3.11/site-packages/django/db/backends/utils.py", line 84, in _execute
    with self.db.wrap_database_errors:
  File "/mnt/myprojects/project/mysite/venv/lib/python3.11/site-packages/django/db/utils.py", line 91, in __exit__
    raise dj_exc_value.with_traceback(traceback) from exc_value
  File "/mnt/myprojects/project/mysite/venv/lib/python3.11/site-packages/django/db/backends/utils.py", line 89, in _execute
    return self.cursor.execute(sql, params)
           ^^^^^^^^^^^^^^^^^^^^^^^^^^^^^^^^
django.db.utils.IntegrityError: ОШИБКА:  значение NULL в столбце "slug" отношения "support_chatroom" нарушает ограничение NOT NULL
DETAIL:  Ошибочная строка содержит (36, 3, null, null).

ERROR --- 2024-02-09 13:59:26,334 --- runserver --- runserver.py --- [35;1mHTTP GET /support/chat/ 500 [1.08, 127.0.0.1:46838][0m
ERROR --- 2024-02-09 14:00:30,835 --- log --- log.py --- Internal Server Error: /support/chat/
Traceback (most recent call last):
  File "/mnt/myprojects/project/mysite/venv/lib/python3.11/site-packages/django/db/backends/utils.py", line 89, in _execute
    return self.cursor.execute(sql, params)
           ^^^^^^^^^^^^^^^^^^^^^^^^^^^^^^^^
psycopg2.errors.NotNullViolation: ОШИБКА:  значение NULL в столбце "slug" отношения "support_chatroom" нарушает ограничение NOT NULL
DETAIL:  Ошибочная строка содержит (37, 3, null, null).


The above exception was the direct cause of the following exception:

Traceback (most recent call last):
  File "/mnt/myprojects/project/mysite/venv/lib/python3.11/site-packages/asgiref/sync.py", line 534, in thread_handler
    raise exc_info[1]
  File "/mnt/myprojects/project/mysite/venv/lib/python3.11/site-packages/django/core/handlers/exception.py", line 42, in inner
    response = await get_response(request)
               ^^^^^^^^^^^^^^^^^^^^^^^^^^^
  File "/mnt/myprojects/project/mysite/venv/lib/python3.11/site-packages/asgiref/sync.py", line 534, in thread_handler
    raise exc_info[1]
  File "/mnt/myprojects/project/mysite/venv/lib/python3.11/site-packages/django/core/handlers/base.py", line 253, in _get_response_async
    response = await wrapped_callback(
               ^^^^^^^^^^^^^^^^^^^^^^^
  File "/mnt/myprojects/project/mysite/venv/lib/python3.11/site-packages/asgiref/sync.py", line 479, in __call__
    ret: _R = await loop.run_in_executor(
              ^^^^^^^^^^^^^^^^^^^^^^^^^^^
  File "/home/kenun/.python3.11/lib/python3.11/concurrent/futures/thread.py", line 58, in run
    result = self.fn(*self.args, **self.kwargs)
             ^^^^^^^^^^^^^^^^^^^^^^^^^^^^^^^^^^
  File "/mnt/myprojects/project/mysite/venv/lib/python3.11/site-packages/asgiref/sync.py", line 538, in thread_handler
    return func(*args, **kwargs)
           ^^^^^^^^^^^^^^^^^^^^^
  File "/mnt/myprojects/project/mysite/venv/lib/python3.11/site-packages/django/views/generic/base.py", line 104, in view
    return self.dispatch(request, *args, **kwargs)
           ^^^^^^^^^^^^^^^^^^^^^^^^^^^^^^^^^^^^^^^
  File "/mnt/myprojects/project/mysite/venv/lib/python3.11/site-packages/django/views/generic/base.py", line 143, in dispatch
    return handler(request, *args, **kwargs)
           ^^^^^^^^^^^^^^^^^^^^^^^^^^^^^^^^^
  File "/mnt/myprojects/project/mysite/venv/lib/python3.11/site-packages/django/views/generic/base.py", line 226, in get
    context = self.get_context_data(**kwargs)
              ^^^^^^^^^^^^^^^^^^^^^^^^^^^^^^^
  File "/mnt/myprojects/project/mysite/support/views.py", line 38, in get_context_data
    ChatRoom.objects.create(
  File "/mnt/myprojects/project/mysite/venv/lib/python3.11/site-packages/django/db/models/manager.py", line 87, in manager_method
    return getattr(self.get_queryset(), name)(*args, **kwargs)
           ^^^^^^^^^^^^^^^^^^^^^^^^^^^^^^^^^^^^^^^^^^^^^^^^^^^
  File "/mnt/myprojects/project/mysite/venv/lib/python3.11/site-packages/django/db/models/query.py", line 658, in create
    obj.save(force_insert=True, using=self.db)
  File "/mnt/myprojects/project/mysite/venv/lib/python3.11/site-packages/django/db/models/base.py", line 814, in save
    self.save_base(
  File "/mnt/myprojects/project/mysite/venv/lib/python3.11/site-packages/django/db/models/base.py", line 877, in save_base
    updated = self._save_table(
              ^^^^^^^^^^^^^^^^^
  File "/mnt/myprojects/project/mysite/venv/lib/python3.11/site-packages/django/db/models/base.py", line 1020, in _save_table
    results = self._do_insert(
              ^^^^^^^^^^^^^^^^
  File "/mnt/myprojects/project/mysite/venv/lib/python3.11/site-packages/django/db/models/base.py", line 1061, in _do_insert
    return manager._insert(
           ^^^^^^^^^^^^^^^^
  File "/mnt/myprojects/project/mysite/venv/lib/python3.11/site-packages/django/db/models/manager.py", line 87, in manager_method
    return getattr(self.get_queryset(), name)(*args, **kwargs)
           ^^^^^^^^^^^^^^^^^^^^^^^^^^^^^^^^^^^^^^^^^^^^^^^^^^^
  File "/mnt/myprojects/project/mysite/venv/lib/python3.11/site-packages/django/db/models/query.py", line 1805, in _insert
    return query.get_compiler(using=using).execute_sql(returning_fields)
           ^^^^^^^^^^^^^^^^^^^^^^^^^^^^^^^^^^^^^^^^^^^^^^^^^^^^^^^^^^^^^
  File "/mnt/myprojects/project/mysite/venv/lib/python3.11/site-packages/django/db/models/sql/compiler.py", line 1820, in execute_sql
    cursor.execute(sql, params)
  File "/mnt/myprojects/project/mysite/venv/lib/python3.11/site-packages/django/db/backends/utils.py", line 102, in execute
    return super().execute(sql, params)
           ^^^^^^^^^^^^^^^^^^^^^^^^^^^^
  File "/mnt/myprojects/project/mysite/venv/lib/python3.11/site-packages/django/db/backends/utils.py", line 67, in execute
    return self._execute_with_wrappers(
           ^^^^^^^^^^^^^^^^^^^^^^^^^^^^
  File "/mnt/myprojects/project/mysite/venv/lib/python3.11/site-packages/django/db/backends/utils.py", line 80, in _execute_with_wrappers
    return executor(sql, params, many, context)
           ^^^^^^^^^^^^^^^^^^^^^^^^^^^^^^^^^^^^
  File "/mnt/myprojects/project/mysite/venv/lib/python3.11/site-packages/django/db/backends/utils.py", line 84, in _execute
    with self.db.wrap_database_errors:
  File "/mnt/myprojects/project/mysite/venv/lib/python3.11/site-packages/django/db/utils.py", line 91, in __exit__
    raise dj_exc_value.with_traceback(traceback) from exc_value
  File "/mnt/myprojects/project/mysite/venv/lib/python3.11/site-packages/django/db/backends/utils.py", line 89, in _execute
    return self.cursor.execute(sql, params)
           ^^^^^^^^^^^^^^^^^^^^^^^^^^^^^^^^
django.db.utils.IntegrityError: ОШИБКА:  значение NULL в столбце "slug" отношения "support_chatroom" нарушает ограничение NOT NULL
DETAIL:  Ошибочная строка содержит (37, 3, null, null).

ERROR --- 2024-02-09 14:00:31,658 --- runserver --- runserver.py --- [35;1mHTTP GET /support/chat/ 500 [0.90, 127.0.0.1:44714][0m
ERROR --- 2024-02-09 14:00:33,647 --- log --- log.py --- Internal Server Error: /support/chat/
Traceback (most recent call last):
  File "/mnt/myprojects/project/mysite/venv/lib/python3.11/site-packages/django/db/backends/utils.py", line 89, in _execute
    return self.cursor.execute(sql, params)
           ^^^^^^^^^^^^^^^^^^^^^^^^^^^^^^^^
psycopg2.errors.NotNullViolation: ОШИБКА:  значение NULL в столбце "slug" отношения "support_chatroom" нарушает ограничение NOT NULL
DETAIL:  Ошибочная строка содержит (38, 3, null, null).


The above exception was the direct cause of the following exception:

Traceback (most recent call last):
  File "/mnt/myprojects/project/mysite/venv/lib/python3.11/site-packages/asgiref/sync.py", line 534, in thread_handler
    raise exc_info[1]
  File "/mnt/myprojects/project/mysite/venv/lib/python3.11/site-packages/django/core/handlers/exception.py", line 42, in inner
    response = await get_response(request)
               ^^^^^^^^^^^^^^^^^^^^^^^^^^^
  File "/mnt/myprojects/project/mysite/venv/lib/python3.11/site-packages/asgiref/sync.py", line 534, in thread_handler
    raise exc_info[1]
  File "/mnt/myprojects/project/mysite/venv/lib/python3.11/site-packages/django/core/handlers/base.py", line 253, in _get_response_async
    response = await wrapped_callback(
               ^^^^^^^^^^^^^^^^^^^^^^^
  File "/mnt/myprojects/project/mysite/venv/lib/python3.11/site-packages/asgiref/sync.py", line 479, in __call__
    ret: _R = await loop.run_in_executor(
              ^^^^^^^^^^^^^^^^^^^^^^^^^^^
  File "/home/kenun/.python3.11/lib/python3.11/concurrent/futures/thread.py", line 58, in run
    result = self.fn(*self.args, **self.kwargs)
             ^^^^^^^^^^^^^^^^^^^^^^^^^^^^^^^^^^
  File "/mnt/myprojects/project/mysite/venv/lib/python3.11/site-packages/asgiref/sync.py", line 538, in thread_handler
    return func(*args, **kwargs)
           ^^^^^^^^^^^^^^^^^^^^^
  File "/mnt/myprojects/project/mysite/venv/lib/python3.11/site-packages/django/views/generic/base.py", line 104, in view
    return self.dispatch(request, *args, **kwargs)
           ^^^^^^^^^^^^^^^^^^^^^^^^^^^^^^^^^^^^^^^
  File "/mnt/myprojects/project/mysite/venv/lib/python3.11/site-packages/django/views/generic/base.py", line 143, in dispatch
    return handler(request, *args, **kwargs)
           ^^^^^^^^^^^^^^^^^^^^^^^^^^^^^^^^^
  File "/mnt/myprojects/project/mysite/venv/lib/python3.11/site-packages/django/views/generic/base.py", line 226, in get
    context = self.get_context_data(**kwargs)
              ^^^^^^^^^^^^^^^^^^^^^^^^^^^^^^^
  File "/mnt/myprojects/project/mysite/support/views.py", line 38, in get_context_data
    ChatRoom.objects.create(
  File "/mnt/myprojects/project/mysite/venv/lib/python3.11/site-packages/django/db/models/manager.py", line 87, in manager_method
    return getattr(self.get_queryset(), name)(*args, **kwargs)
           ^^^^^^^^^^^^^^^^^^^^^^^^^^^^^^^^^^^^^^^^^^^^^^^^^^^
  File "/mnt/myprojects/project/mysite/venv/lib/python3.11/site-packages/django/db/models/query.py", line 658, in create
    obj.save(force_insert=True, using=self.db)
  File "/mnt/myprojects/project/mysite/venv/lib/python3.11/site-packages/django/db/models/base.py", line 814, in save
    self.save_base(
  File "/mnt/myprojects/project/mysite/venv/lib/python3.11/site-packages/django/db/models/base.py", line 877, in save_base
    updated = self._save_table(
              ^^^^^^^^^^^^^^^^^
  File "/mnt/myprojects/project/mysite/venv/lib/python3.11/site-packages/django/db/models/base.py", line 1020, in _save_table
    results = self._do_insert(
              ^^^^^^^^^^^^^^^^
  File "/mnt/myprojects/project/mysite/venv/lib/python3.11/site-packages/django/db/models/base.py", line 1061, in _do_insert
    return manager._insert(
           ^^^^^^^^^^^^^^^^
  File "/mnt/myprojects/project/mysite/venv/lib/python3.11/site-packages/django/db/models/manager.py", line 87, in manager_method
    return getattr(self.get_queryset(), name)(*args, **kwargs)
           ^^^^^^^^^^^^^^^^^^^^^^^^^^^^^^^^^^^^^^^^^^^^^^^^^^^
  File "/mnt/myprojects/project/mysite/venv/lib/python3.11/site-packages/django/db/models/query.py", line 1805, in _insert
    return query.get_compiler(using=using).execute_sql(returning_fields)
           ^^^^^^^^^^^^^^^^^^^^^^^^^^^^^^^^^^^^^^^^^^^^^^^^^^^^^^^^^^^^^
  File "/mnt/myprojects/project/mysite/venv/lib/python3.11/site-packages/django/db/models/sql/compiler.py", line 1820, in execute_sql
    cursor.execute(sql, params)
  File "/mnt/myprojects/project/mysite/venv/lib/python3.11/site-packages/django/db/backends/utils.py", line 102, in execute
    return super().execute(sql, params)
           ^^^^^^^^^^^^^^^^^^^^^^^^^^^^
  File "/mnt/myprojects/project/mysite/venv/lib/python3.11/site-packages/django/db/backends/utils.py", line 67, in execute
    return self._execute_with_wrappers(
           ^^^^^^^^^^^^^^^^^^^^^^^^^^^^
  File "/mnt/myprojects/project/mysite/venv/lib/python3.11/site-packages/django/db/backends/utils.py", line 80, in _execute_with_wrappers
    return executor(sql, params, many, context)
           ^^^^^^^^^^^^^^^^^^^^^^^^^^^^^^^^^^^^
  File "/mnt/myprojects/project/mysite/venv/lib/python3.11/site-packages/django/db/backends/utils.py", line 84, in _execute
    with self.db.wrap_database_errors:
  File "/mnt/myprojects/project/mysite/venv/lib/python3.11/site-packages/django/db/utils.py", line 91, in __exit__
    raise dj_exc_value.with_traceback(traceback) from exc_value
  File "/mnt/myprojects/project/mysite/venv/lib/python3.11/site-packages/django/db/backends/utils.py", line 89, in _execute
    return self.cursor.execute(sql, params)
           ^^^^^^^^^^^^^^^^^^^^^^^^^^^^^^^^
django.db.utils.IntegrityError: ОШИБКА:  значение NULL в столбце "slug" отношения "support_chatroom" нарушает ограничение NOT NULL
DETAIL:  Ошибочная строка содержит (38, 3, null, null).

ERROR --- 2024-02-09 14:00:34,310 --- runserver --- runserver.py --- [35;1mHTTP GET /support/chat/ 500 [0.77, 127.0.0.1:44714][0m
ERROR --- 2024-02-09 14:01:10,886 --- log --- log.py --- Internal Server Error: /support/chat/
Traceback (most recent call last):
  File "/mnt/myprojects/project/mysite/venv/lib/python3.11/site-packages/asgiref/sync.py", line 534, in thread_handler
    raise exc_info[1]
  File "/mnt/myprojects/project/mysite/venv/lib/python3.11/site-packages/django/core/handlers/exception.py", line 42, in inner
    response = await get_response(request)
               ^^^^^^^^^^^^^^^^^^^^^^^^^^^
  File "/mnt/myprojects/project/mysite/venv/lib/python3.11/site-packages/asgiref/sync.py", line 534, in thread_handler
    raise exc_info[1]
  File "/mnt/myprojects/project/mysite/venv/lib/python3.11/site-packages/django/core/handlers/base.py", line 284, in _get_response_async
    response = await sync_to_async(
               ^^^^^^^^^^^^^^^^^^^^
  File "/mnt/myprojects/project/mysite/venv/lib/python3.11/site-packages/asgiref/sync.py", line 479, in __call__
    ret: _R = await loop.run_in_executor(
              ^^^^^^^^^^^^^^^^^^^^^^^^^^^
  File "/home/kenun/.python3.11/lib/python3.11/concurrent/futures/thread.py", line 58, in run
    result = self.fn(*self.args, **self.kwargs)
             ^^^^^^^^^^^^^^^^^^^^^^^^^^^^^^^^^^
  File "/mnt/myprojects/project/mysite/venv/lib/python3.11/site-packages/asgiref/sync.py", line 538, in thread_handler
    return func(*args, **kwargs)
           ^^^^^^^^^^^^^^^^^^^^^
  File "/mnt/myprojects/project/mysite/venv/lib/python3.11/site-packages/django/template/response.py", line 114, in render
    self.content = self.rendered_content
                   ^^^^^^^^^^^^^^^^^^^^^
  File "/mnt/myprojects/project/mysite/venv/lib/python3.11/site-packages/django/template/response.py", line 92, in rendered_content
    return template.render(context, self._request)
           ^^^^^^^^^^^^^^^^^^^^^^^^^^^^^^^^^^^^^^^
  File "/mnt/myprojects/project/mysite/venv/lib/python3.11/site-packages/django/template/backends/django.py", line 57, in render
    context = make_context(
              ^^^^^^^^^^^^^
  File "/mnt/myprojects/project/mysite/venv/lib/python3.11/site-packages/django/template/context.py", line 278, in make_context
    raise TypeError(
TypeError: context must be a dict rather than HttpResponseRedirect.
ERROR --- 2024-02-09 14:01:11,509 --- runserver --- runserver.py --- [35;1mHTTP GET /support/chat/ 500 [0.68, 127.0.0.1:57766][0m
ERROR --- 2024-02-09 14:01:12,996 --- log --- log.py --- Internal Server Error: /support/chat/
Traceback (most recent call last):
  File "/mnt/myprojects/project/mysite/venv/lib/python3.11/site-packages/asgiref/sync.py", line 534, in thread_handler
    raise exc_info[1]
  File "/mnt/myprojects/project/mysite/venv/lib/python3.11/site-packages/django/core/handlers/exception.py", line 42, in inner
    response = await get_response(request)
               ^^^^^^^^^^^^^^^^^^^^^^^^^^^
  File "/mnt/myprojects/project/mysite/venv/lib/python3.11/site-packages/asgiref/sync.py", line 534, in thread_handler
    raise exc_info[1]
  File "/mnt/myprojects/project/mysite/venv/lib/python3.11/site-packages/django/core/handlers/base.py", line 284, in _get_response_async
    response = await sync_to_async(
               ^^^^^^^^^^^^^^^^^^^^
  File "/mnt/myprojects/project/mysite/venv/lib/python3.11/site-packages/asgiref/sync.py", line 479, in __call__
    ret: _R = await loop.run_in_executor(
              ^^^^^^^^^^^^^^^^^^^^^^^^^^^
  File "/home/kenun/.python3.11/lib/python3.11/concurrent/futures/thread.py", line 58, in run
    result = self.fn(*self.args, **self.kwargs)
             ^^^^^^^^^^^^^^^^^^^^^^^^^^^^^^^^^^
  File "/mnt/myprojects/project/mysite/venv/lib/python3.11/site-packages/asgiref/sync.py", line 538, in thread_handler
    return func(*args, **kwargs)
           ^^^^^^^^^^^^^^^^^^^^^
  File "/mnt/myprojects/project/mysite/venv/lib/python3.11/site-packages/django/template/response.py", line 114, in render
    self.content = self.rendered_content
                   ^^^^^^^^^^^^^^^^^^^^^
  File "/mnt/myprojects/project/mysite/venv/lib/python3.11/site-packages/django/template/response.py", line 92, in rendered_content
    return template.render(context, self._request)
           ^^^^^^^^^^^^^^^^^^^^^^^^^^^^^^^^^^^^^^^
  File "/mnt/myprojects/project/mysite/venv/lib/python3.11/site-packages/django/template/backends/django.py", line 57, in render
    context = make_context(
              ^^^^^^^^^^^^^
  File "/mnt/myprojects/project/mysite/venv/lib/python3.11/site-packages/django/template/context.py", line 278, in make_context
    raise TypeError(
TypeError: context must be a dict rather than HttpResponseRedirect.
ERROR --- 2024-02-09 14:01:13,713 --- runserver --- runserver.py --- [35;1mHTTP GET /support/chat/ 500 [0.77, 127.0.0.1:57766][0m
ERROR --- 2024-02-09 14:04:11,621 --- log --- log.py --- Internal Server Error: /support/chat/
Traceback (most recent call last):
  File "/mnt/myprojects/project/mysite/venv/lib/python3.11/site-packages/asgiref/sync.py", line 534, in thread_handler
    raise exc_info[1]
  File "/mnt/myprojects/project/mysite/venv/lib/python3.11/site-packages/django/core/handlers/exception.py", line 42, in inner
    response = await get_response(request)
               ^^^^^^^^^^^^^^^^^^^^^^^^^^^
  File "/mnt/myprojects/project/mysite/venv/lib/python3.11/site-packages/asgiref/sync.py", line 534, in thread_handler
    raise exc_info[1]
  File "/mnt/myprojects/project/mysite/venv/lib/python3.11/site-packages/django/core/handlers/base.py", line 284, in _get_response_async
    response = await sync_to_async(
               ^^^^^^^^^^^^^^^^^^^^
  File "/mnt/myprojects/project/mysite/venv/lib/python3.11/site-packages/asgiref/sync.py", line 479, in __call__
    ret: _R = await loop.run_in_executor(
              ^^^^^^^^^^^^^^^^^^^^^^^^^^^
  File "/home/kenun/.python3.11/lib/python3.11/concurrent/futures/thread.py", line 58, in run
    result = self.fn(*self.args, **self.kwargs)
             ^^^^^^^^^^^^^^^^^^^^^^^^^^^^^^^^^^
  File "/mnt/myprojects/project/mysite/venv/lib/python3.11/site-packages/asgiref/sync.py", line 538, in thread_handler
    return func(*args, **kwargs)
           ^^^^^^^^^^^^^^^^^^^^^
  File "/mnt/myprojects/project/mysite/venv/lib/python3.11/site-packages/django/template/response.py", line 114, in render
    self.content = self.rendered_content
                   ^^^^^^^^^^^^^^^^^^^^^
  File "/mnt/myprojects/project/mysite/venv/lib/python3.11/site-packages/django/template/response.py", line 92, in rendered_content
    return template.render(context, self._request)
           ^^^^^^^^^^^^^^^^^^^^^^^^^^^^^^^^^^^^^^^
  File "/mnt/myprojects/project/mysite/venv/lib/python3.11/site-packages/django/template/backends/django.py", line 57, in render
    context = make_context(
              ^^^^^^^^^^^^^
  File "/mnt/myprojects/project/mysite/venv/lib/python3.11/site-packages/django/template/context.py", line 278, in make_context
    raise TypeError(
TypeError: context must be a dict rather than HttpResponseRedirect.
ERROR --- 2024-02-09 14:04:12,283 --- runserver --- runserver.py --- [35;1mHTTP GET /support/chat/ 500 [0.75, 127.0.0.1:45616][0m
WARNING --- 2024-02-09 14:04:13,023 --- log --- log.py --- Not Found: /favicon.ico
WARNING --- 2024-02-09 14:04:13,024 --- runserver --- runserver.py --- [33mHTTP GET /favicon.ico 404 [0.01, 127.0.0.1:45616][0m
ERROR --- 2024-02-09 14:04:13,221 --- log --- log.py --- Internal Server Error: /support/chat/
Traceback (most recent call last):
  File "/mnt/myprojects/project/mysite/venv/lib/python3.11/site-packages/asgiref/sync.py", line 534, in thread_handler
    raise exc_info[1]
  File "/mnt/myprojects/project/mysite/venv/lib/python3.11/site-packages/django/core/handlers/exception.py", line 42, in inner
    response = await get_response(request)
               ^^^^^^^^^^^^^^^^^^^^^^^^^^^
  File "/mnt/myprojects/project/mysite/venv/lib/python3.11/site-packages/asgiref/sync.py", line 534, in thread_handler
    raise exc_info[1]
  File "/mnt/myprojects/project/mysite/venv/lib/python3.11/site-packages/django/core/handlers/base.py", line 284, in _get_response_async
    response = await sync_to_async(
               ^^^^^^^^^^^^^^^^^^^^
  File "/mnt/myprojects/project/mysite/venv/lib/python3.11/site-packages/asgiref/sync.py", line 479, in __call__
    ret: _R = await loop.run_in_executor(
              ^^^^^^^^^^^^^^^^^^^^^^^^^^^
  File "/home/kenun/.python3.11/lib/python3.11/concurrent/futures/thread.py", line 58, in run
    result = self.fn(*self.args, **self.kwargs)
             ^^^^^^^^^^^^^^^^^^^^^^^^^^^^^^^^^^
  File "/mnt/myprojects/project/mysite/venv/lib/python3.11/site-packages/asgiref/sync.py", line 538, in thread_handler
    return func(*args, **kwargs)
           ^^^^^^^^^^^^^^^^^^^^^
  File "/mnt/myprojects/project/mysite/venv/lib/python3.11/site-packages/django/template/response.py", line 114, in render
    self.content = self.rendered_content
                   ^^^^^^^^^^^^^^^^^^^^^
  File "/mnt/myprojects/project/mysite/venv/lib/python3.11/site-packages/django/template/response.py", line 92, in rendered_content
    return template.render(context, self._request)
           ^^^^^^^^^^^^^^^^^^^^^^^^^^^^^^^^^^^^^^^
  File "/mnt/myprojects/project/mysite/venv/lib/python3.11/site-packages/django/template/backends/django.py", line 57, in render
    context = make_context(
              ^^^^^^^^^^^^^
  File "/mnt/myprojects/project/mysite/venv/lib/python3.11/site-packages/django/template/context.py", line 278, in make_context
    raise TypeError(
TypeError: context must be a dict rather than HttpResponseRedirect.
ERROR --- 2024-02-09 14:04:13,968 --- runserver --- runserver.py --- [35;1mHTTP GET /support/chat/ 500 [0.79, 127.0.0.1:45616][0m
WARNING --- 2024-02-09 17:27:44,542 --- log --- log.py --- Not Found: /favicon.ico
WARNING --- 2024-02-09 17:27:44,563 --- runserver --- runserver.py --- [33mHTTP GET /favicon.ico 404 [0.04, 127.0.0.1:49130][0m
WARNING --- 2024-02-09 17:54:33,553 --- log --- log.py --- Not Found: /@
WARNING --- 2024-02-09 17:54:33,561 --- runserver --- runserver.py --- [33mHTTP GET /@ 404 [0.09, 127.0.0.1:39082][0m
WARNING --- 2024-02-09 17:54:33,895 --- log --- log.py --- Not Found: /favicon.ico
WARNING --- 2024-02-09 17:54:33,896 --- runserver --- runserver.py --- [33mHTTP GET /favicon.ico 404 [0.03, 127.0.0.1:39082][0m
ERROR --- 2024-02-09 18:03:01,282 --- log --- log.py --- Internal Server Error: /addons/CleansingTimer
Traceback (most recent call last):
  File "/mnt/myprojects/project/mysite/venv/lib/python3.11/site-packages/asgiref/sync.py", line 534, in thread_handler
    raise exc_info[1]
  File "/mnt/myprojects/project/mysite/venv/lib/python3.11/site-packages/django/core/handlers/exception.py", line 42, in inner
    response = await get_response(request)
               ^^^^^^^^^^^^^^^^^^^^^^^^^^^
  File "/mnt/myprojects/project/mysite/venv/lib/python3.11/site-packages/asgiref/sync.py", line 534, in thread_handler
    raise exc_info[1]
  File "/mnt/myprojects/project/mysite/venv/lib/python3.11/site-packages/django/core/handlers/base.py", line 253, in _get_response_async
    response = await wrapped_callback(
               ^^^^^^^^^^^^^^^^^^^^^^^
  File "/mnt/myprojects/project/mysite/venv/lib/python3.11/site-packages/asgiref/sync.py", line 479, in __call__
    ret: _R = await loop.run_in_executor(
              ^^^^^^^^^^^^^^^^^^^^^^^^^^^
  File "/home/kenun/.python3.11/lib/python3.11/concurrent/futures/thread.py", line 58, in run
    result = self.fn(*self.args, **self.kwargs)
             ^^^^^^^^^^^^^^^^^^^^^^^^^^^^^^^^^^
  File "/mnt/myprojects/project/mysite/venv/lib/python3.11/site-packages/asgiref/sync.py", line 538, in thread_handler
    return func(*args, **kwargs)
           ^^^^^^^^^^^^^^^^^^^^^
  File "/mnt/myprojects/project/mysite/venv/lib/python3.11/site-packages/django/views/generic/base.py", line 104, in view
    return self.dispatch(request, *args, **kwargs)
           ^^^^^^^^^^^^^^^^^^^^^^^^^^^^^^^^^^^^^^^
  File "/mnt/myprojects/project/mysite/venv/lib/python3.11/site-packages/django/views/generic/base.py", line 143, in dispatch
    return handler(request, *args, **kwargs)
           ^^^^^^^^^^^^^^^^^^^^^^^^^^^^^^^^^
  File "/mnt/myprojects/project/mysite/venv/lib/python3.11/site-packages/django/views/generic/base.py", line 226, in get
    context = self.get_context_data(**kwargs)
              ^^^^^^^^^^^^^^^^^^^^^^^^^^^^^^^
  File "/mnt/myprojects/project/mysite/addons/views.py", line 71, in get_context_data
    context['paid'] = Order.objects.filter(user=user, addon=context['addon'][0], status=True).exists()
                                                            ~~~~~~~~~~~~~~~~^^^
TypeError: 'Addon' object is not subscriptable
ERROR --- 2024-02-09 18:03:02,291 --- runserver --- runserver.py --- [35;1mHTTP GET /addons/CleansingTimer 500 [1.24, 127.0.0.1:58288][0m
WARNING --- 2024-02-09 18:03:51,818 --- log --- log.py --- Not Found: /@
WARNING --- 2024-02-09 18:03:51,838 --- runserver --- runserver.py --- [33mHTTP GET /@ 404 [0.11, 127.0.0.1:33988][0m
WARNING --- 2024-02-10 17:50:19,733 --- runserver --- runserver.py --- [33mHTTP GET /static/img/icon/LOGO.png%3E%20%20%20%20%20%20%3Clink%20rel= 404 [0.01, 127.0.0.1:54164][0m
WARNING --- 2024-02-10 17:50:58,813 --- runserver --- runserver.py --- [33mHTTP GET /static/img/icon/LOGO.png%3E%20%20%20%20%20%20%3Clink%20rel= 404 [0.01, 127.0.0.1:54164][0m
WARNING --- 2024-02-10 17:50:59,297 --- log --- log.py --- Not Found: /favicon.ico
WARNING --- 2024-02-10 17:50:59,298 --- runserver --- runserver.py --- [33mHTTP GET /favicon.ico 404 [0.03, 127.0.0.1:54164][0m
WARNING --- 2024-02-10 17:52:49,322 --- runserver --- runserver.py --- [33mHTTP GET /static/img/icon/LOGO.png%3E%20%20%20%20%20%20%3Clink%20rel= 404 [0.01, 127.0.0.1:59316][0m
WARNING --- 2024-02-10 17:54:57,417 --- runserver --- runserver.py --- [33mHTTP GET /static/img/icon/LOGO.png%3E%20%20%20%20%20%20%3Clink%20rel= 404 [0.01, 127.0.0.1:34654][0m
WARNING --- 2024-02-10 22:30:46,643 --- log --- log.py --- Not Found: /favicon.ico
WARNING --- 2024-02-10 22:30:46,649 --- runserver --- runserver.py --- HTTP GET /favicon.ico 404 [0.01, 172.18.0.1:34032]
WARNING --- 2024-02-10 23:08:26,203 --- log --- log.py --- Not Found: /favicon.ico
WARNING --- 2024-02-10 23:08:26,215 --- runserver --- runserver.py --- [33mHTTP GET /favicon.ico 404 [0.05, 127.0.0.1:43032][0m
WARNING --- 2024-02-10 23:23:26,999 --- log --- log.py --- Forbidden (Permission denied): /flower/
Traceback (most recent call last):
  File "/usr/local/lib/python3.11/site-packages/asgiref/sync.py", line 534, in thread_handler
    raise exc_info[1]
  File "/usr/local/lib/python3.11/site-packages/django/core/handlers/exception.py", line 42, in inner
    response = await get_response(request)
               ^^^^^^^^^^^^^^^^^^^^^^^^^^^
  File "/usr/local/lib/python3.11/site-packages/asgiref/sync.py", line 534, in thread_handler
    raise exc_info[1]
  File "/usr/local/lib/python3.11/site-packages/django/core/handlers/base.py", line 253, in _get_response_async
    response = await wrapped_callback(
               ^^^^^^^^^^^^^^^^^^^^^^^
  File "/usr/local/lib/python3.11/site-packages/asgiref/sync.py", line 479, in __call__
    ret: _R = await loop.run_in_executor(
              ^^^^^^^^^^^^^^^^^^^^^^^^^^^
  File "/usr/local/lib/python3.11/concurrent/futures/thread.py", line 58, in run
    result = self.fn(*self.args, **self.kwargs)
             ^^^^^^^^^^^^^^^^^^^^^^^^^^^^^^^^^^
  File "/usr/local/lib/python3.11/site-packages/asgiref/sync.py", line 538, in thread_handler
    return func(*args, **kwargs)
           ^^^^^^^^^^^^^^^^^^^^^
  File "/usr/local/lib/python3.11/site-packages/django/views/decorators/csrf.py", line 56, in wrapper_view
    return view_func(*args, **kwargs)
           ^^^^^^^^^^^^^^^^^^^^^^^^^^
  File "/mysite/HomePage/views.py", line 150, in flower_proxy_view
    if not request.user.is_superuser: raise PermissionDenied
                                      ^^^^^^^^^^^^^^^^^^^^^^
django.core.exceptions.PermissionDenied
WARNING --- 2024-02-10 23:23:27,026 --- runserver --- runserver.py --- HTTP GET /flower/ 403 [0.03, 172.18.0.1:33470]
WARNING --- 2024-02-10 23:23:27,353 --- log --- log.py --- Forbidden (Permission denied): /flower/
Traceback (most recent call last):
  File "/usr/local/lib/python3.11/site-packages/asgiref/sync.py", line 534, in thread_handler
    raise exc_info[1]
  File "/usr/local/lib/python3.11/site-packages/django/core/handlers/exception.py", line 42, in inner
    response = await get_response(request)
               ^^^^^^^^^^^^^^^^^^^^^^^^^^^
  File "/usr/local/lib/python3.11/site-packages/asgiref/sync.py", line 534, in thread_handler
    raise exc_info[1]
  File "/usr/local/lib/python3.11/site-packages/django/core/handlers/base.py", line 253, in _get_response_async
    response = await wrapped_callback(
               ^^^^^^^^^^^^^^^^^^^^^^^
  File "/usr/local/lib/python3.11/site-packages/asgiref/sync.py", line 479, in __call__
    ret: _R = await loop.run_in_executor(
              ^^^^^^^^^^^^^^^^^^^^^^^^^^^
  File "/usr/local/lib/python3.11/concurrent/futures/thread.py", line 58, in run
    result = self.fn(*self.args, **self.kwargs)
             ^^^^^^^^^^^^^^^^^^^^^^^^^^^^^^^^^^
  File "/usr/local/lib/python3.11/site-packages/asgiref/sync.py", line 538, in thread_handler
    return func(*args, **kwargs)
           ^^^^^^^^^^^^^^^^^^^^^
  File "/usr/local/lib/python3.11/site-packages/django/views/decorators/csrf.py", line 56, in wrapper_view
    return view_func(*args, **kwargs)
           ^^^^^^^^^^^^^^^^^^^^^^^^^^
  File "/mysite/HomePage/views.py", line 150, in flower_proxy_view
    if not request.user.is_superuser: raise PermissionDenied
                                      ^^^^^^^^^^^^^^^^^^^^^^
django.core.exceptions.PermissionDenied
WARNING --- 2024-02-10 23:23:27,358 --- runserver --- runserver.py --- HTTP GET /flower/ 403 [0.01, 172.18.0.1:33470]
WARNING --- 2024-02-11 13:02:56,238 --- runserver --- runserver.py --- HTTP GET /static/js/javascript/wow-model-viewer/viewer_wrath.min.js 404 [0.01, 172.18.0.1:55996]
WARNING --- 2024-02-11 13:02:59,203 --- runserver --- runserver.py --- HTTP GET /static/chat.css 404 [0.01, 172.18.0.1:55996]
WARNING --- 2024-02-11 13:02:59,226 --- runserver --- runserver.py --- HTTP GET /static/img/other/send_message.png 404 [0.03, 172.18.0.1:56004]
WARNING --- 2024-02-11 13:02:59,228 --- runserver --- runserver.py --- HTTP GET /static/img/other/support_icon.png 404 [0.03, 172.18.0.1:56028]
WARNING --- 2024-02-11 13:03:02,072 --- runserver --- runserver.py --- HTTP GET /static/img/other/send_message.png 404 [0.02, 172.18.0.1:55996]
WARNING --- 2024-02-11 13:03:02,073 --- runserver --- runserver.py --- HTTP GET /static/chat.css 404 [0.02, 172.18.0.1:56028]
WARNING --- 2024-02-11 13:03:02,074 --- runserver --- runserver.py --- HTTP GET /static/img/other/support_icon.png 404 [0.02, 172.18.0.1:56004]
WARNING --- 2024-02-11 13:03:10,333 --- runserver --- runserver.py --- HTTP GET /static/img/other/support_icon.png 404 [0.02, 172.18.0.1:56028]
WARNING --- 2024-02-11 13:03:10,341 --- runserver --- runserver.py --- HTTP GET /static/chat.css 404 [0.03, 172.18.0.1:56004]
WARNING --- 2024-02-11 13:03:10,343 --- runserver --- runserver.py --- HTTP GET /static/img/other/send_message.png 404 [0.03, 172.18.0.1:55996]
WARNING --- 2024-02-11 13:03:12,243 --- runserver --- runserver.py --- HTTP GET /static/chat.css 404 [0.01, 172.18.0.1:55996]
WARNING --- 2024-02-11 13:04:56,898 --- runserver --- runserver.py --- HTTP GET /static/img/other/send_message.png 404 [0.01, 172.18.0.1:37472]
WARNING --- 2024-02-11 13:04:56,903 --- runserver --- runserver.py --- HTTP GET /static/chat.css 404 [0.02, 172.18.0.1:37470]
WARNING --- 2024-02-11 13:04:56,923 --- runserver --- runserver.py --- HTTP GET /static/img/other/support_icon.png 404 [0.01, 172.18.0.1:37470]
WARNING --- 2024-02-11 13:05:00,543 --- runserver --- runserver.py --- HTTP GET /static/chat.css 404 [0.02, 172.18.0.1:37470]
WARNING --- 2024-02-11 13:05:00,560 --- runserver --- runserver.py --- HTTP GET /static/img/other/send_message.png 404 [0.02, 172.18.0.1:37502]
WARNING --- 2024-02-11 13:05:00,562 --- runserver --- runserver.py --- HTTP GET /static/img/other/support_icon.png 404 [0.03, 172.18.0.1:37472]
WARNING --- 2024-02-11 13:05:09,603 --- runserver --- runserver.py --- HTTP GET /static/js/javascript/wow-model-viewer/viewer_wrath.min.js 404 [0.01, 172.18.0.1:37472]
WARNING --- 2024-02-11 13:22:09,479 --- log --- log.py --- Not Found: /favicon.ico
WARNING --- 2024-02-11 13:22:09,480 --- runserver --- runserver.py --- [33mHTTP GET /favicon.ico 404 [0.04, 127.0.0.1:42510][0m
WARNING --- 2024-02-27 11:20:46,470 --- log --- log.py --- Not Found: /favicon.ico
WARNING --- 2024-02-27 11:20:46,471 --- runserver --- runserver.py --- [33mHTTP GET /favicon.ico 404 [0.02, 127.0.0.1:39842][0m
WARNING --- 2024-02-28 20:00:23,445 --- log --- log.py --- Not Found: /favicon.ico
WARNING --- 2024-02-28 20:00:23,446 --- runserver --- runserver.py --- [33mHTTP GET /favicon.ico 404 [0.01, 127.0.0.1:39154][0m
ERROR --- 2024-02-28 20:00:59,585 --- log --- log.py --- Internal Server Error: /services/
Traceback (most recent call last):
  File "/mnt/myprojects/project/mysite/venv/lib/python3.11/site-packages/redis/connection.py", line 264, in connect
    sock = self.retry.call_with_retry(
           ^^^^^^^^^^^^^^^^^^^^^^^^^^^
  File "/mnt/myprojects/project/mysite/venv/lib/python3.11/site-packages/redis/retry.py", line 46, in call_with_retry
    return do()
           ^^^^
  File "/mnt/myprojects/project/mysite/venv/lib/python3.11/site-packages/redis/connection.py", line 265, in <lambda>
    lambda: self._connect(), lambda error: self.disconnect(error)
            ^^^^^^^^^^^^^^^
  File "/mnt/myprojects/project/mysite/venv/lib/python3.11/site-packages/redis/connection.py", line 627, in _connect
    raise err
  File "/mnt/myprojects/project/mysite/venv/lib/python3.11/site-packages/redis/connection.py", line 615, in _connect
    sock.connect(socket_address)
ConnectionRefusedError: [Errno 111] Connection refused

During handling of the above exception, another exception occurred:

Traceback (most recent call last):
  File "/mnt/myprojects/project/mysite/venv/lib/python3.11/site-packages/celery/backends/redis.py", line 127, in reconnect_on_error
    yield
  File "/mnt/myprojects/project/mysite/venv/lib/python3.11/site-packages/celery/backends/redis.py", line 177, in _consume_from
    self._pubsub.subscribe(key)
  File "/mnt/myprojects/project/mysite/venv/lib/python3.11/site-packages/redis/client.py", line 916, in subscribe
    ret_val = self.execute_command("SUBSCRIBE", *new_channels.keys())
              ^^^^^^^^^^^^^^^^^^^^^^^^^^^^^^^^^^^^^^^^^^^^^^^^^^^^^^^
  File "/mnt/myprojects/project/mysite/venv/lib/python3.11/site-packages/redis/client.py", line 749, in execute_command
    self.connection = self.connection_pool.get_connection(
                      ^^^^^^^^^^^^^^^^^^^^^^^^^^^^^^^^^^^^
  File "/mnt/myprojects/project/mysite/venv/lib/python3.11/site-packages/redis/connection.py", line 1086, in get_connection
    connection.connect()
  File "/mnt/myprojects/project/mysite/venv/lib/python3.11/site-packages/redis/connection.py", line 270, in connect
    raise ConnectionError(self._error_message(e))
redis.exceptions.ConnectionError: Error 111 connecting to 127.0.0.1:6379. Connection refused.

During handling of the above exception, another exception occurred:

Traceback (most recent call last):
  File "/mnt/myprojects/project/mysite/venv/lib/python3.11/site-packages/redis/connection.py", line 264, in connect
    sock = self.retry.call_with_retry(
           ^^^^^^^^^^^^^^^^^^^^^^^^^^^
  File "/mnt/myprojects/project/mysite/venv/lib/python3.11/site-packages/redis/retry.py", line 46, in call_with_retry
    return do()
           ^^^^
  File "/mnt/myprojects/project/mysite/venv/lib/python3.11/site-packages/redis/connection.py", line 265, in <lambda>
    lambda: self._connect(), lambda error: self.disconnect(error)
            ^^^^^^^^^^^^^^^
  File "/mnt/myprojects/project/mysite/venv/lib/python3.11/site-packages/redis/connection.py", line 627, in _connect
    raise err
  File "/mnt/myprojects/project/mysite/venv/lib/python3.11/site-packages/redis/connection.py", line 615, in _connect
    sock.connect(socket_address)
ConnectionRefusedError: [Errno 111] Connection refused

During handling of the above exception, another exception occurred:

Traceback (most recent call last):
  File "/mnt/myprojects/project/mysite/venv/lib/python3.11/site-packages/kombu/connection.py", line 472, in _reraise_as_library_errors
    yield
  File "/mnt/myprojects/project/mysite/venv/lib/python3.11/site-packages/celery/app/base.py", line 798, in send_task
    self.backend.on_task_call(P, task_id)
  File "/mnt/myprojects/project/mysite/venv/lib/python3.11/site-packages/celery/backends/redis.py", line 373, in on_task_call
    self.result_consumer.consume_from(task_id)
  File "/mnt/myprojects/project/mysite/venv/lib/python3.11/site-packages/celery/backends/redis.py", line 169, in consume_from
    return self.start(task_id)
           ^^^^^^^^^^^^^^^^^^^
  File "/mnt/myprojects/project/mysite/venv/lib/python3.11/site-packages/celery/backends/redis.py", line 147, in start
    self._consume_from(initial_task_id)
  File "/mnt/myprojects/project/mysite/venv/lib/python3.11/site-packages/celery/backends/redis.py", line 176, in _consume_from
    with self.reconnect_on_error():
  File "/home/kenun/.python3.11/lib/python3.11/contextlib.py", line 158, in __exit__
    self.gen.throw(typ, value, traceback)
  File "/mnt/myprojects/project/mysite/venv/lib/python3.11/site-packages/celery/backends/redis.py", line 130, in reconnect_on_error
    self._ensure(self._reconnect_pubsub, ())
  File "/mnt/myprojects/project/mysite/venv/lib/python3.11/site-packages/celery/backends/redis.py", line 384, in ensure
    return retry_over_time(
           ^^^^^^^^^^^^^^^^
  File "/mnt/myprojects/project/mysite/venv/lib/python3.11/site-packages/kombu/utils/functional.py", line 318, in retry_over_time
    return fun(*args, **kwargs)
           ^^^^^^^^^^^^^^^^^^^^
  File "/mnt/myprojects/project/mysite/venv/lib/python3.11/site-packages/celery/backends/redis.py", line 106, in _reconnect_pubsub
    metas = self.backend.client.mget(self.subscribed_to)
            ^^^^^^^^^^^^^^^^^^^^^^^^^^^^^^^^^^^^^^^^^^^^
  File "/mnt/myprojects/project/mysite/venv/lib/python3.11/site-packages/redis/commands/core.py", line 2015, in mget
    return self.execute_command("MGET", *args, **options)
           ^^^^^^^^^^^^^^^^^^^^^^^^^^^^^^^^^^^^^^^^^^^^^^
  File "/mnt/myprojects/project/mysite/venv/lib/python3.11/site-packages/redis/client.py", line 533, in execute_command
    conn = self.connection or pool.get_connection(command_name, **options)
                              ^^^^^^^^^^^^^^^^^^^^^^^^^^^^^^^^^^^^^^^^^^^^
  File "/mnt/myprojects/project/mysite/venv/lib/python3.11/site-packages/redis/connection.py", line 1086, in get_connection
    connection.connect()
  File "/mnt/myprojects/project/mysite/venv/lib/python3.11/site-packages/redis/connection.py", line 270, in connect
    raise ConnectionError(self._error_message(e))
redis.exceptions.ConnectionError: Error 111 connecting to 127.0.0.1:6379. Connection refused.

The above exception was the direct cause of the following exception:

Traceback (most recent call last):
  File "/mnt/myprojects/project/mysite/venv/lib/python3.11/site-packages/asgiref/sync.py", line 534, in thread_handler
    raise exc_info[1]
  File "/mnt/myprojects/project/mysite/venv/lib/python3.11/site-packages/django/core/handlers/exception.py", line 42, in inner
    response = await get_response(request)
               ^^^^^^^^^^^^^^^^^^^^^^^^^^^
  File "/mnt/myprojects/project/mysite/venv/lib/python3.11/site-packages/asgiref/sync.py", line 534, in thread_handler
    raise exc_info[1]
  File "/mnt/myprojects/project/mysite/venv/lib/python3.11/site-packages/django/core/handlers/base.py", line 253, in _get_response_async
    response = await wrapped_callback(
               ^^^^^^^^^^^^^^^^^^^^^^^
  File "/mnt/myprojects/project/mysite/venv/lib/python3.11/site-packages/asgiref/sync.py", line 479, in __call__
    ret: _R = await loop.run_in_executor(
              ^^^^^^^^^^^^^^^^^^^^^^^^^^^
  File "/home/kenun/.python3.11/lib/python3.11/concurrent/futures/thread.py", line 58, in run
    result = self.fn(*self.args, **self.kwargs)
             ^^^^^^^^^^^^^^^^^^^^^^^^^^^^^^^^^^
  File "/mnt/myprojects/project/mysite/venv/lib/python3.11/site-packages/asgiref/sync.py", line 538, in thread_handler
    return func(*args, **kwargs)
           ^^^^^^^^^^^^^^^^^^^^^
  File "/mnt/myprojects/project/mysite/venv/lib/python3.11/site-packages/django/views/generic/base.py", line 104, in view
    return self.dispatch(request, *args, **kwargs)
           ^^^^^^^^^^^^^^^^^^^^^^^^^^^^^^^^^^^^^^^
  File "/mnt/myprojects/project/mysite/venv/lib/python3.11/site-packages/django/views/generic/base.py", line 143, in dispatch
    return handler(request, *args, **kwargs)
           ^^^^^^^^^^^^^^^^^^^^^^^^^^^^^^^^^
  File "/mnt/myprojects/project/mysite/services/views.py", line 70, in post
    send_telegram_message.delay(telegram_id, data)
  File "/mnt/myprojects/project/mysite/venv/lib/python3.11/site-packages/celery/app/task.py", line 444, in delay
    return self.apply_async(args, kwargs)
           ^^^^^^^^^^^^^^^^^^^^^^^^^^^^^^
  File "/mnt/myprojects/project/mysite/venv/lib/python3.11/site-packages/celery/app/task.py", line 594, in apply_async
    return app.send_task(
           ^^^^^^^^^^^^^^
  File "/mnt/myprojects/project/mysite/venv/lib/python3.11/site-packages/celery/app/base.py", line 796, in send_task
    with P.connection._reraise_as_library_errors():
  File "/home/kenun/.python3.11/lib/python3.11/contextlib.py", line 158, in __exit__
    self.gen.throw(typ, value, traceback)
  File "/mnt/myprojects/project/mysite/venv/lib/python3.11/site-packages/kombu/connection.py", line 476, in _reraise_as_library_errors
    raise ConnectionError(str(exc)) from exc
kombu.exceptions.OperationalError: Error 111 connecting to 127.0.0.1:6379. Connection refused.
ERROR --- 2024-02-28 20:01:00,836 --- runserver --- runserver.py --- [35;1mHTTP POST /services/ 500 [20.41, 127.0.0.1:39160][0m
ERROR --- 2024-02-28 20:01:02,276 --- log --- log.py --- Internal Server Error: /services/
Traceback (most recent call last):
  File "/mnt/myprojects/project/mysite/venv/lib/python3.11/site-packages/redis/connection.py", line 264, in connect
    sock = self.retry.call_with_retry(
           ^^^^^^^^^^^^^^^^^^^^^^^^^^^
  File "/mnt/myprojects/project/mysite/venv/lib/python3.11/site-packages/redis/retry.py", line 46, in call_with_retry
    return do()
           ^^^^
  File "/mnt/myprojects/project/mysite/venv/lib/python3.11/site-packages/redis/connection.py", line 265, in <lambda>
    lambda: self._connect(), lambda error: self.disconnect(error)
            ^^^^^^^^^^^^^^^
  File "/mnt/myprojects/project/mysite/venv/lib/python3.11/site-packages/redis/connection.py", line 627, in _connect
    raise err
  File "/mnt/myprojects/project/mysite/venv/lib/python3.11/site-packages/redis/connection.py", line 615, in _connect
    sock.connect(socket_address)
ConnectionRefusedError: [Errno 111] Connection refused

During handling of the above exception, another exception occurred:

Traceback (most recent call last):
  File "/mnt/myprojects/project/mysite/venv/lib/python3.11/site-packages/celery/backends/redis.py", line 127, in reconnect_on_error
    yield
  File "/mnt/myprojects/project/mysite/venv/lib/python3.11/site-packages/celery/backends/redis.py", line 177, in _consume_from
    self._pubsub.subscribe(key)
  File "/mnt/myprojects/project/mysite/venv/lib/python3.11/site-packages/redis/client.py", line 916, in subscribe
    ret_val = self.execute_command("SUBSCRIBE", *new_channels.keys())
              ^^^^^^^^^^^^^^^^^^^^^^^^^^^^^^^^^^^^^^^^^^^^^^^^^^^^^^^
  File "/mnt/myprojects/project/mysite/venv/lib/python3.11/site-packages/redis/client.py", line 749, in execute_command
    self.connection = self.connection_pool.get_connection(
                      ^^^^^^^^^^^^^^^^^^^^^^^^^^^^^^^^^^^^
  File "/mnt/myprojects/project/mysite/venv/lib/python3.11/site-packages/redis/connection.py", line 1086, in get_connection
    connection.connect()
  File "/mnt/myprojects/project/mysite/venv/lib/python3.11/site-packages/redis/connection.py", line 270, in connect
    raise ConnectionError(self._error_message(e))
redis.exceptions.ConnectionError: Error 111 connecting to 127.0.0.1:6379. Connection refused.

During handling of the above exception, another exception occurred:

Traceback (most recent call last):
  File "/mnt/myprojects/project/mysite/venv/lib/python3.11/site-packages/redis/connection.py", line 264, in connect
    sock = self.retry.call_with_retry(
           ^^^^^^^^^^^^^^^^^^^^^^^^^^^
  File "/mnt/myprojects/project/mysite/venv/lib/python3.11/site-packages/redis/retry.py", line 46, in call_with_retry
    return do()
           ^^^^
  File "/mnt/myprojects/project/mysite/venv/lib/python3.11/site-packages/redis/connection.py", line 265, in <lambda>
    lambda: self._connect(), lambda error: self.disconnect(error)
            ^^^^^^^^^^^^^^^
  File "/mnt/myprojects/project/mysite/venv/lib/python3.11/site-packages/redis/connection.py", line 627, in _connect
    raise err
  File "/mnt/myprojects/project/mysite/venv/lib/python3.11/site-packages/redis/connection.py", line 615, in _connect
    sock.connect(socket_address)
ConnectionRefusedError: [Errno 111] Connection refused

During handling of the above exception, another exception occurred:

Traceback (most recent call last):
  File "/mnt/myprojects/project/mysite/venv/lib/python3.11/site-packages/kombu/connection.py", line 472, in _reraise_as_library_errors
    yield
  File "/mnt/myprojects/project/mysite/venv/lib/python3.11/site-packages/celery/app/base.py", line 798, in send_task
    self.backend.on_task_call(P, task_id)
  File "/mnt/myprojects/project/mysite/venv/lib/python3.11/site-packages/celery/backends/redis.py", line 373, in on_task_call
    self.result_consumer.consume_from(task_id)
  File "/mnt/myprojects/project/mysite/venv/lib/python3.11/site-packages/celery/backends/redis.py", line 169, in consume_from
    return self.start(task_id)
           ^^^^^^^^^^^^^^^^^^^
  File "/mnt/myprojects/project/mysite/venv/lib/python3.11/site-packages/celery/backends/redis.py", line 147, in start
    self._consume_from(initial_task_id)
  File "/mnt/myprojects/project/mysite/venv/lib/python3.11/site-packages/celery/backends/redis.py", line 176, in _consume_from
    with self.reconnect_on_error():
  File "/home/kenun/.python3.11/lib/python3.11/contextlib.py", line 158, in __exit__
    self.gen.throw(typ, value, traceback)
  File "/mnt/myprojects/project/mysite/venv/lib/python3.11/site-packages/celery/backends/redis.py", line 130, in reconnect_on_error
    self._ensure(self._reconnect_pubsub, ())
  File "/mnt/myprojects/project/mysite/venv/lib/python3.11/site-packages/celery/backends/redis.py", line 384, in ensure
    return retry_over_time(
           ^^^^^^^^^^^^^^^^
  File "/mnt/myprojects/project/mysite/venv/lib/python3.11/site-packages/kombu/utils/functional.py", line 318, in retry_over_time
    return fun(*args, **kwargs)
           ^^^^^^^^^^^^^^^^^^^^
  File "/mnt/myprojects/project/mysite/venv/lib/python3.11/site-packages/celery/backends/redis.py", line 106, in _reconnect_pubsub
    metas = self.backend.client.mget(self.subscribed_to)
            ^^^^^^^^^^^^^^^^^^^^^^^^^^^^^^^^^^^^^^^^^^^^
  File "/mnt/myprojects/project/mysite/venv/lib/python3.11/site-packages/redis/commands/core.py", line 2015, in mget
    return self.execute_command("MGET", *args, **options)
           ^^^^^^^^^^^^^^^^^^^^^^^^^^^^^^^^^^^^^^^^^^^^^^
  File "/mnt/myprojects/project/mysite/venv/lib/python3.11/site-packages/redis/client.py", line 533, in execute_command
    conn = self.connection or pool.get_connection(command_name, **options)
                              ^^^^^^^^^^^^^^^^^^^^^^^^^^^^^^^^^^^^^^^^^^^^
  File "/mnt/myprojects/project/mysite/venv/lib/python3.11/site-packages/redis/connection.py", line 1086, in get_connection
    connection.connect()
  File "/mnt/myprojects/project/mysite/venv/lib/python3.11/site-packages/redis/connection.py", line 270, in connect
    raise ConnectionError(self._error_message(e))
redis.exceptions.ConnectionError: Error 111 connecting to 127.0.0.1:6379. Connection refused.

The above exception was the direct cause of the following exception:

Traceback (most recent call last):
  File "/mnt/myprojects/project/mysite/venv/lib/python3.11/site-packages/asgiref/sync.py", line 534, in thread_handler
    raise exc_info[1]
  File "/mnt/myprojects/project/mysite/venv/lib/python3.11/site-packages/django/core/handlers/exception.py", line 42, in inner
    response = await get_response(request)
               ^^^^^^^^^^^^^^^^^^^^^^^^^^^
  File "/mnt/myprojects/project/mysite/venv/lib/python3.11/site-packages/asgiref/sync.py", line 534, in thread_handler
    raise exc_info[1]
  File "/mnt/myprojects/project/mysite/venv/lib/python3.11/site-packages/django/core/handlers/base.py", line 253, in _get_response_async
    response = await wrapped_callback(
               ^^^^^^^^^^^^^^^^^^^^^^^
  File "/mnt/myprojects/project/mysite/venv/lib/python3.11/site-packages/asgiref/sync.py", line 479, in __call__
    ret: _R = await loop.run_in_executor(
              ^^^^^^^^^^^^^^^^^^^^^^^^^^^
  File "/home/kenun/.python3.11/lib/python3.11/concurrent/futures/thread.py", line 58, in run
    result = self.fn(*self.args, **self.kwargs)
             ^^^^^^^^^^^^^^^^^^^^^^^^^^^^^^^^^^
  File "/mnt/myprojects/project/mysite/venv/lib/python3.11/site-packages/asgiref/sync.py", line 538, in thread_handler
    return func(*args, **kwargs)
           ^^^^^^^^^^^^^^^^^^^^^
  File "/mnt/myprojects/project/mysite/venv/lib/python3.11/site-packages/django/views/generic/base.py", line 104, in view
    return self.dispatch(request, *args, **kwargs)
           ^^^^^^^^^^^^^^^^^^^^^^^^^^^^^^^^^^^^^^^
  File "/mnt/myprojects/project/mysite/venv/lib/python3.11/site-packages/django/views/generic/base.py", line 143, in dispatch
    return handler(request, *args, **kwargs)
           ^^^^^^^^^^^^^^^^^^^^^^^^^^^^^^^^^
  File "/mnt/myprojects/project/mysite/services/views.py", line 70, in post
    send_telegram_message.delay(telegram_id, data)
  File "/mnt/myprojects/project/mysite/venv/lib/python3.11/site-packages/celery/app/task.py", line 444, in delay
    return self.apply_async(args, kwargs)
           ^^^^^^^^^^^^^^^^^^^^^^^^^^^^^^
  File "/mnt/myprojects/project/mysite/venv/lib/python3.11/site-packages/celery/app/task.py", line 594, in apply_async
    return app.send_task(
           ^^^^^^^^^^^^^^
  File "/mnt/myprojects/project/mysite/venv/lib/python3.11/site-packages/celery/app/base.py", line 796, in send_task
    with P.connection._reraise_as_library_errors():
  File "/home/kenun/.python3.11/lib/python3.11/contextlib.py", line 158, in __exit__
    self.gen.throw(typ, value, traceback)
  File "/mnt/myprojects/project/mysite/venv/lib/python3.11/site-packages/kombu/connection.py", line 476, in _reraise_as_library_errors
    raise ConnectionError(str(exc)) from exc
kombu.exceptions.OperationalError: Error 111 connecting to 127.0.0.1:6379. Connection refused.
ERROR --- 2024-02-28 20:01:03,419 --- runserver --- runserver.py --- [35;1mHTTP POST /services/ 500 [20.27, 127.0.0.1:39154][0m
